Workbook

Sheet 製品標準原価_製品課生産分
I3: 38期実際原価（1個あたり） | O3: 38期実際原価（グラムあたり） | U3: 39期標準原価（1個あたり）
G4: g | M4: 円/個 | S4: 円/個 | Y4: 円/個
G5: 内容量 | I5: 前工程費 | J5: 資材費 | K5: 労務費 | L5: 経費 | M5: 計 | O5: 前工程費 | P5: 資材費 | Q5: 労務費 | R5: 経費 | S5: 計 | U5: 前工程費 | V5: 資材費 | W5: 労務費 | X5: 経費 | Y5: 計
B6: 1 | C6: 20051200013 | D6: MKF-Ⅰ 分包150g(AAAAA) | E6: 製品課 | G6: 150 | H6: 5A | I6: ='4.仕掛品(製品課) _作業用(値)'!E17*'4.仕掛品(製品課) _作業用(値)'!G17 -> 775.8794 | J6: ='4.仕掛品(製品課) _作業用(値)'!U17/'4.仕掛品(製品課) _作業用(値)'!K17 -> 87.543683 | K6: ='4.仕掛品(製品課) _作業用(値)'!W17/'4.仕掛品(製品課) _作業用(値)'!K17 -> 226.12593 | L6: ='4.仕掛品(製品課) _作業用(値)'!AA17/'4.仕掛品(製品課) _作業用(値)'!K17 -> 63.928658 | M6: =SUM(I6:L6) -> 1153.4777 | O6: =I6/$G6 -> 5.1725294 | P6: =J6/$G6 -> 0.58362455 | Q6: =K6/$G6 -> 1.5075062 | R6: =L6/$G6 -> 0.42619105 | S6: =M6/$G6 -> 7.6898512 | U6: =ROUND(I6,-1) -> 780 | V6: =ROUND(J6,-1) -> 90 | W6: =ROUND(K6,-1) -> 230 | X6: =ROUND(L6,-1) -> 60 | Y6: =SUM(U6:X6) -> 1160
B7: 2 | C7: 20071100007 | D7: MKF-Ⅰ携帯ﾊﾟｯｸ 50g(5A) | E7: 製品課 | G7: 50 | H7: 5A | I7: ='4.仕掛品(製品課) _作業用(値)'!E18*'4.仕掛品(製品課) _作業用(値)'!G18 -> 258.62647 | J7: ='4.仕掛品(製品課) _作業用(値)'!U18/'4.仕掛品(製品課) _作業用(値)'!K18 -> 50.414624 | K7: ='4.仕掛品(製品課) _作業用(値)'!W18/'4.仕掛品(製品課) _作業用(値)'!K18 -> 156.87486 | L7: ='4.仕掛品(製品課) _作業用(値)'!AA18/'4.仕掛品(製品課) _作業用(値)'!K18 -> 21.309553 | M7: =SUM(I7:L7) -> 487.22551 | O7: =I7/$G7 -> 5.1725294 | P7: =J7/$G7 -> 1.0082925 | Q7: =K7/$G7 -> 3.1374973 | R7: =L7/$G7 -> 0.42619105 | S7: =M7/$G7 -> 9.7445102 | U7: =ROUND(I7,-1) -> 260 | V7: =ROUND(J7,-1) -> 50 | W7: =ROUND(K7,-1) -> 160 | X7: =ROUND(L7,-1) -> 20 | Y7: =SUM(U7:X7) -> 490
B8: 3 | C8: 20051200005 | D8: 万田HI酵素 分包150g | E8: 製品課 | G8: 150 | H8: B | I8: ='4.仕掛品(製品課) _作業用(値)'!E19*'4.仕掛品(製品課) _作業用(値)'!G19 -> 202.3042 | J8: ='4.仕掛品(製品課) _作業用(値)'!U19/'4.仕掛品(製品課) _作業用(値)'!K19 -> 333.92988 | K8: ='4.仕掛品(製品課) _作業用(値)'!W19/'4.仕掛品(製品課) _作業用(値)'!K19 -> 328.3478 | L8: ='4.仕掛品(製品課) _作業用(値)'!AA19/'4.仕掛品(製品課) _作業用(値)'!K19 -> 63.928658 | M8: =SUM(I8:L8) -> 928.51054 | O8: =I8/$G8 -> 1.3486947 | P8: =J8/$G8 -> 2.2261992 | Q8: =K8/$G8 -> 2.1889854 | R8: =L8/$G8 -> 0.42619105 | S8: =M8/$G8 -> 6.1900703 | U8: =ROUND(I8,-1) -> 200 | V8: =ROUND(J8,-1) -> 330 | W8: =ROUND(K8,-1) -> 330 | X8: =ROUND(L8,-1) -> 60 | Y8: =SUM(U8:X8) -> 920
B9: 4 | C9: 20071000005 | D9: 試供品 HI酵素 5g | E9: 製品課 | G9: 5 | H9: B | I9: ='4.仕掛品(製品課) _作業用(値)'!E20*'4.仕掛品(製品課) _作業用(値)'!G20 -> 6.7434734 | J9: ='4.仕掛品(製品課) _作業用(値)'!U20/'4.仕掛品(製品課) _作業用(値)'!K20 -> 6.1951706 | K9: ='4.仕掛品(製品課) _作業用(値)'!W20/'4.仕掛品(製品課) _作業用(値)'!K20 -> 12.064616 | L9: ='4.仕掛品(製品課) _作業用(値)'!AA20/'4.仕掛品(製品課) _作業用(値)'!K20 -> 2.1309553 | M9: =SUM(I9:L9) -> 27.134215 | O9: =I9/$G9 -> 1.3486947 | P9: =J9/$G9 -> 1.2390341 | Q9: =K9/$G9 -> 2.4129231 | R9: =L9/$G9 -> 0.42619105 | S9: =M9/$G9 -> 5.426843 | U9: =ROUND(I9,-1) -> 10 | V9: =ROUND(J9,-1) -> 10 | W9: =ROUND(K9,-1) -> 10 | X9: =ROUND(L9,-1) -> 0 | Y9: =SUM(U9:X9) -> 30
B10: 5 | C10: 20110800311 | D10: MANDA HI KOHSO | E10: 製品課 | G10: 145 | H10: B | I10: ='4.仕掛品(製品課) _作業用(値)'!E21*'4.仕掛品(製品課) _作業用(値)'!G21 -> 195.56073 | J10: ='4.仕掛品(製品課) _作業用(値)'!U21/'4.仕掛品(製品課) _作業用(値)'!K21 -> 871.73246 | K10: ='4.仕掛品(製品課) _作業用(値)'!W21/'4.仕掛品(製品課) _作業用(値)'!K21 -> 398.45126 | L10: ='4.仕掛品(製品課) _作業用(値)'!AA21/'4.仕掛品(製品課) _作業用(値)'!K21 -> 61.797703 | M10: =SUM(I10:L10) -> 1527.5422 | O10: =I10/$G10 -> 1.3486947 | P10: =J10/$G10 -> 6.011948 | Q10: =K10/$G10 -> 2.7479397 | R10: =L10/$G10 -> 0.42619105 | S10: =M10/$G10 -> 10.534773 | U10: =ROUND(I10,-1) -> 200 | V10: =ROUND(J10,-1) -> 870 | W10: =ROUND(K10,-1) -> 400 | X10: =ROUND(L10,-1) -> 60 | Y10: =SUM(U10:X10) -> 1530
B11: 6 | C11: 20110800629 | D11: 万田HI酵素 145g | E11: 製品課 | G11: 145 | H11: B | I11: ='4.仕掛品(製品課) _作業用(値)'!E22*'4.仕掛品(製品課) _作業用(値)'!G22 -> 195.56073 | J11: ='4.仕掛品(製品課) _作業用(値)'!U22/'4.仕掛品(製品課) _作業用(値)'!K22 -> 292.73446 | K11: ='4.仕掛品(製品課) _作業用(値)'!W22/'4.仕掛品(製品課) _作業用(値)'!K22 -> 292.29949 | L11: ='4.仕掛品(製品課) _作業用(値)'!AA22/'4.仕掛品(製品課) _作業用(値)'!K22 -> 61.797703 | M11: =SUM(I11:L11) -> 842.39238 | O11: =I11/$G11 -> 1.3486947 | P11: =J11/$G11 -> 2.0188584 | Q11: =K11/$G11 -> 2.0158586 | R11: =L11/$G11 -> 0.42619105 | S11: =M11/$G11 -> 5.8096027 | U11: =ROUND(I11,-1) -> 200 | V11: =ROUND(J11,-1) -> 290 | W11: =ROUND(K11,-1) -> 290 | X11: =ROUND(L11,-1) -> 60 | Y11: =SUM(U11:X11) -> 840
B12: 7 | C12: 20200800016 | D12: 万田酵素ｴｸｾﾚﾝﾄ 145g | E12: 製品課 | G12: 145 | H12: BE | I12: ='4.仕掛品(製品課) _作業用(値)'!E23*'4.仕掛品(製品課) _作業用(値)'!G23 -> 245.73753 | J12: ='4.仕掛品(製品課) _作業用(値)'!U23/'4.仕掛品(製品課) _作業用(値)'!K23 -> 995.31872 | K12: ='4.仕掛品(製品課) _作業用(値)'!W23/'4.仕掛品(製品課) _作業用(値)'!K23 -> 1433.2262 | L12: ='4.仕掛品(製品課) _作業用(値)'!AA23/'4.仕掛品(製品課) _作業用(値)'!K23 -> 61.797703 | M12: =SUM(I12:L12) -> 2736.0801 | O12: =I12/$G12 -> 1.6947416 | P12: =J12/$G12 -> 6.8642671 | Q12: =K12/$G12 -> 9.8843185 | R12: =L12/$G12 -> 0.42619105 | S12: =M12/$G12 -> 18.869518 | U12: =ROUND(I12,-1) -> 250 | V12: =ROUND(J12,-1) -> 1000 | W12: =ROUND(K12,-1) -> 1430 | X12: =ROUND(L12,-1) -> 60 | Y12: =SUM(U12:X12) -> 2740
B13: 8 | C13: 20200800017 | D13: 万田酵素ｴｸｾﾚﾝﾄ 分包30g（2.5g×12包） | E13: 製品課 | G13: 30 | H13: BE | I13: ='4.仕掛品(製品課) _作業用(値)'!E24*'4.仕掛品(製品課) _作業用(値)'!G24 -> 50.842248 | J13: ='4.仕掛品(製品課) _作業用(値)'!U24/'4.仕掛品(製品課) _作業用(値)'!K24 -> 94.133199 | K13: ='4.仕掛品(製品課) _作業用(値)'!W24/'4.仕掛品(製品課) _作業用(値)'!K24 -> 141.8846 | L13: ='4.仕掛品(製品課) _作業用(値)'!AA24/'4.仕掛品(製品課) _作業用(値)'!K24 -> 12.785732 | M13: =SUM(I13:L13) -> 299.64578 | O13: =I13/$G13 -> 1.6947416 | P13: =J13/$G13 -> 3.1377733 | Q13: =K13/$G13 -> 4.7294866 | R13: =L13/$G13 -> 0.42619105 | S13: =M13/$G13 -> 9.9881926 | U13: =ROUND(I13,-1) -> 50 | V13: =ROUND(J13,-1) -> 90 | W13: =ROUND(K13,-1) -> 140 | X13: =ROUND(L13,-1) -> 10 | Y13: =SUM(U13:X13) -> 290
B14: 9 | C14: 20200800018 | D14: 万田酵素ｴｸｾﾚﾝﾄ 分包450g | E14: 製品課 | G14: 450 | H14: BE | I14: ='4.仕掛品(製品課) _作業用(値)'!E25*'4.仕掛品(製品課) _作業用(値)'!G25 -> 762.63372 | J14: ='4.仕掛品(製品課) _作業用(値)'!U25/'4.仕掛品(製品課) _作業用(値)'!K25 -> 1267.8189 | K14: ='4.仕掛品(製品課) _作業用(値)'!W25/'4.仕掛品(製品課) _作業用(値)'!K25 -> 1130.3836 | L14: ='4.仕掛品(製品課) _作業用(値)'!AA25/'4.仕掛品(製品課) _作業用(値)'!K25 -> 191.78597 | M14: =SUM(I14:L14) -> 3352.6221 | O14: =I14/$G14 -> 1.6947416 | P14: =J14/$G14 -> 2.8173753 | Q14: =K14/$G14 -> 2.5119635 | R14: =L14/$G14 -> 0.42619105 | S14: =M14/$G14 -> 7.4502714 | U14: =ROUND(I14,-1) -> 760 | V14: =ROUND(J14,-1) -> 1270 | W14: =ROUND(K14,-1) -> 1130 | X14: =ROUND(L14,-1) -> 190 | Y14: =SUM(U14:X14) -> 3350
B15: 10 | C15: 20240100051 | D15: 万田酵素 MANUKA HONEY Premium 分包77.5g | E15: 製品課 | G15: 77.5 | H15: BM | I15: ='4.仕掛品(製品課) _作業用(値)'!E26*'4.仕掛品(製品課) _作業用(値)'!G26 -> 348.76583 | J15: ='4.仕掛品(製品課) _作業用(値)'!U26/'4.仕掛品(製品課) _作業用(値)'!K26 -> 43.109808 | K15: ='4.仕掛品(製品課) _作業用(値)'!W26/'4.仕掛品(製品課) _作業用(値)'!K26 -> 52.433911 | L15: ='4.仕掛品(製品課) _作業用(値)'!AA26/'4.仕掛品(製品課) _作業用(値)'!K26 -> 33.029807 | M15: =SUM(I15:L15) -> 477.33935 | O15: =I15/$G15 -> 4.5002042 | P15: =J15/$G15 -> 0.55625559 | Q15: =K15/$G15 -> 0.6765666 | R15: =L15/$G15 -> 0.42619105 | S15: =M15/$G15 -> 6.1592174 | U15: =ROUND(I15,-1) -> 350 | V15: =ROUND(J15,-1) -> 40 | W15: =ROUND(K15,-1) -> 50 | X15: =ROUND(L15,-1) -> 30 | Y15: =SUM(U15:X15) -> 470
B16: 11 | C16: 20110300008 | D16: Man-Koso CARAT 145g | E16: 製品課 | G16: 145 | H16: C | I16: ='4.仕掛品(製品課) _作業用(値)'!E27*'4.仕掛品(製品課) _作業用(値)'!G27 -> 150.00044 | J16: ='4.仕掛品(製品課) _作業用(値)'!U27/'4.仕掛品(製品課) _作業用(値)'!K27 -> 1404.177 | K16: ='4.仕掛品(製品課) _作業用(値)'!W27/'4.仕掛品(製品課) _作業用(値)'!K27 -> 726.94978 | L16: ='4.仕掛品(製品課) _作業用(値)'!AA27/'4.仕掛品(製品課) _作業用(値)'!K27 -> 61.797703 | M16: =SUM(I16:L16) -> 2342.9249 | O16: =I16/$G16 -> 1.0344858 | P16: =J16/$G16 -> 9.6839791 | Q16: =K16/$G16 -> 5.0134467 | R16: =L16/$G16 -> 0.42619105 | S16: =M16/$G16 -> 16.158103 | U16: =ROUND(I16,-1) -> 150 | V16: =ROUND(J16,-1) -> 1400 | W16: =ROUND(K16,-1) -> 730 | X16: =ROUND(L16,-1) -> 60 | Y16: =SUM(U16:X16) -> 2340
B17: 12 | C17: 20200200001 | D17: 万田酵素超熟分包77.5g | E17: 製品課 | G17: 77.5 | H17: D | I17: ='4.仕掛品(製品課) _作業用(値)'!E28*'4.仕掛品(製品課) _作業用(値)'!G28 -> 104.62214 | J17: ='4.仕掛品(製品課) _作業用(値)'!U28/'4.仕掛品(製品課) _作業用(値)'!K28 -> 162.13702 | K17: ='4.仕掛品(製品課) _作業用(値)'!W28/'4.仕掛品(製品課) _作業用(値)'!K28 -> 91.745649 | L17: ='4.仕掛品(製品課) _作業用(値)'!AA28/'4.仕掛品(製品課) _作業用(値)'!K28 -> 33.029807 | M17: =SUM(I17:L17) -> 391.53462 | O17: =I17/$G17 -> 1.3499631 | P17: =J17/$G17 -> 2.0920906 | Q17: =K17/$G17 -> 1.1838148 | R17: =L17/$G17 -> 0.42619105 | S17: =M17/$G17 -> 5.0520595 | U17: =ROUND(I17,-1) -> 100 | V17: =ROUND(J17,-1) -> 160 | W17: =ROUND(K17,-1) -> 90 | X17: =ROUND(L17,-1) -> 30 | Y17: =SUM(U17:X17) -> 380
... B28: 23 | C28: 20110800295 | D28: 万田酵素 MJ | E28: 製品課 | G28: 90 | H28: G | I28: ='4.仕掛品(製品課) _作業用(値)'!E39*'4.仕掛品(製品課) _作業用(値)'!G39 -> 249.77734 | J28: ='4.仕掛品(製品課) _作業用(値)'!U39/'4.仕掛品(製品課) _作業用(値)'!K39 -> 385.91287 | K28: ='4.仕掛品(製品課) _作業用(値)'!W39/'4.仕掛品(製品課) _作業用(値)'!K39 -> 564.14614 | L28: ='4.仕掛品(製品課) _作業用(値)'!AA39/'4.仕掛品(製品課) _作業用(値)'!K39 -> 38.357195 | M28: =SUM(I28:L28) -> 1238.1936 | O28: =I28/$G28 -> 2.7753038 | P28: =J28/$G28 -> 4.2879208 | Q28: =K28/$G28 -> 6.2682905 | R28: =L28/$G28 -> 0.42619105 | S28: =M28/$G28 -> 13.757706 | U28: =ROUND(I28,-1) -> 250 | V28: =ROUND(J28,-1) -> 390 | W28: =ROUND(K28,-1) -> 560 | X28: =ROUND(L28,-1) -> 40 | Y28: =SUM(U28:X28) -> 1240
B29: 24 | C29: 20231100078 | D29: 発酵しょうが 2.5g 支給用 | E29: 製品課 | G29: 2.5 | H29: GP | I29: ='4.仕掛品(製品課) _作業用(値)'!E40*'4.仕掛品(製品課) _作業用(値)'!G40 -> 3.4869975 | J29: ='4.仕掛品(製品課) _作業用(値)'!U40/'4.仕掛品(製品課) _作業用(値)'!K40 -> 0.34291086 | K29: ='4.仕掛品(製品課) _作業用(値)'!W40/'4.仕掛品(製品課) _作業用(値)'!K40 -> 2.4046883 | L29: ='4.仕掛品(製品課) _作業用(値)'!AA40/'4.仕掛品(製品課) _作業用(値)'!K40 -> 1.0654776 | M29: =SUM(I29:L29) -> 7.3000743 | O29: =I29/$G29 -> 1.394799 | P29: =J29/$G29 -> 0.13716435 | Q29: =K29/$G29 -> 0.96187532 | R29: =L29/$G29 -> 0.42619105 | S29: =M29/$G29 -> 2.9200297 | U29: =ROUNDUP(I29,-1) -> 10 | V29: =ROUND(J29,-1) -> 0 | W29: =ROUND(K29,-1) -> 0 | X29: =ROUND(L29,-1) -> 0 | Y29: =SUM(U29:X29) -> 10
B30: 25 | C30: 20230600044 | D30: 万田酵素 ﾌﾟﾗｽ温 発酵しょうが 77.5g | E30: 製品課 | G30: 77.5 | H30: GP | I30: ='4.仕掛品(製品課) _作業用(値)'!E41*'4.仕掛品(製品課) _作業用(値)'!G41 -> 108.09692 | J30: ='4.仕掛品(製品課) _作業用(値)'!U41/'4.仕掛品(製品課) _作業用(値)'!K41 -> 26.631968 | K30: ='4.仕掛品(製品課) _作業用(値)'!W41/'4.仕掛品(製品課) _作業用(値)'!K41 -> 26.385847 | L30: ='4.仕掛品(製品課) _作業用(値)'!AA41/'4.仕掛品(製品課) _作業用(値)'!K41 -> 33.029807 | M30: =SUM(I30:L30) -> 194.14454 | O30: =I30/$G30 -> 1.394799 | P30: =J30/$G30 -> 0.34363829 | Q30: =K30/$G30 -> 0.34046254 | R30: =L30/$G30 -> 0.42619105 | S30: =M30/$G30 -> 2.5050909 | U30: =ROUND(I30,-1) -> 110 | V30: =ROUND(J30,-1) -> 30 | W30: =ROUND(K30,-1) -> 30 | X30: =ROUND(L30,-1) -> 30 | Y30: =SUM(U30:X30) -> 200
B31: 26 | C31: 20230600045 | D31: 万田酵素 ﾌﾟﾗｽ温 発酵しょうが 20g | E31: 製品課 | G31: 20 | H31: GP | I31: ='4.仕掛品(製品課) _作業用(値)'!E42*'4.仕掛品(製品課) _作業用(値)'!G42 -> 27.89598 | J31: ='4.仕掛品(製品課) _作業用(値)'!U42/'4.仕掛品(製品課) _作業用(値)'!K42 -> 25.076167 | K31: ='4.仕掛品(製品課) _作業用(値)'!W42/'4.仕掛品(製品課) _作業用(値)'!K42 -> 26.324217 | L31: ='4.仕掛品(製品課) _作業用(値)'!AA42/'4.仕掛品(製品課) _作業用(値)'!K42 -> 8.5238211 | M31: =SUM(I31:L31) -> 87.820185 | O31: =I31/$G31 -> 1.394799 | P31: =J31/$G31 -> 1.2538083 | Q31: =K31/$G31 -> 1.3162109 | R31: =L31/$G31 -> 0.42619105 | S31: =M31/$G31 -> 4.3910093 | U31: =ROUND(I31,-1) -> 30 | V31: =ROUND(J31,-1) -> 30 | W31: =ROUND(K31,-1) -> 30 | X31: =ROUND(L31,-1) -> 10 | Y31: =SUM(U31:X31) -> 100
B32: 27 | C32: 20230600046 | D32: 試供品 ﾌﾟﾗｽ温発酵しょうが 2.5g | E32: 製品課 | G32: 2.5 | H32: GP | I32: ='4.仕掛品(製品課) _作業用(値)'!E43*'4.仕掛品(製品課) _作業用(値)'!G43 -> 3.4869975 | J32: ='4.仕掛品(製品課) _作業用(値)'!U43/'4.仕掛品(製品課) _作業用(値)'!K43 -> 4.0551279 | K32: ='4.仕掛品(製品課) _作業用(値)'!W43/'4.仕掛品(製品課) _作業用(値)'!K43 -> 10.665764 | L32: ='4.仕掛品(製品課) _作業用(値)'!AA43/'4.仕掛品(製品課) _作業用(値)'!K43 -> 1.0654776 | M32: =SUM(I32:L32) -> 19.273367 | O32: =I32/$G32 -> 1.394799 | P32: =J32/$G32 -> 1.6220511 | Q32: =K32/$G32 -> 4.2663056 | R32: =L32/$G32 -> 0.42619105 | S32: =M32/$G32 -> 7.7093469 | U32: =ROUND(I32,-1) -> 0 | V32: =ROUND(J32,-1) -> 0 | W32: =ROUND(K32,-1) -> 10 | X32: =ROUND(L32,-1) -> 0 | Y32: =SUM(U32:X32) -> 10
B33: 28 | C33: 20241200012 | D33: 万田酵素ﾌﾟﾗｽ温発酵しょうが 75g 5g×15包 | E33: 製品課 | G33: 75 | H33: GP | I33: ='4.仕掛品(製品課) _作業用(値)'!E44*'4.仕掛品(製品課) _作業用(値)'!G44 -> 104.60993 | J33: ='4.仕掛品(製品課) _作業用(値)'!U44/'4.仕掛品(製品課) _作業用(値)'!K44 -> 529.95559 | K33: ='4.仕掛品(製品課) _作業用(値)'!W44/'4.仕掛品(製品課) _作業用(値)'!K44 -> 356.62886 | L33: ='4.仕掛品(製品課) _作業用(値)'!AA44/'4.仕掛品(製品課) _作業用(値)'!K44 -> 31.964329 | M33: =SUM(I33:L33) -> 1023.1587 | O33: =I33/$G33 -> 1.394799 | P33: =J33/$G33 -> 7.0660745 | Q33: =K33/$G33 -> 4.7550514 | R33: =L33/$G33 -> 0.42619105 | S33: =M33/$G33 -> 13.642116 | U33: =ROUND(I33,-1) -> 100 | V33: =ROUND(J33,-1) -> 530 | W33: =ROUND(K33,-1) -> 360 | X33: =ROUND(L33,-1) -> 30 | Y33: =SUM(U33:X33) -> 1020
B34: 29 | C34: 20231200033 | D34: 万田酵素分包75g （中国虹越） | E34: 製品課 | G34: 75 | H34: KOL | I34: ='4.仕掛品(製品課) _作業用(値)'!E45*'4.仕掛品(製品課) _作業用(値)'!G45 -> 97.501712 | J34: ='4.仕掛品(製品課) _作業用(値)'!U45/'4.仕掛品(製品課) _作業用(値)'!K45 -> 109.79819 | K34: ='4.仕掛品(製品課) _作業用(値)'!W45/'4.仕掛品(製品課) _作業用(値)'!K45 -> 421.81908 | L34: ='4.仕掛品(製品課) _作業用(値)'!AA45/'4.仕掛品(製品課) _作業用(値)'!K45 -> 31.964329 | M34: =SUM(I34:L34) -> 661.08331 | O34: =I34/$G34 -> 1.3000228 | P34: =J34/$G34 -> 1.4639759 | Q34: =K34/$G34 -> 5.6242544 | R34: =L34/$G34 -> 0.42619105 | S34: =M34/$G34 -> 8.8144441 | U34: =ROUND(I34,-1) -> 100 | V34: =ROUND(J34,-1) -> 110 | W34: =ROUND(K34,-1) -> 420 | X34: =ROUND(L34,-1) -> 30 | Y34: =SUM(U34:X34) -> 660
B35: 30 | C35: 20241100041 | D35: 試供品 万田酵素分包5g(中国虹越) | E35: 製品課 | G35: 5 | H35: KOL | I35: ='4.仕掛品(製品課) _作業用(値)'!E46*'4.仕掛品(製品課) _作業用(値)'!G46 -> 6.5001142 | J35: ='4.仕掛品(製品課) _作業用(値)'!U46/'4.仕掛品(製品課) _作業用(値)'!K46 -> 1153.1739 | K35: ='4.仕掛品(製品課) _作業用(値)'!W46/'4.仕掛品(製品課) _作業用(値)'!K46 -> 11.446636 | L35: ='4.仕掛品(製品課) _作業用(値)'!AA46/'4.仕掛品(製品課) _作業用(値)'!K46 -> 2.1309553 | M35: =SUM(I35:L35) -> 1173.2516 | O35: =I35/$G35 -> 1.3000228 | P35: =J35/$G35 -> 230.63478 | Q35: =K35/$G35 -> 2.2893272 | R35: =L35/$G35 -> 0.42619105 | S35: =M35/$G35 -> 234.65032 | U35: =ROUND(I35,-1) -> 10 | V35: =ROUND(J35,-1) -> 1150 | W35: =ROUND(K35,-1) -> 10 | X35: =ROUND(L35,-1) -> 0 | Y35: =SUM(U35:X35) -> 1170
B36: 31 | C36: 20250300087 | D36: 万田酵素 分包150g (中国) | E36: 製品課 | G36: 150 | H36: KOL | I36: ='4.仕掛品(製品課) _作業用(値)'!E47*'4.仕掛品(製品課) _作業用(値)'!G47 -> 195.00342 | J36: ='4.仕掛品(製品課) _作業用(値)'!U47/'4.仕掛品(製品課) _作業用(値)'!K47 -> 77.183908 | K36: ='4.仕掛品(製品課) _作業用(値)'!W47/'4.仕掛品(製品課) _作業用(値)'!K47 -> 288.58999 | L36: ='4.仕掛品(製品課) _作業用(値)'!AA47/'4.仕掛品(製品課) _作業用(値)'!K47 -> 63.928658 | M36: =SUM(I36:L36) -> 624.70598 | O36: =I36/$G36 -> 1.3000228 | P36: =J36/$G36 -> 0.51455939 | Q36: =K36/$G36 -> 1.9239332 | R36: =L36/$G36 -> 0.42619105 | S36: =M36/$G36 -> 4.1647065 | U36: =ROUND(I36,-1) -> 200 | V36: =ROUND(J36,-1) -> 80 | W36: =ROUND(K36,-1) -> 290 | X36: =ROUND(L36,-1) -> 60 | Y36: =SUM(U36:X36) -> 630
B37: 32 | C37: 20171000004 | D37: 万田酵素 MULBERRY 分包 77.5g | E37: 製品課 | G37: 77.5 | H37: MP | I37: ='4.仕掛品(製品課) _作業用(値)'!E48*'4.仕掛品(製品課) _作業用(値)'!G48 -> 91.436421 | J37: ='4.仕掛品(製品課) _作業用(値)'!U48/'4.仕掛品(製品課) _作業用(値)'!K48 -> 28.536968 | K37: ='4.仕掛品(製品課) _作業用(値)'!W48/'4.仕掛品(製品課) _作業用(値)'!K48 -> 26.252289 | L37: ='4.仕掛品(製品課) _作業用(値)'!AA48/'4.仕掛品(製品課) _作業用(値)'!K48 -> 33.029807 | M37: =SUM(I37:L37) -> 179.25548 | O37: =I37/$G37 -> 1.1798248 | P37: =J37/$G37 -> 0.36821894 | Q37: =K37/$G37 -> 0.33873922 | R37: =L37/$G37 -> 0.42619105 | S37: =M37/$G37 -> 2.312974 | U37: =ROUND(I37,-1) -> 90 | V37: =ROUND(J37,-1) -> 30 | W37: =ROUND(K37,-1) -> 30 | X37: =ROUND(L37,-1) -> 30 | Y37: =SUM(U37:X37) -> 180
B38: 33 | C38: 20171000006 | D38: 万田酵素 MULBERRY 分包20g | E38: 製品課 | G38: 20 | H38: MP | I38: ='4.仕掛品(製品課) _作業用(値)'!E49*'4.仕掛品(製品課) _作業用(値)'!G49 -> 23.596496 | J38: ='4.仕掛品(製品課) _作業用(値)'!U49/'4.仕掛品(製品課) _作業用(値)'!K49 -> 20.949852 | K38: ='4.仕掛品(製品課) _作業用(値)'!W49/'4.仕掛品(製品課) _作業用(値)'!K49 -> 45.729023 | L38: ='4.仕掛品(製品課) _作業用(値)'!AA49/'4.仕掛品(製品課) _作業用(値)'!K49 -> 8.5238211 | M38: =SUM(I38:L38) -> 98.799191 | O38: =I38/$G38 -> 1.1798248 | P38: =J38/$G38 -> 1.0474926 | Q38: =K38/$G38 -> 2.2864511 | R38: =L38/$G38 -> 0.42619105 | S38: =M38/$G38 -> 4.9399596 | U38: =ROUND(I38,-1) -> 20 | V38: =ROUND(J38,-1) -> 20 | W38: =ROUND(K38,-1) -> 50 | X38: =ROUND(L38,-1) -> 10 | Y38: =SUM(U38:X38) -> 100
B39: 34 | C39: 20171000010 | D39: 万田酵素 MULBERRY ﾁｭｰﾌﾞﾀｲﾌﾟ 26×3本 | E39: 製品課 | G39: 78 | H39: MP | I39: ='4.仕掛品(製品課) _作業用(値)'!E50*'4.仕掛品(製品課) _作業用(値)'!G50 -> 92.026333 | J39: ='4.仕掛品(製品課) _作業用(値)'!U50/'4.仕掛品(製品課) _作業用(値)'!K50 -> 295.50293 | K39: ='4.仕掛品(製品課) _作業用(値)'!W50/'4.仕掛品(製品課) _作業用(値)'!K50 -> 412.79621 | L39: ='4.仕掛品(製品課) _作業用(値)'!AA50/'4.仕掛品(製品課) _作業用(値)'!K50 -> 33.242902 | M39: =SUM(I39:L39) -> 833.56838 | O39: =I39/$G39 -> 1.1798248 | P39: =J39/$G39 -> 3.7884992 | Q39: =K39/$G39 -> 5.2922591 | R39: =L39/$G39 -> 0.42619105 | S39: =M39/$G39 -> 10.686774 | U39: =ROUND(I39,-1) -> 90 | V39: =ROUND(J39,-1) -> 300 | W39: =ROUND(K39,-1) -> 410 | X39: =ROUND(L39,-1) -> 30 | Y39: =SUM(U39:X39) -> 830
B40: 35 | C40: 20181100045 | D40: 万田酵素 MULBERRY 分包35g 2.5g×14包 | E40: 製品課 | G40: 35 | H40: MP | I40: ='4.仕掛品(製品課) _作業用(値)'!E51*'4.仕掛品(製品課) _作業用(値)'!G51 -> 41.293867 | J40: ='4.仕掛品(製品課) _作業用(値)'!U51/'4.仕掛品(製品課) _作業用(値)'!K51 -> 35.144766 | K40: ='4.仕掛品(製品課) _作業用(値)'!W51/'4.仕掛品(製品課) _作業用(値)'!K51 -> 74.777018 | L40: ='4.仕掛品(製品課) _作業用(値)'!AA51/'4.仕掛品(製品課) _作業用(値)'!K51 -> 14.916687 | M40: =SUM(I40:L40) -> 166.13234 | O40: =I40/$G40 -> 1.1798248 | P40: =J40/$G40 -> 1.0041362 | Q40: =K40/$G40 -> 2.1364862 | R40: =L40/$G40 -> 0.42619105 | S40: =M40/$G40 -> 4.7466382 | U40: =ROUND(I40,-1) -> 40 | V40: =ROUND(J40,-1) -> 40 | W40: =ROUND(K40,-1) -> 70 | X40: =ROUND(L40,-1) -> 10 | Y40: =SUM(U40:X40) -> 160
B41: 36 | C41: 20200200034 | D41: 万田酵素MULBERRY 分包 10g 2.5×4包 | E41: 製品課 | G41: 10 | H41: MP | I41: ='4.仕掛品(製品課) _作業用(値)'!E52*'4.仕掛品(製品課) _作業用(値)'!G52 -> 11.798248 | J41: ='4.仕掛品(製品課) _作業用(値)'!U52/'4.仕掛品(製品課) _作業用(値)'!K52 -> 127.57041 | K41: ='4.仕掛品(製品課) _作業用(値)'!W52/'4.仕掛品(製品課) _作業用(値)'!K52 -> 97.398944 | L41: ='4.仕掛品(製品課) _作業用(値)'!AA52/'4.仕掛品(製品課) _作業用(値)'!K52 -> 4.2619105 | M41: =SUM(I41:L41) -> 241.02951 | O41: =I41/$G41 -> 1.1798248 | P41: =J41/$G41 -> 12.757041 | Q41: =K41/$G41 -> 9.7398944 | R41: =L41/$G41 -> 0.42619105 | S41: =M41/$G41 -> 24.102951 | U41: =ROUND(I41,-1) -> 10 | V41: =ROUND(J41,-1) -> 130 | W41: =ROUND(K41,-1) -> 100 | X41: =ROUND(L41,-1) -> 0 | Y41: =SUM(U41:X41) -> 240
B42: 37 | C42: 20220100027 | D42: MULBERRY 2.5g 支給用 | E42: 製品課 | G42: 2.5 | H42: MP | I42: ='4.仕掛品(製品課) _作業用(値)'!E53*'4.仕掛品(製品課) _作業用(値)'!G53 -> 2.949562 | J42: ='4.仕掛品(製品課) _作業用(値)'!U53/'4.仕掛品(製品課) _作業用(値)'!K53 -> 0.35676342 | K42: ='4.仕掛品(製品課) _作業用(値)'!W53/'4.仕掛品(製品課) _作業用(値)'!K53 -> 2.5382187 | L42: ='4.仕掛品(製品課) _作業用(値)'!AA53/'4.仕掛品(製品課) _作業用(値)'!K53 -> 1.0654776 | M42: =SUM(I42:L42) -> 6.9100217 | O42: =I42/$G42 -> 1.1798248 | P42: =J42/$G42 -> 0.14270537 | Q42: =K42/$G42 -> 1.0152875 | R42: =L42/$G42 -> 0.42619105 | S42: =M42/$G42 -> 2.7640087 | U42: =ROUNDUP(I42,-1) -> 10 | V42: =ROUND(J42,-1) -> 0 | W42: =ROUND(K42,-1) -> 0 | X42: =ROUND(L42,-1) -> 0 | Y42: =SUM(U42:X42) -> 10
B43: 38 | C43: 20230900058 | D43: 万田酵素 MULBERRY 分包12.5g | E43: 製品課 | G43: 12.5 | H43: MP | I43: ='4.仕掛品(製品課) _作業用(値)'!E54*'4.仕掛品(製品課) _作業用(値)'!G54 -> 14.74781 | J43: ='4.仕掛品(製品課) _作業用(値)'!U54/'4.仕掛品(製品課) _作業用(値)'!K54 -> 13.116578 | K43: ='4.仕掛品(製品課) _作業用(値)'!W54/'4.仕掛品(製品課) _作業用(値)'!K54 -> 30.294279 | L43: ='4.仕掛品(製品課) _作業用(値)'!AA54/'4.仕掛品(製品課) _作業用(値)'!K54 -> 5.3273882 | M43: =SUM(I43:L43) -> 63.486055 | O43: =I43/$G43 -> 1.1798248 | P43: =J43/$G43 -> 1.0493262 | Q43: =K43/$G43 -> 2.4235423 | R43: =L43/$G43 -> 0.42619105 | S43: =M43/$G43 -> 5.0788844 | U43: =ROUND(I43,-1) -> 10 | V43: =ROUND(J43,-1) -> 10 | W43: =ROUND(K43,-1) -> 30 | X43: =ROUND(L43,-1) -> 10 | Y43: =SUM(U43:X43) -> 60
B44: 39 | C44: 20060200007 | D44: 万田酵素 金印145g | E44: 製品課 | G44: 145 | H44: O | I44: ='4.仕掛品(製品課) _作業用(値)'!E55*'4.仕掛品(製品課) _作業用(値)'!G55 -> 191.80757 | J44: ='4.仕掛品(製品課) _作業用(値)'!U55/'4.仕掛品(製品課) _作業用(値)'!K55 -> 711.19074 | K44: ='4.仕掛品(製品課) _作業用(値)'!W55/'4.仕掛品(製品課) _作業用(値)'!K55 -> 425.01468 | L44: ='4.仕掛品(製品課) _作業用(値)'!AA55/'4.仕掛品(製品課) _作業用(値)'!K55 -> 61.797703 | M44: =SUM(I44:L44) -> 1389.8107 | O44: =I44/$G44 -> 1.3228108 | P44: =J44/$G44 -> 4.9047637 | Q44: =K44/$G44 -> 2.9311357 | R44: =L44/$G44 -> 0.42619105 | S44: =M44/$G44 -> 9.5849013 | U44: =ROUND(I44,-1) -> 190 | V44: =ROUND(J44,-1) -> 710 | W44: =ROUND(K44,-1) -> 430 | X44: =ROUND(L44,-1) -> 60 | Y44: =SUM(U44:X44) -> 1390
B45: 40 | C45: 20071000014 | D45: 試供品 金印 5g | E45: 製品課 | G45: 5 | H45: O | I45: ='4.仕掛品(製品課) _作業用(値)'!E56*'4.仕掛品(製品課) _作業用(値)'!G56 -> 6.6140541 | J45: ='4.仕掛品(製品課) _作業用(値)'!U56/'4.仕掛品(製品課) _作業用(値)'!K56 -> 8.2544451 | K45: ='4.仕掛品(製品課) _作業用(値)'!W56/'4.仕掛品(製品課) _作業用(値)'!K56 -> 14.060636 | L45: ='4.仕掛品(製品課) _作業用(値)'!AA56/'4.仕掛品(製品課) _作業用(値)'!K56 -> 2.1309553 | M45: =SUM(I45:L45) -> 31.06009 | O45: =I45/$G45 -> 1.3228108 | P45: =J45/$G45 -> 1.650889 | Q45: =K45/$G45 -> 2.8121272 | R45: =L45/$G45 -> 0.42619105 | S45: =M45/$G45 -> 6.2120181 | U45: =ROUND(I45,-1) -> 10 | V45: =ROUND(J45,-1) -> 10 | W45: =ROUND(K45,-1) -> 10 | X45: =ROUND(L45,-1) -> 0 | Y45: =SUM(U45:X45) -> 30
B46: 41 | C46: 20071100028 | D46: 万田酵素 金印 分包150g | E46: 製品課 | G46: 150 | H46: O | I46: ='4.仕掛品(製品課) _作業用(値)'!E57*'4.仕掛品(製品課) _作業用(値)'!G57 -> 198.42162 | J46: ='4.仕掛品(製品課) _作業用(値)'!U57/'4.仕掛品(製品課) _作業用(値)'!K57 -> 255.58587 | K46: ='4.仕掛品(製品課) _作業用(値)'!W57/'4.仕掛品(製品課) _作業用(値)'!K57 -> 281.21272 | L46: ='4.仕掛品(製品課) _作業用(値)'!AA57/'4.仕掛品(製品課) _作業用(値)'!K57 -> 63.928658 | M46: =SUM(I46:L46) -> 799.14887 | O46: =I46/$G46 -> 1.3228108 | P46: =J46/$G46 -> 1.7039058 | Q46: =K46/$G46 -> 1.8747515 | R46: =L46/$G46 -> 0.42619105 | S46: =M46/$G46 -> 5.3276592 | U46: =ROUND(I46,-1) -> 200 | V46: =ROUND(J46,-1) -> 260 | W46: =ROUND(K46,-1) -> 280 | X46: =ROUND(L46,-1) -> 60 | Y46: =SUM(U46:X46) -> 800
B47: 42 | C47: 20110800312 | D47: MANDA KOHSO GOLD 145ｇ | E47: 製品課 | G47: 145 | H47: O | I47: ='4.仕掛品(製品課) _作業用(値)'!E58*'4.仕掛品(製品課) _作業用(値)'!G58 -> 191.80757 | J47: ='4.仕掛品(製品課) _作業用(値)'!U58/'4.仕掛品(製品課) _作業用(値)'!K58 -> 1588.7743 | K47: ='4.仕掛品(製品課) _作業用(値)'!W58/'4.仕掛品(製品課) _作業用(値)'!K58 -> 623.14182 | L47: ='4.仕掛品(製品課) _作業用(値)'!AA58/'4.仕掛品(製品課) _作業用(値)'!K58 -> 61.797703 | M47: =SUM(I47:L47) -> 2465.5214 | O47: =I47/$G47 -> 1.3228108 | P47: =J47/$G47 -> 10.957064 | Q47: =K47/$G47 -> 4.2975298 | R47: =L47/$G47 -> 0.42619105 | S47: =M47/$G47 -> 17.003596 | U47: =ROUND(I47,-1) -> 190 | V47: =ROUND(J47,-1) -> 1590 | W47: =ROUND(K47,-1) -> 620 | X47: =ROUND(L47,-1) -> 60 | Y47: =SUM(U47:X47) -> 2460
B48: 43 | C48: 20140100011 | D48: Man-Koso GOLD 145g | E48: 製品課 | G48: 145 | H48: O | I48: ='4.仕掛品(製品課) _作業用(値)'!E59*'4.仕掛品(製品課) _作業用(値)'!G59 -> 191.80757 | J48: ='4.仕掛品(製品課) _作業用(値)'!U59/'4.仕掛品(製品課) _作業用(値)'!K59 -> 1984.4659 | K48: ='4.仕掛品(製品課) _作業用(値)'!W59/'4.仕掛品(製品課) _作業用(値)'!K59 -> 419.278 | L48: ='4.仕掛品(製品課) _作業用(値)'!AA59/'4.仕掛品(製品課) _作業用(値)'!K59 -> 61.797703 | M48: =SUM(I48:L48) -> 2657.3491 | O48: =I48/$G48 -> 1.3228108 | P48: =J48/$G48 -> 13.685971 | Q48: =K48/$G48 -> 2.8915724 | R48: =L48/$G48 -> 0.42619105 | S48: =M48/$G48 -> 18.326546 | U48: =ROUND(I48,-1) -> 190 | V48: =ROUND(J48,-1) -> 1980 | W48: =ROUND(K48,-1) -> 420 | X48: =ROUND(L48,-1) -> 60 | Y48: =SUM(U48:X48) -> 2650
B49: 44 | C49: 20061200012 | D49: 万田酵素 145g(販売店向け) | E49: 製品課 | G49: 145 | H49: P | I49: ='4.仕掛品(製品課) _作業用(値)'!E60*'4.仕掛品(製品課) _作業用(値)'!G60 -> 183.52784 | J49: ='4.仕掛品(製品課) _作業用(値)'!U60/'4.仕掛品(製品課) _作業用(値)'!K60 -> 178.38354 | K49: ='4.仕掛品(製品課) _作業用(値)'!W60/'4.仕掛品(製品課) _作業用(値)'!K60 -> 272.14884 | L49: ='4.仕掛品(製品課) _作業用(値)'!AA60/'4.仕掛品(製品課) _作業用(値)'!K60 -> 61.797703 | M49: =SUM(I49:L49) -> 695.85792 | O49: =I49/$G49 -> 1.2657092 | P49: =J49/$G49 -> 1.2302313 | Q49: =K49/$G49 -> 1.8768885 | R49: =L49/$G49 -> 0.42619105 | S49: =M49/$G49 -> 4.7990201 | U49: =ROUND(I49,-1) -> 180 | V49: =ROUND(J49,-1) -> 180 | W49: =ROUND(K49,-1) -> 270 | X49: =ROUND(L49,-1) -> 60 | Y49: =SUM(U49:X49) -> 690
B50: 45 | C50: 20070300033 | D50: 万田酵素 分包150g(販売店向け) | E50: 製品課 | G50: 150 | H50: P | I50: ='4.仕掛品(製品課) _作業用(値)'!E61*'4.仕掛品(製品課) _作業用(値)'!G61 -> 189.85638 | J50: ='4.仕掛品(製品課) _作業用(値)'!U61/'4.仕掛品(製品課) _作業用(値)'!K61 -> 84.105232 | K50: ='4.仕掛品(製品課) _作業用(値)'!W61/'4.仕掛品(製品課) _作業用(値)'!K61 -> 242.79606 | L50: ='4.仕掛品(製品課) _作業用(値)'!AA61/'4.仕掛品(製品課) _作業用(値)'!K61 -> 63.928658 | M50: =SUM(I50:L50) -> 580.68633 | O50: =I50/$G50 -> 1.2657092 | P50: =J50/$G50 -> 0.56070155 | Q50: =K50/$G50 -> 1.6186404 | R50: =L50/$G50 -> 0.42619105 | S50: =M50/$G50 -> 3.8712422 | U50: =ROUND(I50,-1) -> 190 | V50: =ROUND(J50,-1) -> 80 | W50: =ROUND(K50,-1) -> 240 | X50: =ROUND(L50,-1) -> 60 | Y50: =SUM(U50:X50) -> 570
B51: 46 | C51: 20080100023 | D51: 試供品 万田酵素 5g(販売店向け) | E51: 製品課 | G51: 5 | H51: P | I51: ='4.仕掛品(製品課) _作業用(値)'!E62*'4.仕掛品(製品課) _作業用(値)'!G62 -> 6.3285461 | J51: ='4.仕掛品(製品課) _作業用(値)'!U62/'4.仕掛品(製品課) _作業用(値)'!K62 -> 2.8439627 | K51: ='4.仕掛品(製品課) _作業用(値)'!W62/'4.仕掛品(製品課) _作業用(値)'!K62 -> 12.13219 | L51: ='4.仕掛品(製品課) _作業用(値)'!AA62/'4.仕掛品(製品課) _作業用(値)'!K62 -> 2.1309553 | M51: =SUM(I51:L51) -> 23.435654 | O51: =I51/$G51 -> 1.2657092 | P51: =J51/$G51 -> 0.56879254 | Q51: =K51/$G51 -> 2.4264379 | R51: =L51/$G51 -> 0.42619105 | S51: =M51/$G51 -> 4.6871308 | U51: =ROUND(I51,-1) -> 10 | V51: =ROUND(J51,-1) -> 0 | W51: =ROUND(K51,-1) -> 10 | X51: =ROUND(L51,-1) -> 0 | Y51: =SUM(U51:X51) -> 20
B52: 47 | C52: 20090100014 | D52: 万田酵素 300g(販売店限定品) | E52: 製品課 | G52: 300 | H52: P | I52: ='4.仕掛品(製品課) _作業用(値)'!E63*'4.仕掛品(製品課) _作業用(値)'!G63 -> 379.71277 | J52: ='4.仕掛品(製品課) _作業用(値)'!U63/'4.仕掛品(製品課) _作業用(値)'!K63 -> 736.16942 | K52: ='4.仕掛品(製品課) _作業用(値)'!W63/'4.仕掛品(製品課) _作業用(値)'!K63 -> 835.02393 | L52: ='4.仕掛品(製品課) _作業用(値)'!AA63/'4.仕掛品(製品課) _作業用(値)'!K63 -> 127.85732 | M52: =SUM(I52:L52) -> 2078.7634 | O52: =I52/$G52 -> 1.2657092 | P52: =J52/$G52 -> 2.4538981 | Q52: =K52/$G52 -> 2.7834131 | R52: =L52/$G52 -> 0.42619105 | S52: =M52/$G52 -> 6.9292115 | U52: =ROUND(I52,-1) -> 380 | V52: =ROUND(J52,-1) -> 740 | W52: =ROUND(K52,-1) -> 840 | X52: =ROUND(L52,-1) -> 130 | Y52: =SUM(U52:X52) -> 2090
...

Sheet Sheet16
C1: 1 | D1: 2 | E1: 3 | F1: 4 | G1: 5 | H1: 6 | I1: 7 | J1: 8 | K1: 9 | L1: 10 | M1: 11 | N1: 12 | O1: 13 | P1: 14 | Q1: 15 | R1: 16 | S1: 17 | T1: 18 | U1: 19 | V1: 20 | W1: 21 | X1: 22 | Y1: 23 | Z1: 24 | AA1: 25 | AB1: 26 | AC1: 27 | AD1: 28 | AE1: 29 | AF1: 30
C2: 5A | D2: B | E2: BE | F2: BM | G2: C | H2: D | I2: DC | J2: EB | K2: FB | L2: G | M2: GP | N2: KOL | O2: MP | P2: O | Q2: P | R2: PE | S2: PG | T2: PR | U2: PSA | V2: PX | W2: PXM | X2: Q | Y2: T | Z2: V | AA2: X | AB2: XC | AC2: Y | AD2: YA | AE2: YC | AF2: ZA
C3: 2 | D3: 4 | E3: 3 | F3: 1 | G3: 1 | H3: 2 | I3: 2 | J3: 5 | K3: 2 | L3: 2 | M3: 6 | N3: 3 | O3: 8 | P3: 5 | Q3: 14 | R3: 9 | S3: 7 | T3: 2 | U3: 3 | V3: 9 | W3: 3 | X3: 1 | Y3: 4 | Z3: 5 | AA3: 6 | AB3: 3 | AC3: 3 | AD3: 1 | AE3: 1 | AF3: 3 | AG3: =SUM(C3:AF3) -> 120
B4: ='4.仕掛品(製品課) _作業用(値)'!A17 -> 20051200013 | C4: ='4.仕掛品(製品課) _作業用(値)'!B17 -> MKF-Ⅰ 分包150g(AAAAA)
B5: ='4.仕掛品(製品課) _作業用(値)'!A18 -> 20071100007 | C5: ='4.仕掛品(製品課) _作業用(値)'!B18 -> MKF-Ⅰ携帯ﾊﾟｯｸ 50g(5A)
C6: ='4.仕掛品(製品課) _作業用(値)'!A19 -> 20051200005 | D6: ='4.仕掛品(製品課) _作業用(値)'!B19 -> 万田HI酵素 分包150g
C7: ='4.仕掛品(製品課) _作業用(値)'!A20 -> 20071000005 | D7: ='4.仕掛品(製品課) _作業用(値)'!B20 -> 試供品 HI酵素 5g
C8: ='4.仕掛品(製品課) _作業用(値)'!A21 -> 20110800311 | D8: ='4.仕掛品(製品課) _作業用(値)'!B21 -> MANDA HI KOHSO
C9: ='4.仕掛品(製品課) _作業用(値)'!A22 -> 20110800629 | D9: ='4.仕掛品(製品課) _作業用(値)'!B22 -> 万田HI酵素 145g
D10: ='4.仕掛品(製品課) _作業用(値)'!A23 -> 20200800016 | E10: ='4.仕掛品(製品課) _作業用(値)'!B23 -> 万田酵素ｴｸｾﾚﾝﾄ 145g
D11: ='4.仕掛品(製品課) _作業用(値)'!A24 -> 20200800017 | E11: ='4.仕掛品(製品課) _作業用(値)'!B24 -> 万田酵素ｴｸｾﾚﾝﾄ 分包30g（2.5g×12包）
D12: ='4.仕掛品(製品課) _作業用(値)'!A25 -> 20200800018 | E12: ='4.仕掛品(製品課) _作業用(値)'!B25 -> 万田酵素ｴｸｾﾚﾝﾄ 分包450g
E13: ='4.仕掛品(製品課) _作業用(値)'!A26 -> 20240100051 | F13: ='4.仕掛品(製品課) _作業用(値)'!B26 -> 万田酵素 MANUKA HONEY Premium 分包77.5g
F14: ='4.仕掛品(製品課) _作業用(値)'!A27 -> 20110300008 | G14: ='4.仕掛品(製品課) _作業用(値)'!B27 -> Man-Koso CARAT 145g

Sheet 4.仕掛品(製品課) _作業用(値)
A1: 第37期 仕掛品(製品課)
L2: 内容量(g)*数量(個)
F3: 製品記号 | H3: 期首棚卸 | K3: 当期投入 | AE3: 当期商品製造原価 | AH3: 在庫調整 | AJ3: 期末棚卸
H4: 数量 | M4: 仕掛品(製品課製造分) | O4: 仕掛品(外注品内製分) | Q4: 仕掛品(製造部製造分) | S4: 資材費 | V4: 労務費(製品課) | X4: 労務費(製造部) | Z4: 経費 | AB4: 外注加工費 | AC4: 別コードに振替 | AJ4: 数量
A5: SCコード | B5: 商品名 | C5: 区分 | D5: 半製品 | E5: 内容量(g) | F5: 製品記号 | G5: ｸﾞﾗﾑ単価 | H5: 数量 | I5: 進捗度 | J5: 金額 | K5: 数量 | M5: 配賦係数 | N5: 金額 | O5: 配賦係数 | P5: 金額 | Q5: 配賦係数 | R5: 金額 | S5: 包材価格 | T5: 配賦係数 | U5: 金額 | V5: 配賦係数 | W5: 金額 | X5: 配賦係数 | Y5: 金額 | Z5: 配賦係数 | AA5: 金額 | AB5: (原液原価込み) | AC5: 数量 | AD5: 金額 | AE5: 数量 | AF5: 金額 | AG5: 単価 | AH5: 数量 | AI5: 原価 | AJ5: 数量 | AK5: 進捗度 | AL5: 金額 | AO5: 34期資材 | AP5: 34期単価 | AR5: 絞り込み
A6: 20110801161 | B6: BE 2.5g×2 | C6: 半製品 | D6: 半製品 | E6: 5 | F6: BE | G6: 1.6947416 | H6: 3800 | J6: 25204.237 | AJ6: 0 | AL6: 0 | AP6: 7.1801316 | AR6: ok
A7: 20110801267 | B7: EB 2.5g×2 | C7: 半製品 | D7: 半製品 | E7: 5 | F7: EB | G7: 1.3583252 | H7: 4500 | J7: 19728.659 | AJ7: 12600 | AL7: 369655.96 | AP7: 2136.147 | AR7: ok
A8: 20230600090 | B8: 発酵しょうが 2.5g | C8: 半製品 | D8: 半製品 | E8: 2.5 | F8: GP | G8: 1.394799 | H8: 44000 | J8: 107278.15 | AJ8: 100000 | AL8: 753532.73 | AR8: ok
A9: 20180700008 | B9: MULBERRY 2.5g | C9: 半製品 | D9: 半製品 | E9: 2.5 | F9: MP | G9: 1.1798248 | H9: 40000 | J9: 87224.699 | AJ9: 24200 | AL9: 172038.19 | AO9: 1775.9687 | AP9: 7296.6701 | AR9: ok
A10: 20110801273 | B10: P 2.5g×2 | C10: 半製品 | D10: 半製品 | E10: 5 | F10: P | G10: 1.2657092 | H10: 124800 | J10: 599836.36 | AJ10: 52300 | AL10: 670818.01 | AO10: 68.967368 | AP10: 729.09329 | AR10: ok
A11: 20170500057 | B11: GINGER 2.5g | C11: 半製品 | D11: 半製品 | E11: 2.5 | F11: PE | G11: 1.1499334 | H11: 31600 | J11: 67389.992 | AJ11: 18000 | AL11: 125180.49 | AP11: 0 | AR11: ok
A12: 20110801158 | B12: PG 2.5g×2 | C12: 半製品 | D12: 半製品 | E12: 5 | F12: PG | G12: 0 | H12: 180 | J12: 1110.9506 | AJ12: 1350 | AL12: 82945.988 | AP12: 0 | AR12: ok
A13: 20110801164 | B13: ｊPG 2.5g×2 | C13: 半製品 | D13: 半製品 | E13: 5 | F13: PG | G13: 1.4973298 | H13: 900 | J13: 5554.7532 | AJ13: 1800 | AL13: 110594.65 | AP13: 0 | AR13: ok
A14: 20170500058 | B14: STANDARD 2.5g | C14: 半製品 | D14: 半製品 | E14: 2.5 | F14: PX | G14: 1.2530514 | H14: 8400 | J14: 20308.946 | AJ14: 26000 | AL14: 463797.99 | AP14: 0 | AR14: ok
A15: 20110801268 | B15: V 2.5g×2 | C15: 半製品 | D15: 半製品 | E15: 5 | F15: V | G15: 1.2113727 | H15: 0 | J15: 0 | AJ15: 12700 | AL15: 337292.91 | AO15: 594.95854 | AP15: 2504.1591 | AR15: ok
A16: 20110801159 | B16: ZA 2.5g×2 | C16: 半製品 | D16: 半製品 | E16: 5 | F16: ZA | G16: 2.2073146 | H16: 4500 | J16: 37735.653 | AJ16: 0 | AL16: 0 | AP16: 0 | AR16: ok
A17: 20051200013 | B17: MKF-Ⅰ 分包150g(AAAAA) | C17: 製品課 | E17: 150 | F17: 5A | G17: 5.1725294 | H17: 0 | J17: 0 | K17: 814 | L17: =E17*K17 -> 122100 | M17: 631565.83 | N17: 674174.91 | S17: 110.73288 | T17: 90136.568 | U17: 71260.558 | V17: 1600 | W17: 184066.51 | Y17: 0 | Z17: 122100 | AA17: 52037.928 | AE17: 814 | AF17: 981539.91 | AG17: 1205.823 | AH17: 0 | AI17: 0 | AJ17: 0 | AL17: 0 | AO17: 3.0756837 | AP17: 27.221301 | AR17: ok
A18: 20071100007 | B18: MKF-Ⅰ携帯ﾊﾟｯｸ 50g(5A) | C18: 製品課 | E18: 50 | F18: 5A | G18: 5.1725294 | H18: 0 | J18: 0 | K18: 671 | L18: =E18*K18 -> 33550 | M18: 173538.36 | N18: 185246.26 | S18: 63.768813 | T18: 42788.873 | U18: 33828.212 | V18: 915 | W18: 105263.03 | Y18: 0 | Z18: 33550 | AA18: 14298.71 | AE18: 671 | AF18: 338636.22 | AG18: 504.67394 | AH18: 0 | AI18: 0 | AJ18: 0 | AL18: 0 | AP18: 0 | AR18: ok
A19: 20051200005 | B19: 万田HI酵素 分包150g | C19: 製品課 | E19: 150 | F19: B | G19: 1.3486947 | H19: 0 | J19: 0 | K19: 960 | L19: =E19*K19 -> 144000 | M19: 194212.03 | N19: 207314.7 | S19: 422.38363 | T19: 405488.29 | U19: 320572.68 | V19: 2740 | W19: 315213.89 | Y19: 0 | Z19: 144000 | AA19: 61371.512 | AE19: 960 | AF19: 904472.79 | AG19: 942.15915 | AH19: 0 | AI19: 0 | AJ19: 0 | AL19: 0 | AP19: 0 | AR19: ok
A20: 20071000005 | B20: 試供品 HI酵素 5g | C20: 製品課 | E20: 5 | F20: B | G20: 1.3486947 | H20: 0 | J20: 0 | K20: 19500 | L20: =E20*K20 -> 97500 | M20: 131497.73 | N20: 140369.33 | S20: 7.8361921 | T20: 152805.75 | U20: 120805.83 | V20: 2045 | W20: 235260 | Y20: 0 | Z20: 97500 | AA20: 41553.628 | AE20: 19500 | AF20: 537988.79 | AG20: 27.589169 | AH20: 0 | AI20: 0 | AJ20: 0 | AL20: 0 | AO20: 3.4266837 | AP20: 22.183364 | AR20: ok
A21: 20110800311 | B21: MANDA HI KOHSO | C21: 製品課 | E21: 145 | F21: B | G21: 1.3486947 | H21: 0 | J21: 0 | K21: 192 | L21: =E21*K21 -> 27840 | M21: 37547.66 | N21: 40080.842 | S21: 1102.6433 | T21: 211707.5 | U21: 167372.63 | V21: 665 | W21: 76502.642 | Y21: 0 | Z21: 27840 | AA21: 11865.159 | AE21: 192 | AF21: 295821.28 | AG21: 1540.7358 | AH21: 0 | AI21: 0 | AJ21: 0 | AL21: 0 | AP21: 368.28403 | AR21: ok
A22: 20110800629 | B22: 万田HI酵素 145g | C22: 製品課 | E22: 145 | F22: B | G22: 1.3486947 | H22: 0 | J22: 0 | K22: 1470 | L22: =E22*K22 -> 213150 | M22: 287474.27 | N22: 306868.95 | S22: 370.27608 | T22: 544305.84 | U22: 430319.66 | V22: 3735 | W22: 429680.25 | Y22: 0 | Z22: 213150 | AA22: 90842.623 | AE22: 1470 | AF22: 1257711.5 | AG22: 855.58604 | AH22: 0 | AI22: 0 | AJ22: 0 | AL22: 0 | AP22: 477.35077 | AR22: ok
A23: 20200800016 | B23: 万田酵素ｴｸｾﾚﾝﾄ 145g | C23: 製品課 | E23: 145 | F23: BE | G23: 1.6947416 | H23: 0 | J23: 0 | K23: 120 | L23: =E23*K23 -> 17400 | M23: 29488.504 | N23: 31477.969 | S23: 1258.9659 | T23: 151075.91 | U23: 119438.25 | V23: 1495 | W23: 171987.14 | Y23: 0 | Z23: 17400 | AA23: 7415.7243 | AE23: 120 | AF23: 330319.08 | AG23: 2752.659 | AH23: 0 | AI23: 0 | AJ23: 0 | AL23: 0 | AP23: 0 | AR23: ok
A24: 20200800017 | B24: 万田酵素ｴｸｾﾚﾝﾄ 分包30g（2.5g×12包） | C24: 製品課 | E24: 30 | F24: BE | G24: 1.6947416 | H24: 0 | J24: 0 | K24: 1800 | L24: =E24*K24 -> 54000 | M24: 91516.046 | N24: 97690.247 | S24: 119.06788 | T24: 214322.19 | U24: 169439.76 | V24: 2220 | W24: 255392.28 | Y24: 0 | Z24: 54000 | AA24: 23014.317 | AE24: 1800 | AF24: 545536.6 | AG24: 303.07589 | AH24: 0 | AI24: 0 | AJ24: 0 | AL24: 0 | AP24: 820.07323 | AR24: ok
A25: 20200800018 | B25: 万田酵素ｴｸｾﾚﾝﾄ 分包450g | C25: 製品課 | E25: 450 | F25: BE | G25: 1.6947416 | H25: 0 | J25: 0 | K25: 402 | L25: =E25*K25 -> 180900 | M25: 306578.75 | N25: 327262.33 | S25: 1603.6479 | T25: 644666.45 | U25: 509663.19 | V25: 3950 | W25: 454414.19 | Y25: 0 | Z25: 180900 | AA25: 77097.962 | AE25: 402 | AF25: 1368437.7 | AG25: 3404.0738 | AH25: 0 | AI25: 0 | AJ25: 0 | AL25: 0 | AP25: 566.432 | AR25: ok
A26: 20240100051 | B26: 万田酵素 MANUKA HONEY Premium 分包77.5g | C26: 製品課 | E26: 77.5 | F26: BM | G26: 4.5002042 | H26: 0 | J26: 0 | K26: 14700 | L26: =E26*K26 -> 1139250 | M26: 5126857.6 | N26: 5472745.1 | S26: 54.529045 | T26: 801576.97 | U26: 633714.18 | V26: 6700 | W26: 770778.5 | Y26: 0 | Z26: 1139250 | AA26: 485538.16 | AE26: 14700 | AF26: 7362775.9 | AG26: 500.86911 | AH26: 0 | AI26: 0 | AJ26: 0 | AL26: 0 | AO26: 0 | AP26: 130.25509 | AR26: ok
A27: 20110300008 | B27: Man-Koso CARAT 145g | C27: 製品課 | E27: 145 | F27: C | G27: 1.0344858 | H27: 0 | J27: 0 | K27: 163 | L27: =E27*K27 -> 23635 | M27: 24450.072 | N27: 26099.615 | S27: 1776.1255 | T27: 289508.46 | U27: 228880.85 | V27: 1030 | W27: 118492.81 | Y27: 0 | Z27: 23635 | AA27: 10073.026 | AE27: 163 | AF27: 383546.3 | AG27: 2353.0448 | AH27: 0 | AI27: 0 | AJ27: 0 | AL27: 0 | AO27: 371.03526 | AP27: 2226.1295 | AR27: ok
A28: 20200200001 | B28: 万田酵素超熟分包77.5g | C28: 製品課 | E28: 77.5 | F28: D | G28: 1.3499631 | H28: 0 | J28: 0 | K28: 2000 | L28: =E28*K28 -> 155000 | M28: 209244.28 | N28: 223361.1 | S28: 205.08505 | T28: 410170.09 | U28: 324274.04 | V28: 1595 | W28: 183491.3 | Y28: 0 | Z28: 155000 | AA28: 66059.613 | AE28: 2000 | AF28: 797186.06 | AG28: 398.59303 | AH28: 0 | AI28: 0 | AJ28: 0 | AL28: 0 | AN28: 合計チェック | AO28: 0 | AP28: 949.51363 | AR28: ok
A29: 20200200003 | B29: 万田酵素超熟分包2.5g×5 | C29: 製品課 | E29: 12.5 | F29: D | G29: 1.3499631 | H29: 0 | J29: 0 | K29: 300 | L29: =E29*K29 -> 3750 | M29: 5062.3615 | N29: 5403.8977 | S29: 203.84191 | T29: 61152.572 | U29: 48346.264 | V29: 470 | W29: 54069.536 | Y29: 0 | Z29: 3750 | AA29: 1598.2165 | AE29: 300 | AF29: 109417.91 | AG29: 364.72638 | AH29: 0 | AI29: 0 | AJ29: 0 | AL29: 0 | AP29: 0 | AR29: ok
A30: 20211100014 | B30: 特選EXプラス分包70g(2.5g×28包) | C30: 製品課 | E30: 70 | F30: DC | G30: 2.5414453 | H30: 0 | J30: 0 | K30: 5665 | L30: =E30*K30 -> 396550 | M30: 1007810.1 | N30: 1075802.8 | S30: 219.41091 | T30: 1242962.8 | U30: 982666.91 | V30: 8100 | W30: 931836.69 | Y30: 0 | Z30: 396550 | AA30: 169006.06 | AE30: 5665 | AF30: 3159312.5 | AG30: 557.68976 | AH30: 0 | AI30: 0 | AJ30: 0 | AL30: 0 | AP30: 0 | AR30: ok
A31: 20211100015 | B31: 特選EXプラス分包150g(2.5g×60包) | C31: 製品課 | E31: 150 | F31: DC | G31: 2.5414453 | H31: 0 | J31: 0 | K31: 3060 | L31: =E31*K31 -> 459000 | M31: 1166523.4 | N31: 1245223.8 | S31: 371.06034 | T31: 1135444.6 | U31: 897664.73 | V31: 7830 | W31: 900775.47 | Y31: 0 | Z31: 459000 | AA31: 195621.69 | AE31: 3060 | AF31: 3239285.7 | AG31: 1058.5901 | AH31: 0 | AI31: 0 | AJ31: 0 | AL31: 0 | AP31: 209.03947 | AR31: ok
A32: 20071200005 | B32: 試供品 ｽｰﾊﾟｰ万田酵素(赤) 5g | C32: 製品課 | E32: 5 | F32: EB | G32: 1.3583252 | H32: 0 | J32: 0 | K32: 25100 | L32: =E32*K32 -> 125500 | M32: 170469.81 | N32: 181970.68 | S32: 8.6917813 | T32: 218163.71 | U32: 172476.81 | V32: 2855 | W32: 328443.67 | Y32: 0 | Z32: 125500 | AA32: 53486.977 | AE32: 25100 | AF32: 736378.14 | AG32: 29.337775 | AH32: 0 | AI32: 0 | AJ32: 0 | AL32: 0 | AO32: 0 | AP32: 0 | AR32: ok
A33: 20231100072 | B33: ｽｰﾊﾟｰ万田酵素 分包 35g | C33: 製品課 | E33: 35 | F33: EB | G33: 1.3583252 | H33: 0 | J33: 0 | K33: 3400 | L33: =E33*K33 -> 119000 | M33: 161640.69 | N33: 172545.91 | S33: 77.041259 | T33: 261940.28 | U33: 207085.88 | V33: 4435 | W33: 510209.35 | Y33: 0 | Z33: 119000 | AA33: 50716.735 | AE33: 3400 | AF33: 940557.87 | AG33: 276.63467 | AH33: 0 | AI33: 0 | AJ33: 0 | AL33: 0 | AO33: 0 | AP33: 130.25509 | AR33: ok
A34: 20231100073 | B34: ｽｰﾊﾟｰ万田酵素 分包150g | C34: 製品課 | E34: 150 | F34: EB | G34: 1.3583252 | H34: 0 | J34: 0 | K34: 880 | L34: =E34*K34 -> 132000 | M34: 179298.92 | N34: 191395.46 | S34: 201.10053 | T34: 176968.47 | U34: 139908.49 | V34: 2345 | W34: 269772.47 | Y34: 0 | Z34: 132000 | AA34: 56257.219 | AE34: 880 | AF34: 657333.65 | AG34: 746.97005 | AH34: 0 | AI34: 0 | AJ34: 0 | AL34: 0 | AO34: 0 | AP34: 130.25509 | AR34: ok
A35: 20231100074 | B35: ｽｰﾊﾟｰ万田酵素 分包450g | C35: 製品課 | E35: 450 | F35: EB | G35: 1.3583252 | H35: 0 | J35: 0 | K35: 350 | L35: =E35*K35 -> 157500 | M35: 213936.21 | N35: 228369.58 | S35: 1109.6177 | T35: 388366.19 | U35: 307036.22 | V35: 3040 | W35: 349726.36 | Y35: 0 | Z35: 157500 | AA35: 67125.091 | AE35: 350 | AF35: 952257.25 | AG35: 2720.735 | AH35: 0 | AI35: 0 | AJ35: 0 | AL35: 0 | AO35: 0 | AP35: 130.25509 | AR35: ok
A36: 20220600066 | B36: ｺﾞｰﾙﾄﾞEX155g | C36: 製品課 | E36: 155 | F36: FB | G36: 1.8947649 | H36: 0 | J36: 0 | K36: 1392 | L36: =E36*K36 -> 215760 | M36: 408814.48 | N36: 436395.46 | S36: 1525.2944 | T36: 2123209.7 | U36: 1678576.3 | V36: 5260 | W36: 605118.64 | Y36: 0 | Z36: 215760 | AA36: 91954.982 | AE36: 1392 | AF36: 2812045.4 | AG36: 2020.1476 | AH36: 0 | AI36: 0 | AJ36: 0 | AL36: 0 | AP36: 5.3945159 | AR36: ok
A37: 20221200022 | B37: ｺﾞｰﾙﾄﾞEX300g | C37: 製品課 | E37: 300 | F37: FB | G37: 1.8947649 | H37: 0 | J37: 0 | K37: 1080 | L37: =E37*K37 -> 324000 | M37: 613903.83 | N37: 655321.33 | S37: 1351.8023 | T37: 1459946.5 | U37: 1154210.8 | V37: 7075 | W37: 813919.08 | Y37: 0 | Z37: 324000 | AA37: 138085.9 | AE37: 1080 | AF37: 2761537.1 | AG37: 2556.9788 | AH37: 0 | AI37: 0 | AJ37: 0 | AL37: 0 | AP37: 0 | AR37: ok
A38: 20080100003 | B38: 試供品 万田酵素 MJ(5g) | C38: 製品課 | E38: 5 | F38: G | G38: 2.7753038 | H38: 0 | J38: 0 | K38: 1300 | L38: =E38*K38 -> 6500 | M38: 18039.475 | N38: 19256.522 | S38: 7.3021925 | T38: 9492.8502 | U38: 7504.8985 | V38: 225 | W38: 25884.352 | Y38: 0 | Z38: 6500 | AA38: 2770.2418 | AE38: 1300 | AF38: 55416.015 | AG38: 42.627704 | AH38: 0 | AI38: 0 | AJ38: 0 | AL38: 0 | AP38: 0 | AR38: ok
A39: 20110800295 | B39: 万田酵素 MJ | C39: 製品課 | E39: 90 | F39: G | G39: 2.7753038 | H39: 0 | J39: 0 | K39: 468 | L39: =E39*K39 -> 42120 | M39: 116895.8 | N39: 124782.26 | S39: 488.13626 | T39: 228447.77 | U39: 180607.22 | V39: 2295 | W39: 264020.4 | Y39: 0 | Z39: 42120 | AA39: 17951.167 | AE39: 468 | AF39: 587361.05 | AG39: 1255.045 | AH39: 0 | AI39: 0 | AJ39: 0 | AL39: 0 | AP39: 0 | AR39: ok
A40: 20231100078 | B40: 発酵しょうが 2.5g 支給用 | C40: 製品課 | E40: 2.5 | F40: GP | G40: 1.394799 | H40: 0 | J40: 0 | K40: 288000 | L40: =E40*K40 -> 720000 | M40: 1004255.3 | N40: 1072008.1 | S40: 0.43374357 | T40: 124918.15 | U40: 98758.328 | V40: 6020 | W40: 692550.23 | Y40: 0 | Z40: 720000 | AA40: 306857.56 | AE40: 288000 | AF40: 2170174.3 | AG40: 7.5353273 | AH40: 0 | AI40: 0 | AJ40: 0 | AL40: 0 | AR40: ok
...

Sheet 製品課発生原価サマリ
E1: 前工程費単価 | G1: 仕掛品（製品課）原価
E2: 仕掛品（製造部）原価 | H2: 製造費用
E3: グラム単価 | G3: 生産量 | H3: 製造部 | I3: 製品課 | M3: グラム単価 | N3: 製造部＋製品課 | O3: グラム単価 | Q3: check | S3: #製品課発生 グラム単価内訳
E4: 38期実際 | H4: 前工程費 | I4: 資材費 | J4: 労務費 | K4: 経費 | L4: 小計:製品課 | M4: # | N4: 計：製造費用 | S4: 資材費 | T4: 労務費 | U4: 経費
D5: 製品アイテム数 | G5: g | H5: \ | I5: \ | J5: \ | K5: \ | L5: \ | M5: 円/g | N5: \ | O5: 円/g | S5: 円/g | T5: 円/g | U5: 円/g
E6: a | G6: b | H6: c=a*b | I6: d | J6: e | K6: f | L6: h=d+e+f | M6: i=h/b | N6: j=c+h | O6: k=j/b | Q6: c=a*b
A7: 製品課生産分 | B7: 1 | C7: 5A | D7: =COUNTIF('4.仕掛品(製品課) _作業用(値)'!F:F,製品課発生原価サマリ!C7) -> 2 | E7: 5.1725294 | G7: =SUMIF('4.仕掛品(製品課) _作業用(値)'!$F:$F,$C7,'4.仕掛品(製品課) _作業用(値)'!L:L) -> 155650 | H7: =SUMIF('4.仕掛品(製品課) _作業用(値)'!$F:$F,$C7,'4.仕掛品(製品課) _作業用(値)'!M:M) -> 805104.19 | I7: =SUMIF('4.仕掛品(製品課) _作業用(値)'!$F:$F,$C7,'4.仕掛品(製品課) _作業用(値)'!U:U) -> 105088.77 | J7: =SUMIF('4.仕掛品(製品課) _作業用(値)'!$F:$F,$C7,'4.仕掛品(製品課) _作業用(値)'!W:W) -> 289329.54 | K7: =SUMIF('4.仕掛品(製品課) _作業用(値)'!$F:$F,$C7,'4.仕掛品(製品課) _作業用(値)'!AA:AA) -> 66336.638 | L7: =SUM(I7:K7) -> 460754.95 | M7: =L7/G7 -> 2.9601988 | N7: =SUM(H7:K7) -> 1265859.1 | O7: =N7/G7 -> 8.1327282 | Q7: =E7*G7 -> 805104.19 | R7: =H7-Q7 -> 0 | S7: =I7/$G7 -> 0.67516075 | T7: =J7/$G7 -> 1.858847 | U7: =K7/$G7 -> 0.42619105
B8: 2 | C8: B | D8: =COUNTIF('4.仕掛品(製品課) _作業用(値)'!F:F,製品課発生原価サマリ!C8) -> 4 | E8: 1.3486947 | G8: =SUMIF('4.仕掛品(製品課) _作業用(値)'!$F:$F,$C8,'4.仕掛品(製品課) _作業用(値)'!L:L) -> 482490 | H8: =SUMIF('4.仕掛品(製品課) _作業用(値)'!$F:$F,$C8,'4.仕掛品(製品課) _作業用(値)'!M:M) -> 650731.7 | I8: =SUMIF('4.仕掛品(製品課) _作業用(値)'!$F:$F,$C8,'4.仕掛品(製品課) _作業用(値)'!U:U) -> 1039070.8 | J8: =SUMIF('4.仕掛品(製品課) _作業用(値)'!$F:$F,$C8,'4.仕掛品(製品課) _作業用(値)'!W:W) -> 1056656.8 | K8: =SUMIF('4.仕掛品(製品課) _作業用(値)'!$F:$F,$C8,'4.仕掛品(製品課) _作業用(値)'!AA:AA) -> 205632.92 | L8: =SUM(I8:K8) -> 2301360.5 | M8: =L8/G8 -> 4.7697579 | N8: =SUM(H8:K8) -> 2952092.2 | O8: =N8/G8 -> 6.1184526 | Q8: =E8*G8 -> 650731.7 | R8: =H8-Q8 -> 0 | S8: =I8/$G8 -> 2.1535592 | T8: =J8/$G8 -> 2.1900076 | U8: =K8/$G8 -> 0.42619105
B9: 3 | C9: BE | D9: 3 | E9: 1.6947416 | G9: =SUMIF('4.仕掛品(製品課) _作業用(値)'!$F:$F,$C9,'4.仕掛品(製品課) _作業用(値)'!L:L) -> 252300 | H9: =SUMIF('4.仕掛品(製品課) _作業用(値)'!$F:$F,$C9,'4.仕掛品(製品課) _作業用(値)'!M:M) -> 427583.31 | I9: =SUMIF('4.仕掛品(製品課) _作業用(値)'!$F:$F,$C9,'4.仕掛品(製品課) _作業用(値)'!U:U) -> 798541.2 | J9: =SUMIF('4.仕掛品(製品課) _作業用(値)'!$F:$F,$C9,'4.仕掛品(製品課) _作業用(値)'!W:W) -> 881793.61 | K9: =SUMIF('4.仕掛品(製品課) _作業用(値)'!$F:$F,$C9,'4.仕掛品(製品課) _作業用(値)'!AA:AA) -> 107528 | L9: =SUM(I9:K9) -> 1787862.8 | M9: =L9/G9 -> 7.0862577 | N9: =SUM(H9:K9) -> 2215446.1 | O9: =N9/G9 -> 8.7809993 | Q9: =E9*G9 -> 427583.31 | R9: =H9-Q9 -> 0 | S9: =I9/$G9 -> 3.1650464 | T9: =J9/$G9 -> 3.4950202 | U9: =K9/$G9 -> 0.42619105
B10: 4 | C10: BM | D10: =COUNTIF('4.仕掛品(製品課) _作業用(値)'!F:F,製品課発生原価サマリ!C10) -> 1 | E10: 4.5002042 | G10: =SUMIF('4.仕掛品(製品課) _作業用(値)'!$F:$F,$C10,'4.仕掛品(製品課) _作業用(値)'!L:L) -> 1139250 | H10: =SUMIF('4.仕掛品(製品課) _作業用(値)'!$F:$F,$C10,'4.仕掛品(製品課) _作業用(値)'!M:M) -> 5126857.6 | I10: =SUMIF('4.仕掛品(製品課) _作業用(値)'!$F:$F,$C10,'4.仕掛品(製品課) _作業用(値)'!U:U) -> 633714.18 | J10: =SUMIF('4.仕掛品(製品課) _作業用(値)'!$F:$F,$C10,'4.仕掛品(製品課) _作業用(値)'!W:W) -> 770778.5 | K10: =SUMIF('4.仕掛品(製品課) _作業用(値)'!$F:$F,$C10,'4.仕掛品(製品課) _作業用(値)'!AA:AA) -> 485538.16 | L10: =SUM(I10:K10) -> 1890030.8 | M10: =L10/G10 -> 1.6590132 | N10: =SUM(H10:K10) -> 7016888.5 | O10: =N10/G10 -> 6.1592174 | Q10: =E10*G10 -> 5126857.6 | R10: =H10-Q10 -> 0 | S10: =I10/$G10 -> 0.55625559 | T10: =J10/$G10 -> 0.6765666 | U10: =K10/$G10 -> 0.42619105
B11: 5 | C11: C | D11: =COUNTIF('4.仕掛品(製品課) _作業用(値)'!F:F,製品課発生原価サマリ!C11) -> 1 | E11: 1.0344858 | G11: =SUMIF('4.仕掛品(製品課) _作業用(値)'!$F:$F,$C11,'4.仕掛品(製品課) _作業用(値)'!L:L) -> 23635 | H11: =SUMIF('4.仕掛品(製品課) _作業用(値)'!$F:$F,$C11,'4.仕掛品(製品課) _作業用(値)'!M:M) -> 24450.072 | I11: =SUMIF('4.仕掛品(製品課) _作業用(値)'!$F:$F,$C11,'4.仕掛品(製品課) _作業用(値)'!U:U) -> 228880.85 | J11: =SUMIF('4.仕掛品(製品課) _作業用(値)'!$F:$F,$C11,'4.仕掛品(製品課) _作業用(値)'!W:W) -> 118492.81 | K11: =SUMIF('4.仕掛品(製品課) _作業用(値)'!$F:$F,$C11,'4.仕掛品(製品課) _作業用(値)'!AA:AA) -> 10073.026 | L11: =SUM(I11:K11) -> 357446.69 | M11: =L11/G11 -> 15.123617 | N11: =SUM(H11:K11) -> 381896.76 | O11: =N11/G11 -> 16.158103 | Q11: =E11*G11 -> 24450.072 | R11: =H11-Q11 -> 0 | S11: =I11/$G11 -> 9.6839791 | T11: =J11/$G11 -> 5.0134467 | U11: =K11/$G11 -> 0.42619105
B12: 6 | C12: D | D12: =COUNTIF('4.仕掛品(製品課) _作業用(値)'!F:F,製品課発生原価サマリ!C12) -> 2 | E12: 1.3499631 | G12: =SUMIF('4.仕掛品(製品課) _作業用(値)'!$F:$F,$C12,'4.仕掛品(製品課) _作業用(値)'!L:L) -> 158750 | H12: =SUMIF('4.仕掛品(製品課) _作業用(値)'!$F:$F,$C12,'4.仕掛品(製品課) _作業用(値)'!M:M) -> 214306.64 | I12: =SUMIF('4.仕掛品(製品課) _作業用(値)'!$F:$F,$C12,'4.仕掛品(製品課) _作業用(値)'!U:U) -> 372620.31 | J12: =SUMIF('4.仕掛品(製品課) _作業用(値)'!$F:$F,$C12,'4.仕掛品(製品課) _作業用(値)'!W:W) -> 237560.84 | K12: =SUMIF('4.仕掛品(製品課) _作業用(値)'!$F:$F,$C12,'4.仕掛品(製品課) _作業用(値)'!AA:AA) -> 67657.83 | L12: =SUM(I12:K12) -> 677838.97 | M12: =L12/G12 -> 4.2698518 | N12: =SUM(H12:K12) -> 892145.61 | O12: =N12/G12 -> 5.6198149 | Q12: =E12*G12 -> 214306.64 | R12: =H12-Q12 -> 0 | S12: =I12/$G12 -> 2.3472145 | T12: =J12/$G12 -> 1.4964462 | U12: =K12/$G12 -> 0.42619105
B13: 7 | C13: DC | D13: =COUNTIF('4.仕掛品(製品課) _作業用(値)'!F:F,製品課発生原価サマリ!C13) -> 2 | E13: 2.5414453 | G13: =SUMIF('4.仕掛品(製品課) _作業用(値)'!$F:$F,$C13,'4.仕掛品(製品課) _作業用(値)'!L:L) -> 855550 | H13: =SUMIF('4.仕掛品(製品課) _作業用(値)'!$F:$F,$C13,'4.仕掛品(製品課) _作業用(値)'!M:M) -> 2174333.6 | I13: =SUMIF('4.仕掛品(製品課) _作業用(値)'!$F:$F,$C13,'4.仕掛品(製品課) _作業用(値)'!U:U) -> 1880331.6 | J13: =SUMIF('4.仕掛品(製品課) _作業用(値)'!$F:$F,$C13,'4.仕掛品(製品課) _作業用(値)'!W:W) -> 1832612.2 | K13: =SUMIF('4.仕掛品(製品課) _作業用(値)'!$F:$F,$C13,'4.仕掛品(製品課) _作業用(値)'!AA:AA) -> 364627.76 | L13: =SUM(I13:K13) -> 4077571.5 | M13: =L13/G13 -> 4.7660237 | N13: =SUM(H13:K13) -> 6251905.1 | O13: =N13/G13 -> 7.307469 | Q13: =E13*G13 -> 2174333.6 | R13: =H13-Q13 -> 0 | S13: =I13/$G13 -> 2.1978045 | T13: =J13/$G13 -> 2.1420281 | U13: =K13/$G13 -> 0.42619105
B14: 8 | C14: EB | D14: =COUNTIF('4.仕掛品(製品課) _作業用(値)'!F:F,製品課発生原価サマリ!C14) -> 5 | E14: 1.3583252 | G14: =SUMIF('4.仕掛品(製品課) _作業用(値)'!$F:$F,$C14,'4.仕掛品(製品課) _作業用(値)'!L:L) -> 534000 | H14: =SUMIF('4.仕掛品(製品課) _作業用(値)'!$F:$F,$C14,'4.仕掛品(製品課) _作業用(値)'!M:M) -> 725345.63 | I14: =SUMIF('4.仕掛品(製品課) _作業用(値)'!$F:$F,$C14,'4.仕掛品(製品課) _作業用(値)'!U:U) -> 826507.4 | J14: =SUMIF('4.仕掛品(製品課) _作業用(値)'!$F:$F,$C14,'4.仕掛品(製品課) _作業用(値)'!W:W) -> 1458151.9 | K14: =SUMIF('4.仕掛品(製品課) _作業用(値)'!$F:$F,$C14,'4.仕掛品(製品課) _作業用(値)'!AA:AA) -> 227586.02 | L14: =SUM(I14:K14) -> 2512245.3 | M14: =L14/G14 -> 4.7045792 | N14: =SUM(H14:K14) -> 3237590.9 | O14: =N14/G14 -> 6.0629043 | Q14: =E14*G14 -> 725345.63 | R14: =H14-Q14 -> 0 | S14: =I14/$G14 -> 1.5477667 | T14: =J14/$G14 -> 2.7306215 | U14: =K14/$G14 -> 0.42619105
B15: 9 | C15: FB | D15: =COUNTIF('4.仕掛品(製品課) _作業用(値)'!F:F,製品課発生原価サマリ!C15) -> 2 | E15: 1.8947649 | G15: =SUMIF('4.仕掛品(製品課) _作業用(値)'!$F:$F,$C15,'4.仕掛品(製品課) _作業用(値)'!L:L) -> 539760 | H15: =SUMIF('4.仕掛品(製品課) _作業用(値)'!$F:$F,$C15,'4.仕掛品(製品課) _作業用(値)'!M:M) -> 1022718.3 | I15: =SUMIF('4.仕掛品(製品課) _作業用(値)'!$F:$F,$C15,'4.仕掛品(製品課) _作業用(値)'!U:U) -> 2832787.1 | J15: =SUMIF('4.仕掛品(製品課) _作業用(値)'!$F:$F,$C15,'4.仕掛品(製品課) _作業用(値)'!W:W) -> 1419037.7 | K15: =SUMIF('4.仕掛品(製品課) _作業用(値)'!$F:$F,$C15,'4.仕掛品(製品課) _作業用(値)'!AA:AA) -> 230040.88 | L15: =SUM(I15:K15) -> 4481865.7 | M15: =L15/G15 -> 8.3034418 | N15: =SUM(H15:K15) -> 5504584 | O15: =N15/G15 -> 10.198207 | Q15: =E15*G15 -> 1022718.3 | R15: =H15-Q15 -> 0 | S15: =I15/$G15 -> 5.2482346 | T15: =J15/$G15 -> 2.6290161 | U15: =K15/$G15 -> 0.42619105
B16: 10 | C16: G | D16: =COUNTIF('4.仕掛品(製品課) _作業用(値)'!F:F,製品課発生原価サマリ!C16) -> 2 | E16: 2.7753038 | G16: =SUMIF('4.仕掛品(製品課) _作業用(値)'!$F:$F,$C16,'4.仕掛品(製品課) _作業用(値)'!L:L) -> 48620 | H16: =SUMIF('4.仕掛品(製品課) _作業用(値)'!$F:$F,$C16,'4.仕掛品(製品課) _作業用(値)'!M:M) -> 134935.27 | I16: =SUMIF('4.仕掛品(製品課) _作業用(値)'!$F:$F,$C16,'4.仕掛品(製品課) _作業用(値)'!U:U) -> 188112.12 | J16: =SUMIF('4.仕掛品(製品課) _作業用(値)'!$F:$F,$C16,'4.仕掛品(製品課) _作業用(値)'!W:W) -> 289904.75 | K16: =SUMIF('4.仕掛品(製品課) _作業用(値)'!$F:$F,$C16,'4.仕掛品(製品課) _作業用(値)'!AA:AA) -> 20721.409 | L16: =SUM(I16:K16) -> 498738.28 | M16: =L16/G16 -> 10.257883 | N16: =SUM(H16:K16) -> 633673.55 | O16: =N16/G16 -> 13.033187 | Q16: =E16*G16 -> 134935.27 | R16: =H16-Q16 -> 0 | S16: =I16/$G16 -> 3.8690276 | T16: =J16/$G16 -> 5.9626645 | U16: =K16/$G16 -> 0.42619105
B17: 11 | C17: GP | D17: =COUNTIF('4.仕掛品(製品課) _作業用(値)'!F:F,製品課発生原価サマリ!C17) -> 6 | E17: 1.394799 | G17: =SUMIF('4.仕掛品(製品課) _作業用(値)'!$F:$F,$C17,'4.仕掛品(製品課) _作業用(値)'!L:L) -> 16198500 | H17: =SUMIF('4.仕掛品(製品課) _作業用(値)'!$F:$F,$C17,'4.仕掛品(製品課) _作業用(値)'!M:M) -> 22593652 | I17: =SUMIF('4.仕掛品(製品課) _作業用(値)'!$F:$F,$C17,'4.仕掛品(製品課) _作業用(値)'!U:U) -> 6401306.2 | J17: =SUMIF('4.仕掛品(製品課) _作業用(値)'!$F:$F,$C17,'4.仕掛品(製品課) _作業用(値)'!W:W) -> 8308301.9 | K17: =SUMIF('4.仕掛品(製品課) _作業用(値)'!$F:$F,$C17,'4.仕掛品(製品課) _作業用(値)'!AA:AA) -> 6903655.8 | L17: =SUM(I17:K17) -> 21613264 | M17: =L17/G17 -> 1.3342756 | N17: =SUM(H17:K17) -> 44206916 | O17: =N17/G17 -> 2.7290746 | Q17: =E17*G17 -> 22593652 | R17: =H17-Q17 -> 0 | S17: =I17/$G17 -> 0.39517895 | T17: =J17/$G17 -> 0.51290564 | U17: =K17/$G17 -> 0.42619105
B18: 12 | C18: KOL | D18: =COUNTIF('4.仕掛品(製品課) _作業用(値)'!F:F,製品課発生原価サマリ!C18) -> 3 | E18: 1.3000228 | G18: =SUMIF('4.仕掛品(製品課) _作業用(値)'!$F:$F,$C18,'4.仕掛品(製品課) _作業用(値)'!L:L) -> 1104500 | H18: =SUMIF('4.仕掛品(製品課) _作業用(値)'!$F:$F,$C18,'4.仕掛品(製品課) _作業用(値)'!M:M) -> 1435875.2 | I18: =SUMIF('4.仕掛品(製品課) _作業用(値)'!$F:$F,$C18,'4.仕掛品(製品課) _作業用(値)'!U:U) -> 12078614 | J18: =SUMIF('4.仕掛品(製品課) _作業用(値)'!$F:$F,$C18,'4.仕掛品(製品課) _作業用(値)'!W:W) -> 2159905.4 | K18: =SUMIF('4.仕掛品(製品課) _作業用(値)'!$F:$F,$C18,'4.仕掛品(製品課) _作業用(値)'!AA:AA) -> 470728.02 | L18: =SUM(I18:K18) -> 14709248 | M18: =L18/G18 -> 13.317563 | N18: =SUM(H18:K18) -> 16145123 | O18: =N18/G18 -> 14.617585 | Q18: =E18*G18 -> 1435875.2 | R18: =H18-Q18 -> 0 | S18: =I18/$G18 -> 10.935821 | T18: =J18/$G18 -> 1.9555504 | U18: =K18/$G18 -> 0.42619105
B19: 13 | C19: MP | D19: =COUNTIF('4.仕掛品(製品課) _作業用(値)'!F:F,製品課発生原価サマリ!C19) -> 8 | E19: 1.1798248 | G19: =SUMIF('4.仕掛品(製品課) _作業用(値)'!$F:$F,$C19,'4.仕掛品(製品課) _作業用(値)'!L:L) -> 15047750 | H19: =SUMIF('4.仕掛品(製品課) _作業用(値)'!$F:$F,$C19,'4.仕掛品(製品課) _作業用(値)'!M:M) -> 17753708 | I19: =SUMIF('4.仕掛品(製品課) _作業用(値)'!$F:$F,$C19,'4.仕掛品(製品課) _作業用(値)'!U:U) -> 6244723 | J19: =SUMIF('4.仕掛品(製品課) _作業用(値)'!$F:$F,$C19,'4.仕掛品(製品課) _作業用(値)'!W:W) -> 6184634.6 | K19: =SUMIF('4.仕掛品(製品課) _作業用(値)'!$F:$F,$C19,'4.仕掛品(製品課) _作業用(値)'!AA:AA) -> 6413216.4 | L19: =SUM(I19:K19) -> 18842574 | M19: =L19/G19 -> 1.2521855 | N19: =SUM(H19:K19) -> 36596282 | O19: =N19/G19 -> 2.4320103 | Q19: =E19*G19 -> 17753708 | R19: =H19-Q19 -> 0 | S19: =I19/$G19 -> 0.4149938 | T19: =J19/$G19 -> 0.41100062 | U19: =K19/$G19 -> 0.42619105
B20: 14 | C20: O | D20: =COUNTIF('4.仕掛品(製品課) _作業用(値)'!F:F,製品課発生原価サマリ!C20) -> 5 | E20: 1.3228108 | G20: =SUMIF('4.仕掛品(製品課) _作業用(値)'!$F:$F,$C20,'4.仕掛品(製品課) _作業用(値)'!L:L) -> 210550 | H20: =SUMIF('4.仕掛品(製品課) _作業用(値)'!$F:$F,$C20,'4.仕掛品(製品課) _作業用(値)'!M:M) -> 278517.82 | I20: =SUMIF('4.仕掛品(製品課) _作業用(値)'!$F:$F,$C20,'4.仕掛品(製品課) _作業用(値)'!U:U) -> 923675.45 | J20: =SUMIF('4.仕掛品(製品課) _作業用(値)'!$F:$F,$C20,'4.仕掛品(製品課) _作業用(値)'!W:W) -> 501581.23 | K20: =SUMIF('4.仕掛品(製品課) _作業用(値)'!$F:$F,$C20,'4.仕掛品(製品課) _作業用(値)'!AA:AA) -> 89734.526 | L20: =SUM(I20:K20) -> 1514991.2 | M20: =L20/G20 -> 7.1953987 | N20: =SUM(H20:K20) -> 1793509 | O20: =N20/G20 -> 8.5182096 | Q20: =E20*G20 -> 278517.82 | R20: =H20-Q20 -> 0 | S20: =I20/$G20 -> 4.3869648 | T20: =J20/$G20 -> 2.3822428 | U20: =K20/$G20 -> 0.42619105
B21: 15 | C21: P | D21: 14 | E21: 1.2657092 | G21: =SUM('4.仕掛品(製品課) _作業用(値)'!L60:L73) -> 4587955 | H21: =SUMIF('4.仕掛品(製品課) _作業用(値)'!$F:$F,$C21,'4.仕掛品(製品課) _作業用(値)'!M:M) -> 5807016.9 | I21: =SUMIF('4.仕掛品(製品課) _作業用(値)'!$F:$F,$C21,'4.仕掛品(製品課) _作業用(値)'!U:U) -> 7265088.2 | J21: =SUMIF('4.仕掛品(製品課) _作業用(値)'!$F:$F,$C21,'4.仕掛品(製品課) _作業用(値)'!W:W) -> 9126247.5 | K21: =SUMIF('4.仕掛品(製品課) _作業用(値)'!$F:$F,$C21,'4.仕掛品(製品課) _作業用(値)'!AA:AA) -> 1955345.4 | L21: =SUM(I21:K21) -> 18346681 | M21: =L21/G21 -> 3.9988799 | N21: =SUM(H21:K21) -> 24153698 | O21: =N21/G21 -> 5.2645891 | Q21: =E21*G21 -> 5807016.9 | R21: =H21-Q21 -> 0 | S21: =I21/$G21 -> 1.5835134 | T21: =J21/$G21 -> 1.9891755 | U21: =K21/$G21 -> 0.42619105
B22: 16 | C22: PE | D22: =COUNTIF('4.仕掛品(製品課) _作業用(値)'!F:F,製品課発生原価サマリ!C22) -> 9 | E22: 1.1499334 | G22: =SUMIF('4.仕掛品(製品課) _作業用(値)'!$F:$F,$C22,'4.仕掛品(製品課) _作業用(値)'!L:L) -> 33786950 | H22: =SUMIF('4.仕掛品(製品課) _作業用(値)'!$F:$F,$C22,'4.仕掛品(製品課) _作業用(値)'!M:M) -> 38852741 | I22: =SUMIF('4.仕掛品(製品課) _作業用(値)'!$F:$F,$C22,'4.仕掛品(製品課) _作業用(値)'!U:U) -> 11173154 | J22: =SUMIF('4.仕掛品(製品課) _作業用(値)'!$F:$F,$C22,'4.仕掛品(製品課) _作業用(値)'!W:W) -> 14199005 | K22: =SUMIF('4.仕掛品(製品課) _作業用(値)'!$F:$F,$C22,'4.仕掛品(製品課) _作業用(値)'!AA:AA) -> 14399696 | L22: =SUM(I22:K22) -> 39771855 | M22: =L22/G22 -> 1.1771366 | N22: =SUM(H22:K22) -> 78624595 | O22: =N22/G22 -> 2.3270699 | Q22: =E22*G22 -> 38852741 | R22: =H22-Q22 -> 0 | S22: =I22/$G22 -> 0.33069435 | T22: =J22/$G22 -> 0.42025117 | U22: =K22/$G22 -> 0.42619105
B23: 17 | C23: PG | D23: =COUNTIF('4.仕掛品(製品課) _作業用(値)'!F:F,製品課発生原価サマリ!C23) -> 7 | E23: 1.4973298 | G23: =SUMIF('4.仕掛品(製品課) _作業用(値)'!$F:$F,$C23,'4.仕掛品(製品課) _作業用(値)'!L:L) -> 149400 | H23: =SUMIF('4.仕掛品(製品課) _作業用(値)'!$F:$F,$C23,'4.仕掛品(製品課) _作業用(値)'!M:M) -> 223701.07 | I23: =SUMIF('4.仕掛品(製品課) _作業用(値)'!$F:$F,$C23,'4.仕掛品(製品課) _作業用(値)'!U:U) -> 259476.76 | J23: =SUMIF('4.仕掛品(製品課) _作業用(値)'!$F:$F,$C23,'4.仕掛品(製品課) _作業用(値)'!W:W) -> 466493.55 | K23: =SUMIF('4.仕掛品(製品課) _作業用(値)'!$F:$F,$C23,'4.仕掛品(製品課) _作業用(値)'!AA:AA) -> 63672.943 | L23: =SUM(I23:K23) -> 789643.26 | M23: =L23/G23 -> 5.2854301 | N23: =SUM(H23:K23) -> 1013344.3 | O23: =N23/G23 -> 6.7827599 | Q23: =E23*G23 -> 223701.07 | R23: =H23-Q23 -> 0 | S23: =I23/$G23 -> 1.7367922 | T23: =J23/$G23 -> 3.1224468 | U23: =K23/$G23 -> 0.42619105
B24: 18 | C24: PR | D24: =COUNTIF('4.仕掛品(製品課) _作業用(値)'!F:F,製品課発生原価サマリ!C24) -> 2 | E24: 1.8060342 | G24: =SUMIF('4.仕掛品(製品課) _作業用(値)'!$F:$F,$C24,'4.仕掛品(製品課) _作業用(値)'!L:L) -> 465000 | H24: =SUMIF('4.仕掛品(製品課) _作業用(値)'!$F:$F,$C24,'4.仕掛品(製品課) _作業用(値)'!M:M) -> 839805.88 | I24: =SUMIF('4.仕掛品(製品課) _作業用(値)'!$F:$F,$C24,'4.仕掛品(製品課) _作業用(値)'!U:U) -> 13924143 | J24: =SUMIF('4.仕掛品(製品課) _作業用(値)'!$F:$F,$C24,'4.仕掛品(製品課) _作業用(値)'!W:W) -> 1196432.3 | K24: =SUMIF('4.仕掛品(製品課) _作業用(値)'!$F:$F,$C24,'4.仕掛品(製品課) _作業用(値)'!AA:AA) -> 198178.84 | L24: =SUM(I24:K24) -> 15318755 | M24: =L24/G24 -> 32.943558 | N24: =SUM(H24:K24) -> 16158560 | O24: =N24/G24 -> 34.749592 | Q24: =E24*G24 -> 839805.88 | R24: =H24-Q24 -> 0 | S24: =I24/$G24 -> 29.944394 | T24: =J24/$G24 -> 2.5729727 | U24: =K24/$G24 -> 0.42619105
B25: 19 | C25: PSA | D25: =COUNTIF('4.仕掛品(製品課) _作業用(値)'!F:F,製品課発生原価サマリ!C25) -> 3 | E25: 1.7935093 | G25: =SUMIF('4.仕掛品(製品課) _作業用(値)'!$F:$F,$C25,'4.仕掛品(製品課) _作業用(値)'!L:L) -> 1948000 | H25: =SUMIF('4.仕掛品(製品課) _作業用(値)'!$F:$F,$C25,'4.仕掛品(製品課) _作業用(値)'!M:M) -> 3493756 | I25: =SUMIF('4.仕掛品(製品課) _作業用(値)'!$F:$F,$C25,'4.仕掛品(製品課) _作業用(値)'!U:U) -> 2198090.9 | J25: =SUMIF('4.仕掛品(製品課) _作業用(値)'!$F:$F,$C25,'4.仕掛品(製品課) _作業用(値)'!W:W) -> 5310318.7 | K25: =SUMIF('4.仕掛品(製品課) _作業用(値)'!$F:$F,$C25,'4.仕掛品(製品課) _作業用(値)'!AA:AA) -> 830220.17 | L25: =SUM(I25:K25) -> 8338629.8 | M25: =L25/G25 -> 4.2806108 | N25: =SUM(H25:K25) -> 11832386 | O25: =N25/G25 -> 6.0741201 | Q25: =E25*G25 -> 3493756 | R25: =H25-Q25 -> 0 | S25: =I25/$G25 -> 1.1283834 | T25: =J25/$G25 -> 2.7260363 | U25: =K25/$G25 -> 0.42619105
B26: 20 | C26: PX | D26: =COUNTIF('4.仕掛品(製品課) _作業用(値)'!F:F,製品課発生原価サマリ!C26) -> 9 | E26: 1.2530514 | G26: =SUMIF('4.仕掛品(製品課) _作業用(値)'!$F:$F,$C26,'4.仕掛品(製品課) _作業用(値)'!L:L) -> 11305500 | H26: =SUMIF('4.仕掛品(製品課) _作業用(値)'!$F:$F,$C26,'4.仕掛品(製品課) _作業用(値)'!M:M) -> 14166372 | I26: =SUMIF('4.仕掛品(製品課) _作業用(値)'!$F:$F,$C26,'4.仕掛品(製品課) _作業用(値)'!U:U) -> 5200588.8 | J26: =SUMIF('4.仕掛品(製品課) _作業用(値)'!$F:$F,$C26,'4.仕掛品(製品課) _作業用(値)'!W:W) -> 7661193.1 | K26: =SUMIF('4.仕掛品(製品課) _作業用(値)'!$F:$F,$C26,'4.仕掛品(製品課) _作業用(値)'!AA:AA) -> 4818303 | L26: =SUM(I26:K26) -> 17680085 | M26: =L26/G26 -> 1.5638481 | N26: =SUM(H26:K26) -> 31846457 | O26: =N26/G26 -> 2.8168995 | Q26: =E26*G26 -> 14166372 | R26: =H26-Q26 -> 0 | S26: =I26/$G26 -> 0.4600052 | T26: =J26/$G26 -> 0.67765186 | U26: =K26/$G26 -> 0.42619105
B27: 21 | C27: PXM | D27: =COUNTIF('4.仕掛品(製品課) _作業用(値)'!F:F,製品課発生原価サマリ!C27) -> 3 | E27: 4.0081229 | G27: =SUMIF('4.仕掛品(製品課) _作業用(値)'!$F:$F,$C27,'4.仕掛品(製品課) _作業用(値)'!L:L) -> 692250 | H27: =SUMIF('4.仕掛品(製品課) _作業用(値)'!$F:$F,$C27,'4.仕掛品(製品課) _作業用(値)'!M:M) -> 2774623.1 | I27: =SUMIF('4.仕掛品(製品課) _作業用(値)'!$F:$F,$C27,'4.仕掛品(製品課) _作業用(値)'!U:U) -> 883377.84 | J27: =SUMIF('4.仕掛品(製品課) _作業用(値)'!$F:$F,$C27,'4.仕掛品(製品課) _作業用(値)'!W:W) -> 890421.73 | K27: =SUMIF('4.仕掛品(製品課) _作業用(値)'!$F:$F,$C27,'4.仕掛品(製品課) _作業用(値)'!AA:AA) -> 295030.76 | L27: =SUM(I27:K27) -> 2068830.3 | M27: =L27/G27 -> 2.9885595 | N27: =SUM(H27:K27) -> 4843453.4 | O27: =N27/G27 -> 6.9966825 | Q27: =E27*G27 -> 2774623.1 | R27: =H27-Q27 -> 0 | S27: =I27/$G27 -> 1.2760966 | T27: =J27/$G27 -> 1.2862719 | U27: =K27/$G27 -> 0.42619105
B28: 22 | C28: Q | D28: =COUNTIF('4.仕掛品(製品課) _作業用(値)'!F:F,製品課発生原価サマリ!C28) -> 1 | E28: 1.5486311 | G28: =SUMIF('4.仕掛品(製品課) _作業用(値)'!$F:$F,$C28,'4.仕掛品(製品課) _作業用(値)'!L:L) -> 150000 | H28: =SUMIF('4.仕掛品(製品課) _作業用(値)'!$F:$F,$C28,'4.仕掛品(製品課) _作業用(値)'!M:M) -> 232294.67 | I28: =SUMIF('4.仕掛品(製品課) _作業用(値)'!$F:$F,$C28,'4.仕掛品(製品課) _作業用(値)'!U:U) -> 462177.98 | J28: =SUMIF('4.仕掛品(製品課) _作業用(値)'!$F:$F,$C28,'4.仕掛品(製品課) _作業用(値)'!W:W) -> 496979.57 | K28: =SUMIF('4.仕掛品(製品課) _作業用(値)'!$F:$F,$C28,'4.仕掛品(製品課) _作業用(値)'!AA:AA) -> 63928.658 | L28: =SUM(I28:K28) -> 1023086.2 | M28: =L28/G28 -> 6.8205747 | N28: =SUM(H28:K28) -> 1255380.9 | O28: =N28/G28 -> 8.3692059 | Q28: =E28*G28 -> 232294.67 | R28: =H28-Q28 -> 0 | S28: =I28/$G28 -> 3.0811866 | T28: =J28/$G28 -> 3.3131971 | U28: =K28/$G28 -> 0.42619105
B29: 23 | C29: T | D29: 4 | E29: 1.5800702 | G29: =SUM('4.仕掛品(製品課) _作業用(値)'!L104:L107) -> 7735000 | H29: =SUMIF('4.仕掛品(製品課) _作業用(値)'!$F:$F,$C29,'4.仕掛品(製品課) _作業用(値)'!M:M) -> 12221843 | I29: =SUMIF('4.仕掛品(製品課) _作業用(値)'!$F:$F,$C29,'4.仕掛品(製品課) _作業用(値)'!U:U) -> 995809.28 | J29: =SUMIF('4.仕掛品(製品課) _作業用(値)'!$F:$F,$C29,'4.仕掛品(製品課) _作業用(値)'!W:W) -> 2637903.1 | K29: =SUMIF('4.仕掛品(製品課) _作業用(値)'!$F:$F,$C29,'4.仕掛品(製品課) _作業用(値)'!AA:AA) -> 3296587.8 | L29: =SUM(I29:K29) -> 6930300.2 | M29: =L29/G29 -> 0.89596641 | N29: =SUM(H29:K29) -> 19152143 | O29: =N29/G29 -> 2.4760366 | Q29: =E29*G29 -> 12221843 | R29: =H29-Q29 -> 0 | S29: =I29/$G29 -> 0.1287407 | T29: =J29/$G29 -> 0.34103466 | U29: =K29/$G29 -> 0.42619105
B30: 24 | C30: V | D30: =COUNTIF('4.仕掛品(製品課) _作業用(値)'!F:F,製品課発生原価サマリ!C30) -> 5 | E30: 1.2113727 | G30: =SUMIF('4.仕掛品(製品課) _作業用(値)'!$F:$F,$C30,'4.仕掛品(製品課) _作業用(値)'!L:L) -> 519300 | H30: =SUMIF('4.仕掛品(製品課) _作業用(値)'!$F:$F,$C30,'4.仕掛品(製品課) _作業用(値)'!M:M) -> 629065.84 | I30: =SUMIF('4.仕掛品(製品課) _作業用(値)'!$F:$F,$C30,'4.仕掛品(製品課) _作業用(値)'!U:U) -> 1147267.7 | J30: =SUMIF('4.仕掛品(製品課) _作業用(値)'!$F:$F,$C30,'4.仕掛品(製品課) _作業用(値)'!W:W) -> 1456426.2 | K30: =SUMIF('4.仕掛品(製品課) _作業用(値)'!$F:$F,$C30,'4.仕掛品(製品課) _作業用(値)'!AA:AA) -> 221321.01 | L30: =SUM(I30:K30) -> 2825014.9 | M30: =L30/G30 -> 5.4400441 | N30: =SUM(H30:K30) -> 3454080.7 | O30: =N30/G30 -> 6.6514168 | Q30: =E30*G30 -> 629065.84 | R30: =H30-Q30 -> 0 | S30: =I30/$G30 -> 2.209258 | T30: =J30/$G30 -> 2.8045951 | U30: =K30/$G30 -> 0.42619105
