Workbook

Sheet SC決算仕訳 仕掛品
D2: 借方 | H2: 貸方
B3: 原価計算仕訳 | D3: 科目番号 | E3: 科目 | F3: 補助科目 | G3: 金額 | H3: 科目番号 | I3: 科目 | J3: 補助科目 | K3: 金額 | L3: 摘要
B4: ＃5 | D4: 554 | E4: 月末仕掛品棚卸高 | G4: =K4 -> XXX | H4: 135 | I4: 仕掛品 | K4: XXX | L4: 期末（前月末）棚卸振替 原液 | M4: 1月までは毎月労務費経費をそのまま仕掛品に振り替えている（よってどんどん月末仕掛残高が増加する）が、2月からは製造部から期末見込み数量を入手し、当該予定数量に前期の単価をかけてより近い月末仕掛品残高を毎月振り替えている。
B5: ＃5 | D5: 135 | E5: 仕掛品 | G5: =K5 -> 5.3099047e+09 | H5: 505 | I5: 期末仕掛品棚卸高 | K5: =仕掛品SC総括!E19 -> 5.3099047e+09 | L5: 期末棚卸振替 原液
B6: ＃5 | D6: 676 | E6: 試験研究費 | G6: =K6 -> 223806.18 | H6: 505 | I6: 期末材料棚卸高 | K6: =仕掛品SC総括!E15 -> 223806.18 | L6: 期末仕掛品振替 原液研究費
B7: ＃5 | D7: 672 | E7: 販売促進費 | G7: =K7 -> 322538.84 | H7: 505 | I7: 期末材料棚卸高 | K7: =仕掛品SC総括!E16 -> 322538.84 | L7: 期末仕掛品振替 原液販促費
B8: ＃5 | D8: 712 | E8: 雑損失 | G8: =K8 -> 6606711.9 | H8: 505 | I8: 期末材料棚卸高 | K8: =仕掛品SC総括!E17 -> 6606711.9 | L8: 期末仕掛品振替 原液廃棄処分

Sheet 仕掛品SC総括
B2: 数量ベース
B3: 期首 | C3: =仕掛品SC明細!G945 -> 5556625.5 | D3: 半製品へ | E3: =仕掛品SC明細!L945 -> 111416.6
B4: 原材料 | C4: =仕掛品SC明細!H945 -> 114478.11 | D4: 製造部生産分 | E4: =仕掛品SC明細!Q945 -> 65228
B5: 前工程から | C5: =仕掛品SC明細!K945 -> 386681.71 | D5: 試験研究費 | E5: =仕掛品SC明細!M945 -> 162.25
B6: 在庫調整 | C6: =仕掛品SC明細!R945 -> 9682.087 | D6: 販促費 | E6: =仕掛品SC明細!N945 -> 306.7
D7: 廃棄処理 | E7: =仕掛品SC明細!O945 -> 6118.1
D8: 次工程へ | E8: =仕掛品SC明細!P945 -> 400779.63 | F8: 歩減り | G8: =E8-C5 -> 14097.92
D9: 期末在庫 | E9: =仕掛品SC明細!S945 -> 5483456.1
C10: =SUM(C3:C9) -> 6067467.4 | E10: =SUM(E3:E9) -> 6067467.4
B12: 金額ベース
B13: 期首（AC） | C13: =仕掛品SC明細!G946 -> 5.0024282e+09 | D13: 半製品へ | E13: =仕掛品SC明細!L946 -> 1.5673634e+08
B14: 原材料(原材料SCより） | C14: =仕掛品SC明細!H946 -> 83005480 | D14: 製造部生産分 | E14: =仕掛品SC明細!Q946 -> 83224533
B15: 労務費 | C15: =仕掛品SC明細!I946 -> 113594700 | D15: 試験研究費 | E15: =仕掛品SC明細!M946 -> 223806.18
B16: 経費 | C16: =仕掛品SC明細!J946 -> 1.8173356e+08 | D16: 販促費 | E16: =仕掛品SC明細!N946 -> 322538.84
D17: 廃棄処理 | E17: =仕掛品SC明細!O946 -> 6606711.9
B18: 前工程から | D18: 次工程へ
B19: 在庫調整 | C19: =仕掛品SC明細!R946 -> 1830940.7 | D19: 期末在庫 | E19: =仕掛品SC明細!S946 -> 5.3099047e+09
C20: =SUM(C13:C19) -> 5.3825928e+09 | E20: =SUM(E13:E19) -> 5.5570186e+09 | F20: =C20-E20 -> -1.7442575e+08

Sheet 仕掛品SC明細
A1: 第38期 仕掛品(製造課) | U1: 第38期 原液単位原価
A3: 年度 | B3: 番手 | C3: 種類 | D3: 名寄 | E3: SC単価 | G3: 期首棚卸 | H3: 原材料 | I3: 労務費 | J3: 経費 | K3: 前工程費 | L3: 完成品 | M3: 研究費 | N3: 販促費 | O3: 廃棄処分 | P3: 次工程へ | Q3: 製造部 | R3: 在庫調整 | S3: 期末棚卸 | U3: 原液名 | V3: 1ℓ当たりの | W3: 1㎏当たりの | X3: 1g当たりの
Q4: 生産分 | R4: （マイナス＝貸方） | V4: 原液単位原価 | W4: 原液単位原価 | X4: 原液単位原価
A5: S62 | B5: 13 | C5: 13R | D5: =VLOOKUP(C5,'仕掛品名寄（貼付）'!B:C,2,FALSE) -> R | E5: =VLOOKUP(D5,'仕掛品標準単価一覧表（貼付）'!B:G,6,FALSE) -> 908 | F5: 数量 | G5: 510 | H5: =SUMIF('1.3②原材料使用'!B:E,C5,'1.3②原材料使用'!E:E) -> 0 | I5: =SUMIF('2.10原液別作業時間'!A:B,C5,'2.10原液別作業時間'!B:B) -> 0 | J5: =SUM(G5:H5,K5) -> 510 | K5: =SUMIF('2.2⑤純増減→前工程費'!B:E,C5,'2.2⑤純増減→前工程費'!E:E) -> 0 | L5: =SUMIF('2.6完成品'!C:D,C5,'2.6完成品'!D:D) -> 0 | M5: =SUMIF('2.3研究費'!D:E,C5,'2.3研究費'!E:E) -> 0 | N5: =SUMIF('2.4販促費'!D:E,C5,'2.4販促費'!E:E) -> 0 | O5: =SUMIF('2.5廃棄処分'!D:E,C5,'2.5廃棄処分'!E:E) -> 0 | P5: =SUMIF('2.1④異種原液'!D:E,C5,'2.1④異種原液'!E:E) -> 0 | Q5: =SUMIF('2.7製造部生産分'!D:I,C5,'2.7製造部生産分'!H:H) -> 0 | R5: =-(G5+H5+K5-L5-M5-N5-O5-P5-Q5-S5) -> 0 | S5: =SUMIF('2.9原液在庫'!B:H,C5,'2.9原液在庫'!H:H) -> 510 | T5: =IFERROR(SUM(G6:K6)/(G5+H5+K5),0) -> 1046.1796 | U5: =C5 -> 13R | V5: =IF(ISERROR(SUM(G6:K6)/SUM(L5:Q5,S5)),0,SUM(G6:K6)/SUM(L5:Q5,S5)) -> 1046.1796 | W5: =V5 -> 1046.1796 | X5: =W5/1000 -> 1.0461796
F6: 金額 | G6: 518251.59 | I6: =I5*労務費経費単価SC!D$7 -> 0 | J6: =J5*労務費経費単価SC!D$11 -> 15300 | K6: =K5*$E5 -> 0 | L6: =L5*$E5 -> 0 | M6: =M5*$E5 -> 0 | N6: =N5*$E5 -> 0 | O6: =O5*$E5 -> 0 | P6: =P5*$E5 -> 0 | Q6: =Q5*$E5 -> 0 | R6: =R5*$E5 -> 0 | S6: =S5*$E5 -> 463080
A7: S63 | B7: 14 | C7: 14R | D7: =VLOOKUP(C7,'仕掛品名寄（貼付）'!B:C,2,FALSE) -> R | E7: =VLOOKUP(D7,'仕掛品標準単価一覧表（貼付）'!B:G,6,FALSE) -> 908 | F7: 数量 | G7: 840.5 | H7: =SUMIF('1.3②原材料使用'!B:E,C7,'1.3②原材料使用'!E:E) -> 0 | I7: =SUMIF('2.10原液別作業時間'!A:B,C7,'2.10原液別作業時間'!B:B) -> 0 | J7: =SUM(G7:H7,K7) -> 840.5 | K7: =SUMIF('2.2⑤純増減→前工程費'!B:E,C7,'2.2⑤純増減→前工程費'!E:E) -> 0 | L7: =SUMIF('2.6完成品'!C:D,C7,'2.6完成品'!D:D) -> 0 | M7: =SUMIF('2.3研究費'!D:E,C7,'2.3研究費'!E:E) -> 0 | N7: =SUMIF('2.4販促費'!D:E,C7,'2.4販促費'!E:E) -> 0 | O7: =SUMIF('2.5廃棄処分'!D:E,C7,'2.5廃棄処分'!E:E) -> 0 | P7: =SUMIF('2.1④異種原液'!D:E,C7,'2.1④異種原液'!E:E) -> 0 | Q7: =SUMIF('2.7製造部生産分'!D:I,C7,'2.7製造部生産分'!H:H) -> 0 | R7: =-(G7+H7+K7-L7-M7-N7-O7-P7-Q7-S7) -> 0 | S7: =SUMIF('2.9原液在庫'!B:H,C7,'2.9原液在庫'!H:H) -> 840.5 | T7: =IFERROR(SUM(G8:K8)/(G7+H7+K7),0) -> 1059.1737 | U7: =C7 -> 14R | V7: =IF(ISERROR(SUM(G8:K8)/SUM(L7:Q7,S7)),0,SUM(G8:K8)/SUM(L7:Q7,S7)) -> 1059.1737 | W7: =V7 -> 1059.1737 | X7: =W7/1000 -> 1.0591737
F8: 金額 | G8: 865020.52 | I8: =I7*労務費経費単価SC!D$7 -> 0 | J8: =J7*労務費経費単価SC!D$11 -> 25215 | K8: =K7*$E7 -> 0 | L8: =L7*$E7 -> 0 | M8: =M7*$E7 -> 0 | N8: =N7*$E7 -> 0 | O8: =O7*$E7 -> 0 | P8: =P7*$E7 -> 0 | Q8: =Q7*$E7 -> 0 | R8: =R7*$E7 -> 0 | S8: =S7*$E7 -> 763174
C9: 14G | D9: =VLOOKUP(C9,'仕掛品名寄（貼付）'!B:C,2,FALSE) -> G | E9: =VLOOKUP(D9,'仕掛品標準単価一覧表（貼付）'!B:G,6,FALSE) -> 2344.7184 | F9: 数量 | G9: 371 | H9: =SUMIF('1.3②原材料使用'!B:E,C9,'1.3②原材料使用'!E:E) -> 0 | I9: =SUMIF('2.10原液別作業時間'!A:B,C9,'2.10原液別作業時間'!B:B) -> 0 | J9: =SUM(G9:H9,K9) -> 371 | K9: =SUMIF('2.2⑤純増減→前工程費'!B:E,C9,'2.2⑤純増減→前工程費'!E:E) -> 0 | L9: =SUMIF('2.6完成品'!C:D,C9,'2.6完成品'!D:D) -> 0 | M9: =SUMIF('2.3研究費'!D:E,C9,'2.3研究費'!E:E) -> 0 | N9: =SUMIF('2.4販促費'!D:E,C9,'2.4販促費'!E:E) -> 0 | O9: =SUMIF('2.5廃棄処分'!D:E,C9,'2.5廃棄処分'!E:E) -> 0 | P9: =SUMIF('2.1④異種原液'!D:E,C9,'2.1④異種原液'!E:E) -> 0 | Q9: =SUMIF('2.7製造部生産分'!D:I,C9,'2.7製造部生産分'!H:H) -> 0 | R9: =-(G9+H9+K9-L9-M9-N9-O9-P9-Q9-S9) -> 0 | S9: =SUMIF('2.9原液在庫'!B:H,C9,'2.9原液在庫'!H:H) -> 371 | T9: =IFERROR(SUM(G10:K10)/(G9+H9+K9),0) -> 1106.1866 | U9: =C9 -> 14G | V9: =IF(ISERROR(SUM(G10:K10)/SUM(L9:Q9,S9)),0,SUM(G10:K10)/SUM(L9:Q9,S9)) -> 1106.1866 | W9: =V9 -> 1106.1866 | X9: =W9/1000 -> 1.1061866
F10: 金額 | G10: 399265.23 | I10: =I9*労務費経費単価SC!D$7 -> 0 | J10: =J9*労務費経費単価SC!D$11 -> 11130 | K10: =K9*$E9 -> 0 | L10: =L9*$E9 -> 0 | M10: =M9*$E9 -> 0 | N10: =N9*$E9 -> 0 | O10: =O9*$E9 -> 0 | P10: =P9*$E9 -> 0 | Q10: =Q9*$E9 -> 0 | R10: =R9*$E9 -> 0 | S10: =S9*$E9 -> 869890.53
A11: H1 | B11: 15 | C11: 15R | D11: =VLOOKUP(C11,'仕掛品名寄（貼付）'!B:C,2,FALSE) -> R | E11: =VLOOKUP(D11,'仕掛品標準単価一覧表（貼付）'!B:G,6,FALSE) -> 908 | F11: 数量 | G11: 612 | H11: =SUMIF('1.3②原材料使用'!B:E,C11,'1.3②原材料使用'!E:E) -> 0 | I11: =SUMIF('2.10原液別作業時間'!A:B,C11,'2.10原液別作業時間'!B:B) -> 0 | J11: =SUM(G11:H11,K11) -> 612 | K11: =SUMIF('2.2⑤純増減→前工程費'!B:E,C11,'2.2⑤純増減→前工程費'!E:E) -> 0 | L11: =SUMIF('2.6完成品'!C:D,C11,'2.6完成品'!D:D) -> 0 | M11: =SUMIF('2.3研究費'!D:E,C11,'2.3研究費'!E:E) -> 0 | N11: =SUMIF('2.4販促費'!D:E,C11,'2.4販促費'!E:E) -> 0 | O11: =SUMIF('2.5廃棄処分'!D:E,C11,'2.5廃棄処分'!E:E) -> 0 | P11: =SUMIF('2.1④異種原液'!D:E,C11,'2.1④異種原液'!E:E) -> 0 | Q11: =SUMIF('2.7製造部生産分'!D:I,C11,'2.7製造部生産分'!H:H) -> 0 | R11: =-(G11+H11+K11-L11-M11-N11-O11-P11-Q11-S11) -> 0 | S11: =SUMIF('2.9原液在庫'!B:H,C11,'2.9原液在庫'!H:H) -> 612 | T11: =IFERROR(SUM(G12:K12)/(G11+H11+K11),0) -> 1096.5966 | U11: =C11 -> 15R | V11: =IF(ISERROR(SUM(G12:K12)/SUM(L11:Q11,S11)),0,SUM(G12:K12)/SUM(L11:Q11,S11)) -> 1096.5966 | W11: =V11 -> 1096.5966 | X11: =W11/1000 -> 1.0965966
F12: 金額 | G12: 652757.13 | I12: =I11*労務費経費単価SC!D$7 -> 0 | J12: =J11*労務費経費単価SC!D$11 -> 18360 | K12: =K11*$E11 -> 0 | L12: =L11*$E11 -> 0 | M12: =M11*$E11 -> 0 | N12: =N11*$E11 -> 0 | O12: =O11*$E11 -> 0 | P12: =P11*$E11 -> 0 | Q12: =Q11*$E11 -> 0 | R12: =R11*$E11 -> 0 | S12: =S11*$E11 -> 555696
C13: 15HI納 | D13: =VLOOKUP(C13,'仕掛品名寄（貼付）'!B:C,2,FALSE) -> その他 | E13: =VLOOKUP(D13,'仕掛品標準単価一覧表（貼付）'!B:G,6,FALSE) -> 1080 | F13: 数量 | G13: 0 | H13: =SUMIF('1.3②原材料使用'!B:E,C13,'1.3②原材料使用'!E:E) -> 0 | I13: =SUMIF('2.10原液別作業時間'!A:B,C13,'2.10原液別作業時間'!B:B) -> 0 | J13: =SUM(G13:H13,K13) -> 0 | K13: =SUMIF('2.2⑤純増減→前工程費'!B:E,C13,'2.2⑤純増減→前工程費'!E:E) -> 0 | L13: =SUMIF('2.6完成品'!C:D,C13,'2.6完成品'!D:D) -> 0 | M13: =SUMIF('2.3研究費'!D:E,C13,'2.3研究費'!E:E) -> 0 | N13: =SUMIF('2.4販促費'!D:E,C13,'2.4販促費'!E:E) -> 0 | O13: =SUMIF('2.5廃棄処分'!D:E,C13,'2.5廃棄処分'!E:E) -> 0 | P13: =SUMIF('2.1④異種原液'!D:E,C13,'2.1④異種原液'!E:E) -> 0 | Q13: =SUMIF('2.7製造部生産分'!D:I,C13,'2.7製造部生産分'!H:H) -> 0 | R13: =-(G13+H13+K13-L13-M13-N13-O13-P13-Q13-S13) -> 0 | S13: =SUMIF('2.9原液在庫'!B:H,C13,'2.9原液在庫'!H:H) -> 0 | T13: =IFERROR(SUM(G14:K14)/(G13+H13+K13),0) -> 0 | U13: =C13 -> 15HI納 | V13: =IF(ISERROR(SUM(G14:K14)/SUM(L13:Q13,S13)),0,SUM(G14:K14)/SUM(L13:Q13,S13)) -> 0 | W13: =V13 -> 0 | X13: =W13/1000 -> 0
F14: 金額 | I14: =I13*労務費経費単価SC!D$7 -> 0 | J14: =J13*労務費経費単価SC!D$11 -> 0 | K14: =K13*$E13 -> 0 | L14: =L13*$E13 -> 0 | M14: =M13*$E13 -> 0 | N14: =N13*$E13 -> 0 | O14: =O13*$E13 -> 0 | P14: =P13*$E13 -> 0 | Q14: =Q13*$E13 -> 0 | R14: =R13*$E13 -> 0 | S14: =S13*$E13 -> 0
C15: 15R花 | D15: =VLOOKUP(C15,'仕掛品名寄（貼付）'!B:C,2,FALSE) -> その他 | E15: =VLOOKUP(D15,'仕掛品標準単価一覧表（貼付）'!B:G,6,FALSE) -> 1080 | F15: 数量 | G15: 329 | H15: =SUMIF('1.3②原材料使用'!B:E,C15,'1.3②原材料使用'!E:E) -> 0 | I15: =SUMIF('2.10原液別作業時間'!A:B,C15,'2.10原液別作業時間'!B:B) -> 0 | J15: =SUM(G15:H15,K15) -> 329 | K15: =SUMIF('2.2⑤純増減→前工程費'!B:E,C15,'2.2⑤純増減→前工程費'!E:E) -> 0 | L15: =SUMIF('2.6完成品'!C:D,C15,'2.6完成品'!D:D) -> 0 | M15: =SUMIF('2.3研究費'!D:E,C15,'2.3研究費'!E:E) -> 0 | N15: =SUMIF('2.4販促費'!D:E,C15,'2.4販促費'!E:E) -> 0 | O15: =SUMIF('2.5廃棄処分'!D:E,C15,'2.5廃棄処分'!E:E) -> 0 | P15: =SUMIF('2.1④異種原液'!D:E,C15,'2.1④異種原液'!E:E) -> 0 | Q15: =SUMIF('2.7製造部生産分'!D:I,C15,'2.7製造部生産分'!H:H) -> 0 | R15: =-(G15+H15+K15-L15-M15-N15-O15-P15-Q15-S15) -> 0 | S15: =SUMIF('2.9原液在庫'!B:H,C15,'2.9原液在庫'!H:H) -> 329 | T15: =IFERROR(SUM(G16:K16)/(G15+H15+K15),0) -> 1082.909 | U15: =C15 -> 15R花 | V15: =IF(ISERROR(SUM(G16:K16)/SUM(L15:Q15,S15)),0,SUM(G16:K16)/SUM(L15:Q15,S15)) -> 1082.909 | W15: =V15 -> 1082.909 | X15: =W15/1000 -> 1.082909
F16: 金額 | G16: 346407.05 | I16: =I15*労務費経費単価SC!D$7 -> 0 | J16: =J15*労務費経費単価SC!D$11 -> 9870 | K16: =K15*$E15 -> 0 | L16: =L15*$E15 -> 0 | M16: =M15*$E15 -> 0 | N16: =N15*$E15 -> 0 | O16: =O15*$E15 -> 0 | P16: =P15*$E15 -> 0 | Q16: =Q15*$E15 -> 0 | R16: =R15*$E15 -> 0 | S16: =S15*$E15 -> 355320
C17: 15R納 | D17: =VLOOKUP(C17,'仕掛品名寄（貼付）'!B:C,2,FALSE) -> その他 | E17: =VLOOKUP(D17,'仕掛品標準単価一覧表（貼付）'!B:G,6,FALSE) -> 1080 | F17: 数量 | G17: 708 | H17: =SUMIF('1.3②原材料使用'!B:E,C17,'1.3②原材料使用'!E:E) -> 0 | I17: =SUMIF('2.10原液別作業時間'!A:B,C17,'2.10原液別作業時間'!B:B) -> 0 | J17: =SUM(G17:H17,K17) -> 708 | K17: =SUMIF('2.2⑤純増減→前工程費'!B:E,C17,'2.2⑤純増減→前工程費'!E:E) -> 0 | L17: =SUMIF('2.6完成品'!C:D,C17,'2.6完成品'!D:D) -> 0 | M17: =SUMIF('2.3研究費'!D:E,C17,'2.3研究費'!E:E) -> 0 | N17: =SUMIF('2.4販促費'!D:E,C17,'2.4販促費'!E:E) -> 0 | O17: =SUMIF('2.5廃棄処分'!D:E,C17,'2.5廃棄処分'!E:E) -> 0 | P17: =SUMIF('2.1④異種原液'!D:E,C17,'2.1④異種原液'!E:E) -> 0 | Q17: =SUMIF('2.7製造部生産分'!D:I,C17,'2.7製造部生産分'!H:H) -> 0 | R17: =-(G17+H17+K17-L17-M17-N17-O17-P17-Q17-S17) -> 0 | S17: =SUMIF('2.9原液在庫'!B:H,C17,'2.9原液在庫'!H:H) -> 708 | T17: =IFERROR(SUM(G18:K18)/(G17+H17+K17),0) -> 271.25443 | U17: =C17 -> 15R納 | V17: =IF(ISERROR(SUM(G18:K18)/SUM(L17:Q17,S17)),0,SUM(G18:K18)/SUM(L17:Q17,S17)) -> 271.25443 | W17: =V17 -> 271.25443 | X17: =W17/1000 -> 0.27125443
F18: 金額 | G18: 170808.14 | I18: =I17*労務費経費単価SC!D$7 -> 0 | J18: =J17*労務費経費単価SC!D$11 -> 21240 | K18: =K17*$E17 -> 0 | L18: =L17*$E17 -> 0 | M18: =M17*$E17 -> 0 | N18: =N17*$E17 -> 0 | O18: =O17*$E17 -> 0 | P18: =P17*$E17 -> 0 | Q18: =Q17*$E17 -> 0 | R18: =R17*$E17 -> 0 | S18: =S17*$E17 -> 764640
C19: 15Rｶ | D19: =VLOOKUP(C19,'仕掛品名寄（貼付）'!B:C,2,FALSE) -> その他 | E19: =VLOOKUP(D19,'仕掛品標準単価一覧表（貼付）'!B:G,6,FALSE) -> 1080 | F19: 数量 | G19: 286.5 | H19: =SUMIF('1.3②原材料使用'!B:E,C19,'1.3②原材料使用'!E:E) -> 0 | I19: =SUMIF('2.10原液別作業時間'!A:B,C19,'2.10原液別作業時間'!B:B) -> 0 | J19: =SUM(G19:H19,K19) -> 286.5 | K19: =SUMIF('2.2⑤純増減→前工程費'!B:E,C19,'2.2⑤純増減→前工程費'!E:E) -> 0 | L19: =SUMIF('2.6完成品'!C:D,C19,'2.6完成品'!D:D) -> 0 | M19: =SUMIF('2.3研究費'!D:E,C19,'2.3研究費'!E:E) -> 0 | N19: =SUMIF('2.4販促費'!D:E,C19,'2.4販促費'!E:E) -> 0 | O19: =SUMIF('2.5廃棄処分'!D:E,C19,'2.5廃棄処分'!E:E) -> 0 | P19: =SUMIF('2.1④異種原液'!D:E,C19,'2.1④異種原液'!E:E) -> 0 | Q19: =SUMIF('2.7製造部生産分'!D:I,C19,'2.7製造部生産分'!H:H) -> 0 | R19: =-(G19+H19+K19-L19-M19-N19-O19-P19-Q19-S19) -> 0 | S19: =SUMIF('2.9原液在庫'!B:H,C19,'2.9原液在庫'!H:H) -> 286.5 | T19: =IFERROR(SUM(G20:K20)/(G19+H19+K19),0) -> 1054.1858 | U19: =C19 -> 15Rｶ | V19: =IF(ISERROR(SUM(G20:K20)/SUM(L19:Q19,S19)),0,SUM(G20:K20)/SUM(L19:Q19,S19)) -> 1054.1858 | W19: =V19 -> 1054.1858 | X19: =W19/1000 -> 1.0541858
F20: 金額 | G20: 293429.24 | I20: =I19*労務費経費単価SC!D$7 -> 0 | J20: =J19*労務費経費単価SC!D$11 -> 8595 | K20: =K19*$E19 -> 0 | L20: =L19*$E19 -> 0 | M20: =M19*$E19 -> 0 | N20: =N19*$E19 -> 0 | O20: =O19*$E19 -> 0 | P20: =P19*$E19 -> 0 | Q20: =Q19*$E19 -> 0 | R20: =R19*$E19 -> 0 | S20: =S19*$E19 -> 309420
C21: 15R海 | D21: =VLOOKUP(C21,'仕掛品名寄（貼付）'!B:C,2,FALSE) -> その他 | E21: =VLOOKUP(D21,'仕掛品標準単価一覧表（貼付）'!B:G,6,FALSE) -> 1080 | F21: 数量 | G21: 289.5 | H21: =SUMIF('1.3②原材料使用'!B:E,C21,'1.3②原材料使用'!E:E) -> 0 | I21: =SUMIF('2.10原液別作業時間'!A:B,C21,'2.10原液別作業時間'!B:B) -> 0 | J21: =SUM(G21:H21,K21) -> 289.5 | K21: =SUMIF('2.2⑤純増減→前工程費'!B:E,C21,'2.2⑤純増減→前工程費'!E:E) -> 0 | L21: =SUMIF('2.6完成品'!C:D,C21,'2.6完成品'!D:D) -> 0 | M21: =SUMIF('2.3研究費'!D:E,C21,'2.3研究費'!E:E) -> 0 | N21: =SUMIF('2.4販促費'!D:E,C21,'2.4販促費'!E:E) -> 10 | O21: =SUMIF('2.5廃棄処分'!D:E,C21,'2.5廃棄処分'!E:E) -> 0 | P21: =SUMIF('2.1④異種原液'!D:E,C21,'2.1④異種原液'!E:E) -> 0 | Q21: =SUMIF('2.7製造部生産分'!D:I,C21,'2.7製造部生産分'!H:H) -> 0 | R21: =-(G21+H21+K21-L21-M21-N21-O21-P21-Q21-S21) -> 0 | S21: =SUMIF('2.9原液在庫'!B:H,C21,'2.9原液在庫'!H:H) -> 279.5 | T21: =IFERROR(SUM(G22:K22)/(G21+H21+K21),0) -> 1164.4984 | U21: =C21 -> 15R海 | V21: =IF(ISERROR(SUM(G22:K22)/SUM(L21:Q21,S21)),0,SUM(G22:K22)/SUM(L21:Q21,S21)) -> 1164.4984 | W21: =V21 -> 1164.4984 | X21: =W21/1000 -> 1.1644984
F22: 金額 | G22: 328437.28 | I22: =I21*労務費経費単価SC!D$7 -> 0 | J22: =J21*労務費経費単価SC!D$11 -> 8685 | K22: =K21*$E21 -> 0 | L22: =L21*$E21 -> 0 | M22: =M21*$E21 -> 0 | N22: =N21*$E21 -> 10800 | O22: =O21*$E21 -> 0 | P22: =P21*$E21 -> 0 | Q22: =Q21*$E21 -> 0 | R22: =R21*$E21 -> 0 | S22: =S21*$E21 -> 301860
C23: 15RB海 | D23: =VLOOKUP(C23,'仕掛品名寄（貼付）'!B:C,2,FALSE) -> その他 | E23: =VLOOKUP(D23,'仕掛品標準単価一覧表（貼付）'!B:G,6,FALSE) -> 1080 | F23: 数量 | G23: 0 | H23: =SUMIF('1.3②原材料使用'!B:E,C23,'1.3②原材料使用'!E:E) -> 0 | I23: =SUMIF('2.10原液別作業時間'!A:B,C23,'2.10原液別作業時間'!B:B) -> 0 | J23: =SUM(G23:H23,K23) -> 0 | K23: =SUMIF('2.2⑤純増減→前工程費'!B:E,C23,'2.2⑤純増減→前工程費'!E:E) -> 0 | L23: =SUMIF('2.6完成品'!C:D,C23,'2.6完成品'!D:D) -> 0 | M23: =SUMIF('2.3研究費'!D:E,C23,'2.3研究費'!E:E) -> 0 | N23: =SUMIF('2.4販促費'!D:E,C23,'2.4販促費'!E:E) -> 0 | O23: =SUMIF('2.5廃棄処分'!D:E,C23,'2.5廃棄処分'!E:E) -> 0 | P23: =SUMIF('2.1④異種原液'!D:E,C23,'2.1④異種原液'!E:E) -> 0 | Q23: =SUMIF('2.7製造部生産分'!D:I,C23,'2.7製造部生産分'!H:H) -> 0 | R23: =-(G23+H23+K23-L23-M23-N23-O23-P23-Q23-S23) -> 0 | S23: =SUMIF('2.9原液在庫'!B:H,C23,'2.9原液在庫'!H:H) -> 0 | T23: =IFERROR(SUM(G24:K24)/(G23+H23+K23),0) -> 0 | U23: =C23 -> 15RB海 | V23: =IF(ISERROR(SUM(G24:K24)/SUM(L23:Q23,S23)),0,SUM(G24:K24)/SUM(L23:Q23,S23)) -> 0 | W23: =V23 -> 0 | X23: =W23/1000 -> 0
F24: 金額 | I24: =I23*労務費経費単価SC!D$7 -> 0 | J24: =J23*労務費経費単価SC!D$11 -> 0 | K24: =K23*$E23 -> 0 | L24: =L23*$E23 -> 0 | M24: =M23*$E23 -> 0 | N24: =N23*$E23 -> 0 | O24: =O23*$E23 -> 0 | P24: =P23*$E23 -> 0 | Q24: =Q23*$E23 -> 0 | R24: =R23*$E23 -> 0 | S24: =S23*$E23 -> 0
C25: 15HI | D25: =VLOOKUP(C25,'仕掛品名寄（貼付）'!B:C,2,FALSE) -> HI | E25: =VLOOKUP(D25,'仕掛品標準単価一覧表（貼付）'!B:G,6,FALSE) -> 1176 | F25: 数量 | G25: 892 | H25: =SUMIF('1.3②原材料使用'!B:E,C25,'1.3②原材料使用'!E:E) -> 0 | I25: =SUMIF('2.10原液別作業時間'!A:B,C25,'2.10原液別作業時間'!B:B) -> 0 | J25: =SUM(G25:H25,K25) -> 892 | K25: =SUMIF('2.2⑤純増減→前工程費'!B:E,C25,'2.2⑤純増減→前工程費'!E:E) -> 0 | L25: =SUMIF('2.6完成品'!C:D,C25,'2.6完成品'!D:D) -> 0 | M25: =SUMIF('2.3研究費'!D:E,C25,'2.3研究費'!E:E) -> 0 | N25: =SUMIF('2.4販促費'!D:E,C25,'2.4販促費'!E:E) -> 0 | O25: =SUMIF('2.5廃棄処分'!D:E,C25,'2.5廃棄処分'!E:E) -> 0 | P25: =SUMIF('2.1④異種原液'!D:E,C25,'2.1④異種原液'!E:E) -> 0 | Q25: =SUMIF('2.7製造部生産分'!D:I,C25,'2.7製造部生産分'!H:H) -> 0 | R25: =-(G25+H25+K25-L25-M25-N25-O25-P25-Q25-S25) -> 0 | S25: =SUMIF('2.9原液在庫'!B:H,C25,'2.9原液在庫'!H:H) -> 892 | T25: =IFERROR(SUM(G26:K26)/(G25+H25+K25),0) -> 1102.4369 | U25: =C25 -> 15HI | V25: =IF(ISERROR(SUM(G26:K26)/SUM(L25:Q25,S25)),0,SUM(G26:K26)/SUM(L25:Q25,S25)) -> 1102.4369 | W25: =V25 -> 1102.4369 | X25: =W25/1000 -> 1.1024369
F26: 金額 | G26: 956613.76 | I26: =I25*労務費経費単価SC!D$7 -> 0 | J26: =J25*労務費経費単価SC!D$11 -> 26760 | K26: =K25*$E25 -> 0 | L26: =L25*$E25 -> 0 | M26: =M25*$E25 -> 0 | N26: =N25*$E25 -> 0 | O26: =O25*$E25 -> 0 | P26: =P25*$E25 -> 0 | Q26: =Q25*$E25 -> 0 | R26: =R25*$E25 -> 0 | S26: =S25*$E25 -> 1048992
C27: 15HIﾆ | D27: =VLOOKUP(C27,'仕掛品名寄（貼付）'!B:C,2,FALSE) -> その他 | E27: =VLOOKUP(D27,'仕掛品標準単価一覧表（貼付）'!B:G,6,FALSE) -> 1080 | F27: 数量 | G27: 1154.5 | H27: =SUMIF('1.3②原材料使用'!B:E,C27,'1.3②原材料使用'!E:E) -> 0 | I27: =SUMIF('2.10原液別作業時間'!A:B,C27,'2.10原液別作業時間'!B:B) -> 0 | J27: =SUM(G27:H27,K27) -> 1154.5 | K27: =SUMIF('2.2⑤純増減→前工程費'!B:E,C27,'2.2⑤純増減→前工程費'!E:E) -> 0 | L27: =SUMIF('2.6完成品'!C:D,C27,'2.6完成品'!D:D) -> 0 | M27: =SUMIF('2.3研究費'!D:E,C27,'2.3研究費'!E:E) -> 0 | N27: =SUMIF('2.4販促費'!D:E,C27,'2.4販促費'!E:E) -> 0 | O27: =SUMIF('2.5廃棄処分'!D:E,C27,'2.5廃棄処分'!E:E) -> 0 | P27: =SUMIF('2.1④異種原液'!D:E,C27,'2.1④異種原液'!E:E) -> 0 | Q27: =SUMIF('2.7製造部生産分'!D:I,C27,'2.7製造部生産分'!H:H) -> 0 | R27: =-(G27+H27+K27-L27-M27-N27-O27-P27-Q27-S27) -> 0 | S27: =SUMIF('2.9原液在庫'!B:H,C27,'2.9原液在庫'!H:H) -> 1154.5 | T27: =IFERROR(SUM(G28:K28)/(G27+H27+K27),0) -> 1082.1402 | U27: =C27 -> 15HIﾆ | V27: =IF(ISERROR(SUM(G28:K28)/SUM(L27:Q27,S27)),0,SUM(G28:K28)/SUM(L27:Q27,S27)) -> 1082.1402 | W27: =V27 -> 1082.1402 | X27: =W27/1000 -> 1.0821402
F28: 金額 | G28: 1214695.8 | I28: =I27*労務費経費単価SC!D$7 -> 0 | J28: =J27*労務費経費単価SC!D$11 -> 34635 | K28: =K27*$E27 -> 0 | L28: =L27*$E27 -> 0 | M28: =M27*$E27 -> 0 | N28: =N27*$E27 -> 0 | O28: =O27*$E27 -> 0 | P28: =P27*$E27 -> 0 | Q28: =Q27*$E27 -> 0 | R28: =R27*$E27 -> 0 | S28: =S27*$E27 -> 1246860
C29: 15HI海 | D29: =VLOOKUP(C29,'仕掛品名寄（貼付）'!B:C,2,FALSE) -> その他 | E29: =VLOOKUP(D29,'仕掛品標準単価一覧表（貼付）'!B:G,6,FALSE) -> 1080 | F29: 数量 | G29: 0 | H29: =SUMIF('1.3②原材料使用'!B:E,C29,'1.3②原材料使用'!E:E) -> 0 | I29: =SUMIF('2.10原液別作業時間'!A:B,C29,'2.10原液別作業時間'!B:B) -> 0 | J29: =SUM(G29:H29,K29) -> 0 | K29: =SUMIF('2.2⑤純増減→前工程費'!B:E,C29,'2.2⑤純増減→前工程費'!E:E) -> 0 | L29: =SUMIF('2.6完成品'!C:D,C29,'2.6完成品'!D:D) -> 0 | M29: =SUMIF('2.3研究費'!D:E,C29,'2.3研究費'!E:E) -> 0 | N29: =SUMIF('2.4販促費'!D:E,C29,'2.4販促費'!E:E) -> 0 | O29: =SUMIF('2.5廃棄処分'!D:E,C29,'2.5廃棄処分'!E:E) -> 0 | P29: =SUMIF('2.1④異種原液'!D:E,C29,'2.1④異種原液'!E:E) -> 0 | Q29: =SUMIF('2.7製造部生産分'!D:I,C29,'2.7製造部生産分'!H:H) -> 0 | R29: =-(G29+H29+K29-L29-M29-N29-O29-P29-Q29-S29) -> 0 | S29: =SUMIF('2.9原液在庫'!B:H,C29,'2.9原液在庫'!H:H) -> 0 | T29: =IFERROR(SUM(G30:K30)/(G29+H29+K29),0) -> 0 | U29: =C29 -> 15HI海 | V29: =IF(ISERROR(SUM(G30:K30)/SUM(L29:Q29,S29)),0,SUM(G30:K30)/SUM(L29:Q29,S29)) -> 0 | W29: =V29 -> 0 | X29: =W29/1000 -> 0
F30: 金額 | I30: =I29*労務費経費単価SC!D$7 -> 0 | J30: =J29*労務費経費単価SC!D$11 -> 0 | K30: =K29*$E29 -> 0 | L30: =L29*$E29 -> 0 | M30: =M29*$E29 -> 0 | N30: =N29*$E29 -> 0 | O30: =O29*$E29 -> 0 | P30: =P29*$E29 -> 0 | Q30: =Q29*$E29 -> 0 | R30: =R29*$E29 -> 0 | S30: =S29*$E29 -> 0
C31: 15HI海ｸ | D31: =VLOOKUP(C31,'仕掛品名寄（貼付）'!B:C,2,FALSE) -> その他 | E31: =VLOOKUP(D31,'仕掛品標準単価一覧表（貼付）'!B:G,6,FALSE) -> 1080 | F31: 数量 | G31: 0 | H31: =SUMIF('1.3②原材料使用'!B:E,C31,'1.3②原材料使用'!E:E) -> 0 | I31: =SUMIF('2.10原液別作業時間'!A:B,C31,'2.10原液別作業時間'!B:B) -> 0 | J31: =SUM(G31:H31,K31) -> 0 | K31: =SUMIF('2.2⑤純増減→前工程費'!B:E,C31,'2.2⑤純増減→前工程費'!E:E) -> 0 | L31: =SUMIF('2.6完成品'!C:D,C31,'2.6完成品'!D:D) -> 0 | M31: =SUMIF('2.3研究費'!D:E,C31,'2.3研究費'!E:E) -> 0 | N31: =SUMIF('2.4販促費'!D:E,C31,'2.4販促費'!E:E) -> 0 | O31: =SUMIF('2.5廃棄処分'!D:E,C31,'2.5廃棄処分'!E:E) -> 0 | P31: =SUMIF('2.1④異種原液'!D:E,C31,'2.1④異種原液'!E:E) -> 0 | Q31: =SUMIF('2.7製造部生産分'!D:I,C31,'2.7製造部生産分'!H:H) -> 0 | R31: =-(G31+H31+K31-L31-M31-N31-O31-P31-Q31-S31) -> 0 | S31: =SUMIF('2.9原液在庫'!B:H,C31,'2.9原液在庫'!H:H) -> 0 | T31: =IFERROR(SUM(G32:K32)/(G31+H31+K31),0) -> 0 | U31: =C31 -> 15HI海ｸ | V31: =IF(ISERROR(SUM(G32:K32)/SUM(L31:Q31,S31)),0,SUM(G32:K32)/SUM(L31:Q31,S31)) -> 0 | W31: =V31 -> 0 | X31: =W31/1000 -> 0
F32: 金額 | I32: =I31*労務費経費単価SC!D$7 -> 0 | J32: =J31*労務費経費単価SC!D$11 -> 0 | K32: =K31*$E31 -> 0 | L32: =L31*$E31 -> 0 | M32: =M31*$E31 -> 0 | N32: =N31*$E31 -> 0 | O32: =O31*$E31 -> 0 | P32: =P31*$E31 -> 0 | Q32: =Q31*$E31 -> 0 | R32: =R31*$E31 -> 0 | S32: =S31*$E31 -> 0
C33: 15HI海ｸﾄ | D33: =VLOOKUP(C33,'仕掛品名寄（貼付）'!B:C,2,FALSE) -> その他 | E33: =VLOOKUP(D33,'仕掛品標準単価一覧表（貼付）'!B:G,6,FALSE) -> 1080 | F33: 数量 | G33: 0 | H33: =SUMIF('1.3②原材料使用'!B:E,C33,'1.3②原材料使用'!E:E) -> 0 | I33: =SUMIF('2.10原液別作業時間'!A:B,C33,'2.10原液別作業時間'!B:B) -> 0 | J33: =SUM(G33:H33,K33) -> 0 | K33: =SUMIF('2.2⑤純増減→前工程費'!B:E,C33,'2.2⑤純増減→前工程費'!E:E) -> 0 | L33: =SUMIF('2.6完成品'!C:D,C33,'2.6完成品'!D:D) -> 0 | M33: =SUMIF('2.3研究費'!D:E,C33,'2.3研究費'!E:E) -> 0 | N33: =SUMIF('2.4販促費'!D:E,C33,'2.4販促費'!E:E) -> 0 | O33: =SUMIF('2.5廃棄処分'!D:E,C33,'2.5廃棄処分'!E:E) -> 0 | P33: =SUMIF('2.1④異種原液'!D:E,C33,'2.1④異種原液'!E:E) -> 0 | Q33: =SUMIF('2.7製造部生産分'!D:I,C33,'2.7製造部生産分'!H:H) -> 0 | R33: =-(G33+H33+K33-L33-M33-N33-O33-P33-Q33-S33) -> 0 | S33: =SUMIF('2.9原液在庫'!B:H,C33,'2.9原液在庫'!H:H) -> 0 | T33: =IFERROR(SUM(G34:K34)/(G33+H33+K33),0) -> 0 | U33: =C33 -> 15HI海ｸﾄ | V33: =IF(ISERROR(SUM(G34:K34)/SUM(L33:Q33,S33)),0,SUM(G34:K34)/SUM(L33:Q33,S33)) -> 0 | W33: =V33 -> 0 | X33: =W33/1000 -> 0
F34: 金額 | I34: =I33*労務費経費単価SC!D$7 -> 0 | J34: =J33*労務費経費単価SC!D$11 -> 0 | K34: =K33*$E33 -> 0 | L34: =L33*$E33 -> 0 | M34: =M33*$E33 -> 0 | N34: =N33*$E33 -> 0 | O34: =O33*$E33 -> 0 | P34: =P33*$E33 -> 0 | Q34: =Q33*$E33 -> 0 | R34: =R33*$E33 -> 0 | S34: =S33*$E33 -> 0
C35: 15HIﾆﾊﾟ | D35: =VLOOKUP(C35,'仕掛品名寄（貼付）'!B:C,2,FALSE) -> その他 | E35: =VLOOKUP(D35,'仕掛品標準単価一覧表（貼付）'!B:G,6,FALSE) -> 1080 | F35: 数量 | G35: 0 | H35: =SUMIF('1.3②原材料使用'!B:E,C35,'1.3②原材料使用'!E:E) -> 0 | I35: =SUMIF('2.10原液別作業時間'!A:B,C35,'2.10原液別作業時間'!B:B) -> 0 | J35: =SUM(G35:H35,K35) -> 0 | K35: =SUMIF('2.2⑤純増減→前工程費'!B:E,C35,'2.2⑤純増減→前工程費'!E:E) -> 0 | L35: =SUMIF('2.6完成品'!C:D,C35,'2.6完成品'!D:D) -> 0 | M35: =SUMIF('2.3研究費'!D:E,C35,'2.3研究費'!E:E) -> 0 | N35: =SUMIF('2.4販促費'!D:E,C35,'2.4販促費'!E:E) -> 0 | O35: =SUMIF('2.5廃棄処分'!D:E,C35,'2.5廃棄処分'!E:E) -> 0 | P35: =SUMIF('2.1④異種原液'!D:E,C35,'2.1④異種原液'!E:E) -> 0 | Q35: =SUMIF('2.7製造部生産分'!D:I,C35,'2.7製造部生産分'!H:H) -> 0 | R35: =-(G35+H35+K35-L35-M35-N35-O35-P35-Q35-S35) -> 0 | S35: =SUMIF('2.9原液在庫'!B:H,C35,'2.9原液在庫'!H:H) -> 0 | T35: =IFERROR(SUM(G36:K36)/(G35+H35+K35),0) -> 0 | U35: =C35 -> 15HIﾆﾊﾟ | V35: =IF(ISERROR(SUM(G36:K36)/SUM(L35:Q35,S35)),0,SUM(G36:K36)/SUM(L35:Q35,S35)) -> 0 | W35: =V35 -> 0 | X35: =W35/1000 -> 0
F36: 金額 | I36: =I35*労務費経費単価SC!D$7 -> 0 | J36: =J35*労務費経費単価SC!D$11 -> 0 | K36: =K35*$E35 -> 0 | L36: =L35*$E35 -> 0 | M36: =M35*$E35 -> 0 | N36: =N35*$E35 -> 0 | O36: =O35*$E35 -> 0 | P36: =P35*$E35 -> 0 | Q36: =Q35*$E35 -> 0 | R36: =R35*$E35 -> 0 | S36: =S35*$E35 -> 0
C37: 15HIB海 | D37: =VLOOKUP(C37,'仕掛品名寄（貼付）'!B:C,2,FALSE) -> HIB海 | E37: =VLOOKUP(D37,'仕掛品標準単価一覧表（貼付）'!B:G,6,FALSE) -> 1314 | F37: 数量 | G37: 0 | H37: =SUMIF('1.3②原材料使用'!B:E,C37,'1.3②原材料使用'!E:E) -> 0 | I37: =SUMIF('2.10原液別作業時間'!A:B,C37,'2.10原液別作業時間'!B:B) -> 0 | J37: =SUM(G37:H37,K37) -> 0 | K37: =SUMIF('2.2⑤純増減→前工程費'!B:E,C37,'2.2⑤純増減→前工程費'!E:E) -> 0 | L37: =SUMIF('2.6完成品'!C:D,C37,'2.6完成品'!D:D) -> 0 | M37: =SUMIF('2.3研究費'!D:E,C37,'2.3研究費'!E:E) -> 0 | N37: =SUMIF('2.4販促費'!D:E,C37,'2.4販促費'!E:E) -> 0 | O37: =SUMIF('2.5廃棄処分'!D:E,C37,'2.5廃棄処分'!E:E) -> 0 | P37: =SUMIF('2.1④異種原液'!D:E,C37,'2.1④異種原液'!E:E) -> 0 | Q37: =SUMIF('2.7製造部生産分'!D:I,C37,'2.7製造部生産分'!H:H) -> 0 | R37: =-(G37+H37+K37-L37-M37-N37-O37-P37-Q37-S37) -> 0 | S37: =SUMIF('2.9原液在庫'!B:H,C37,'2.9原液在庫'!H:H) -> 0 | T37: =IFERROR(SUM(G38:K38)/(G37+H37+K37),0) -> 0 | U37: =C37 -> 15HIB海 | V37: =IF(ISERROR(SUM(G38:K38)/SUM(L37:Q37,S37)),0,SUM(G38:K38)/SUM(L37:Q37,S37)) -> 0 | W37: =V37 -> 0 | X37: =W37/1000 -> 0
F38: 金額 | I38: =I37*労務費経費単価SC!D$7 -> 0 | J38: =J37*労務費経費単価SC!D$11 -> 0 | K38: =K37*$E37 -> 0 | L38: =L37*$E37 -> 0 | M38: =M37*$E37 -> 0 | N38: =N37*$E37 -> 0 | O38: =O37*$E37 -> 0 | P38: =P37*$E37 -> 0 | Q38: =Q37*$E37 -> 0 | R38: =R37*$E37 -> 0 | S38: =S37*$E37 -> 0
C39: 15G | D39: =VLOOKUP(C39,'仕掛品名寄（貼付）'!B:C,2,FALSE) -> G | E39: =VLOOKUP(D39,'仕掛品標準単価一覧表（貼付）'!B:G,6,FALSE) -> 2344.7184 | F39: 数量 | G39: 863.5 | H39: =SUMIF('1.3②原材料使用'!B:E,C39,'1.3②原材料使用'!E:E) -> 0 | I39: =SUMIF('2.10原液別作業時間'!A:B,C39,'2.10原液別作業時間'!B:B) -> 0 | J39: =SUM(G39:H39,K39) -> 863.5 | K39: =SUMIF('2.2⑤純増減→前工程費'!B:E,C39,'2.2⑤純増減→前工程費'!E:E) -> 0 | L39: =SUMIF('2.6完成品'!C:D,C39,'2.6完成品'!D:D) -> 0 | M39: =SUMIF('2.3研究費'!D:E,C39,'2.3研究費'!E:E) -> 0 | N39: =SUMIF('2.4販促費'!D:E,C39,'2.4販促費'!E:E) -> 0 | O39: =SUMIF('2.5廃棄処分'!D:E,C39,'2.5廃棄処分'!E:E) -> 0 | P39: =SUMIF('2.1④異種原液'!D:E,C39,'2.1④異種原液'!E:E) -> 0 | Q39: =SUMIF('2.7製造部生産分'!D:I,C39,'2.7製造部生産分'!H:H) -> 0 | R39: =-(G39+H39+K39-L39-M39-N39-O39-P39-Q39-S39) -> 0 | S39: =SUMIF('2.9原液在庫'!B:H,C39,'2.9原液在庫'!H:H) -> 863.5 | T39: =IFERROR(SUM(G40:K40)/(G39+H39+K39),0) -> 1115.8244 | U39: =C39 -> 15G | V39: =IF(ISERROR(SUM(G40:K40)/SUM(L39:Q39,S39)),0,SUM(G40:K40)/SUM(L39:Q39,S39)) -> 1115.8244 | W39: =V39 -> 1115.8244 | X39: =W39/1000 -> 1.1158244
F40: 金額 | G40: 937609.34 | I40: =I39*労務費経費単価SC!D$7 -> 0 | J40: =J39*労務費経費単価SC!D$11 -> 25905 | K40: =K39*$E39 -> 0 | L40: =L39*$E39 -> 0 | M40: =M39*$E39 -> 0 | N40: =N39*$E39 -> 0 | O40: =O39*$E39 -> 0 | P40: =P39*$E39 -> 0 | Q40: =Q39*$E39 -> 0 | R40: =R39*$E39 -> 0 | S40: =S39*$E39 -> 2024664.3
A41: H2 | B41: 16 | C41: 16R | D41: =VLOOKUP(C41,'仕掛品名寄（貼付）'!B:C,2,FALSE) -> R | E41: =VLOOKUP(D41,'仕掛品標準単価一覧表（貼付）'!B:G,6,FALSE) -> 908 | F41: 数量 | G41: 446 | H41: =SUMIF('1.3②原材料使用'!B:E,C41,'1.3②原材料使用'!E:E) -> 0 | I41: =SUMIF('2.10原液別作業時間'!A:B,C41,'2.10原液別作業時間'!B:B) -> 0 | J41: =SUM(G41:H41,K41) -> 446 | K41: =SUMIF('2.2⑤純増減→前工程費'!B:E,C41,'2.2⑤純増減→前工程費'!E:E) -> 0 | L41: =SUMIF('2.6完成品'!C:D,C41,'2.6完成品'!D:D) -> 0 | M41: =SUMIF('2.3研究費'!D:E,C41,'2.3研究費'!E:E) -> 0 | N41: =SUMIF('2.4販促費'!D:E,C41,'2.4販促費'!E:E) -> 0 | O41: =SUMIF('2.5廃棄処分'!D:E,C41,'2.5廃棄処分'!E:E) -> 0 | P41: =SUMIF('2.1④異種原液'!D:E,C41,'2.1④異種原液'!E:E) -> 0 | Q41: =SUMIF('2.7製造部生産分'!D:I,C41,'2.7製造部生産分'!H:H) -> 0 | R41: =-(G41+H41+K41-L41-M41-N41-O41-P41-Q41-S41) -> 0 | S41: =SUMIF('2.9原液在庫'!B:H,C41,'2.9原液在庫'!H:H) -> 446 | T41: =IFERROR(SUM(G42:K42)/(G41+H41+K41),0) -> 1087.6669 | U41: =C41 -> 16R | V41: =IF(ISERROR(SUM(G42:K42)/SUM(L41:Q41,S41)),0,SUM(G42:K42)/SUM(L41:Q41,S41)) -> 1087.6669 | W41: =V41 -> 1087.6669 | X41: =W41/1000 -> 1.0876669
...

Sheet 労務費経費単価SC
B3: 労務費・経費単価は38期実際より算出
B5: 労務費 | C5: 実際発生額 | D5: ='[1]仕掛品（製造課）'!H947 -> 1.1360899e+08
C6: 実際作業時間（分） | D6: ='[1]仕掛品（製造課）'!H946 -> 246945
C7: 単価（分） | D7: =ROUND(D5/D6,0) -> 460
B9: 経費 | C9: 実際発生額 | D9: ='[1]仕掛品（製造課）'!I947 -> 178875254
C10: 実際作業量（KG） | D10: ='[1]仕掛品（製造課）'!I946 -> 6057785.3
C11: 単価（KG） | D11: =ROUND(D9/D10,0) -> 30
A13: 検討： | B13: 経費VER2 | C13: 実際発生額 | D13: ='[1]仕掛品（製造課）'!I947 -> 178875254
C14: 実際作業量（KG） | D14: ='[1]仕掛品（製造課）'!I946 -> 6057785.3
C15: 単価（KG） | D15: =ROUND(D13/D14,0) -> 30

Sheet 仕掛品標準単価一覧表（貼付）
B2: 仕掛原液 | C2: 前工程費 | D2: 原材料費 | E2: 労務費 | F2: 経費 | G2: 計
B3: R1 | C3: ー | D3: 296.32652 | E3: 251.17111 | F3: 30 | G3: 577.49762 | I3: TRUE
B4: R2 | C4: ー | D4: 541.39681 | E4: 269.58919 | F4: 60 | G4: 870.986 | I4: TRUE
B5: R3 | C5: ー | D5: 531.71335 | E5: 476.89975 | F5: 90 | G5: 1098.6131 | I5: TRUE
B6: R | C6: 878 | D6: 0 | E6: 0 | F6: 30 | G6: 908 | I6: TRUE
B7: Rリ | C7: 908 | D7: 14.1184 | E7: 44 | F7: 30 | G7: 996.1184 | I7: TRUE
B8: RB | C8: 996.1184 | D8: 0 | E8: 0.4 | F8: 30 | G8: 1026.5184 | I8: TRUE
B9: P | C9: 1026.5184 | D9: 0 | E9: 237 | F9: 30 | G9: 1293.5184 | I9: TRUE
B10: Rマ | C10: 996.1184 | D10: 79 | E10: 69.9 | F10: 30 | G10: 1175.0184 | I10: TRUE
B11: MP | C11: 1175.0184 | D11: 0 | E11: 168.3 | F11: 30 | G11: 1373.3184 | I11: TRUE
B12: RG | C12: 996.1184 | D12: 41 | E12: 61.3 | F12: 30 | G12: 1128.4184 | I12: TRUE
B13: RGI | C13: 1128.4184 | D13: 0 | E13: 228.8 | F13: 30 | G13: 1387.2184 | I13: TRUE
B14: GP | C14: 1387.2184 | D14: 0 | E14: 105.9 | F14: 30 | G14: 1523.1184 | I14: TRUE
B15: LPA | C15: 996.1184 | D15: 0 | E15: 469.5 | F15: 30 | G15: 1495.6184 | I15: TRUE
B16: Rシ | C16: 908 | D16: 0 | E16: 53 | F16: 30 | G16: 991 | I16: TRUE
B17: PE | C17: 991 | D17: 0 | E17: 192 | F17: 30 | G17: 1213 | I17: TRUE
... B37: FB | C37: 2544.7184 | D37: 333 | E37: 85 | F37: 30 | G37: 2992.7184 | I37: TRUE
B38: 植物用 | C38: 1217 | D38: ー | E38: ー | F38: 30 | G38: 1247 | I38: TRUE
B39: LP | C39: 1972.0805 | D39: 0 | E39: 0 | F39: 30 | G39: 2002.0805 | I39: TRUE
B40: 圧搾カス | C40: 0 | D40: 0 | E40: 0 | F40: 0 | G40: 359.30244
B41: その他 | C41: 0 | D41: 0 | E41: 0 | F41: 0 | G41: 1080

Sheet 仕掛品名寄（貼付）
B3: 種類
B4: 13R | C4: R
B5: 14R | C5: R
B6: 14G | C6: G
B7: 15R | C7: R
B8: 15HI納 | C8: その他
B9: 15R花 | C9: その他
B10: 15R納 | C10: その他
B11: 15Rｶ | C11: その他
B12: 15R海 | C12: その他
B13: 15RB海 | C13: その他
B14: 15HI | C14: HI
B15: 15HIﾆ | C15: その他
... B294: KNN | C294: その他
B295: 2380 | C295: その他
B296: 1A | C296: その他
B297: 5A | C297: その他
B298: A | C298: その他
B299: BA | C299: その他
B300: BB | C300: その他
B301: BC | C301: その他
B302: BD | C302: その他
B303: BE | C303: その他
B304: BF | C304: その他
B305: BG | C305: その他
B306: BH | C306: その他
B307: BHA | C307: その他
... B472: Rﾘ | C472: Rリ
B473: 循環参照回避用数値チェック

Sheet DBより貼付⇒

Sheet 2.1④異種原液
A1: 受入原液コード | B1: 受入原液名 | C1: 使用原液コード | D1: 使用原液名 | E1: 使用原液量 | F1: Q_受入記録.工程名 | G1: Q_使用記録.工程名 | H1: 受入原液⇔使用原液
A2: 10-07 | B2: 試作品 | C2: 1-41-1 | D2: 41R | E2: 712 | F2: C工程 | G2: C工程 | H2: =IF(B2=D2,"同原液","異種原液") -> 異種原液
A3: 1-19-2A | B3: 19HIA | C3: 1-16-2-02 | D3: 16HIｸ | E3: 117 | F3: 調合工程 | G3: 調合工程 | H3: =IF(B3=D3,"同原液","異種原液") -> 異種原液
A4: 1-19-2A | B4: 19HIA | C4: 1-19-2 | D4: 19HI | E4: 3270.5 | F4: 調合工程 | G4: 調合工程 | H4: =IF(B4=D4,"同原液","異種原液") -> 異種原液
A5: 1-19-2A | B5: 19HIA | C5: 1-41-1 | D5: 41R | E5: 58.5 | F5: 調合工程 | G5: 調合工程 | H5: =IF(B5=D5,"同原液","異種原液") -> 異種原液
A6: 1-19-3A | B6: 19GA | C6: 1-16-2-02 | D6: 16HIｸ | E6: 117 | F6: 調合工程 | G6: 調合工程 | H6: =IF(B6=D6,"同原液","異種原液") -> 異種原液
A7: 1-19-3A | B7: 19GA | C7: 1-19-3 | D7: 19G | E7: 3320 | F7: 調合工程 | G7: 調合工程 | H7: =IF(B7=D7,"同原液","異種原液") -> 異種原液
A8: 1-19-3A | B8: 19GA | C8: 1-41-1 | D8: 41R | E8: 58.5 | F8: 調合工程 | G8: 調合工程 | H8: =IF(B8=D8,"同原液","異種原液") -> 異種原液
A9: 1-41-1-00 | B9: 41RG | C9: 1-00-09 | D9: GIN | E9: 572 | F9: 調合工程 | G9: 調合工程 | H9: =IF(B9=D9,"同原液","異種原液") -> 異種原液
A10: 1-41-1-00 | B10: 41RG | C10: 1-41-1-01 | D10: 41Rﾘ | E10: 11435 | F10: 調合工程 | G10: 調合工程 | H10: =IF(B10=D10,"同原液","異種原液") -> 異種原液
A11: 1-41-1-00-01 | B11: 41RGI | C11: 1-41-1-00 | D11: 41RG | E11: 17822 | F11: I工程 | G11: I工程 | H11: =IF(B11=D11,"同原液","異種原液") -> 異種原液
A12: 1-41-1-05 | B12: 41Rﾏ | C12: 1-41-1-01 | D12: 41Rﾘ | E12: 22756.5 | F12: 添加･混合工程 | G12: 添加･混合工程 | H12: =IF(B12=D12,"同原液","異種原液") -> 異種原液
A13: 1-41-1-05 | B13: 41Rﾏ | C13: 7-10 | D13: 桑 | E13: 894.83 | F13: 添加･混合工程 | G13: 添加･混合工程 | H13: =IF(B13=D13,"同原液","異種原液") -> 異種原液
... A74: 5-20-1A | B74: LPA | C74: 1-41-1-01 | D74: 41Rﾘ | E74: 25973 | F74: 圧搾工程 | G74: 圧搾工程 | H74: =IF(B74=D74,"同原液","異種原液") -> 異種原液

Sheet 2.7製造部生産分
L2: ↓製造部労務DBより(202505) | M2: 作業時間
A3: バルク充填 | B3: 36240 | D3: 集計用 | G3: 生産数 | H3: kg換算 | I3: 時間按分 | L3: バルク充填 | M3: 36240
A4: BG | B4: 320 | D4: BG | E4: 20081000015 | F4: 原料 万田HI酵素(BG 混合品) | G4: 136 | H4: 136 | I4: 320 | L4: BG | M4: 320
A5: BH | B5: 0 | D5: BH | E5: 20100200005 | F5: 原料 万田HI酵素BH | G5: 0 | H5: 0 | I5: 0 | L5: GIN | M5: 1585
A6: BZ | B6: 0 | D6: BZ | E6: 20230300007 | F6: 植物発酵ｴｷｽ ｱﾚﾙｷﾞｰ特定原材料 | G6: 0 | H6: 0 | I6: 0 | L6: GPA | M6: 660
A7: PQ | B7: 0 | D7: PQ | E7: 20080700013 | F7: 原料 万田酵素(PQ 混合品) | G7: 0 | H7: 0 | I7: 0 | L7: H | M7: 1060
A8: GPA | B8: 660 | D8: GPA | E8: 20240100001 | F8: 原料 万田酵素発酵しょうがGPA混合 | G8: 522 | H8: 522 | I8: 660 | L8: LPA | M8: 13520
A9: GPB | B9: 0 | D9: GPB | E9: 20230700046 | F9: 原料 万田酵素発酵しょうがGPB混合 | G9: 0 | H9: 0 | I9: 0 | L9: LPZ | M9: 180
A10: H | B10: 1060 | D10: H | E10: 20090700009 | F10: 犬猫向け植物発酵ｴｷｽ(ｱｰｽ技研) | G10: 391 | H10: 391 | I10: 1060 | L10: MPA | M10: 340
A11: LPA | B11: 13520 | D11: LPA | E11: 20110400012 | F11: MKﾐｸｽﾁｬｰ(ﾘｷｯﾄﾞ)(kg) | G11: 930 | H11: 930 | I11: 643.1509 | L11: OF | M11: 170
B12: 0 | D12: LPA | E12: 20050300004 | F12: 低分子化万田酵素 1kg | G12: 18620 | H12: 18620 | I12: 12876.849 | L12: P | M12: 3060
A13: LPZ | B13: 180 | D13: LPZ | E13: 20210300049 | F13: MKﾐｸｽﾁｬｰ(ﾌﾞﾛｯｸﾀｲﾌﾟ)(kg) | G13: 50 | H13: 50 | I13: 180 | L13: P(ﾄﾞﾘﾝｸ用) | M13: 1835
A14: MPA | B14: 340 | D14: MPA | E14: 20180500057 | F14: 原料 万田酵素 MULBERRY MPA(混合 | G14: 522 | H14: 522 | I14: 340 | L14: PEA | M14: 1160
A15: OF | B15: 170 | D15: OF | E15: 20090900007 | F15: 原料 万田酵素金印(OF 混合品) | G15: 122 | H15: 122 | I15: 170 | L15: PXA | M15: 780
A16: P | B16: 3060 | D16: P | E16: 20191100098 | F16: MKﾐｸｽﾁｬｰ(ﾍﾟｰｽﾄ) 20kg | G16: 105 | H16: 2100 | I16: 603.08008 | L16: RX | M16: 8650
A17: P(ﾄﾞﾘﾝｸ用) | B17: 1835 | D17: P | E17: 20110400011 | F17: MKﾐｸｽﾁｬｰ(ﾍﾟｰｽﾄ)(kg) | G17: 0 | H17: 0 | I17: 0 | L17: T | M17: 1810
D18: P | E18: 20110800287 | F18: 業務用酵素 万田酵素 1kg | G18: 0 | H18: 0 | I18: 0 | L18: X | M18: 1110
D19: P | E19: 20240200017 | F19: 植物発酵ｴｷｽ 万田酵素 20kg | G19: 0 | H19: 0 | I19: 0
D20: P | E20: 20110800692 | F20: 原料 万田酵素 | G20: 14945 | H20: 14945 | I20: 4291.9199
A21: PEA | B21: 1160 | D21: PEA | E21: 20091200006 | F21: 原料 万田酵素ﾌﾟﾗｽ温(PEA 混合品) | G21: 2074 | H21: 2074 | I21: 1160
A22: PXA | B22: 780 | D22: PXA | E22: 20180200004 | F22: 原料 万田酵素 PXA (混合品) | G22: 1044 | H22: 1044 | I22: 780
A23: RX | B23: 8650 | D23: RX | E23: 20201200034 | F23: 原料 万田酵素 X | G23: 0 | H23: 0 | I23: 0
B24: 0 | D24: RX | E24: 20040100009 | F24: 原料 万田酵素(植物用） | G24: 14700 | H24: 14700 | I24: 8650
A25: X | B25: 1110 | D25: X | E25: 20220300014 | F25: MANDA HARVEST ｻﾝﾊﾞﾙｸ | G25: 6000 | H25: 6000 | I25: 1110
A26: T | B26: 1810 | D26: T | E26: 20111001044 | F26: 畜産用植物性発酵物(A飼料) バルク | G26: 3072 | H26: 3072 | I26: 1810
D27: T
A28: GIN | B28: 1585 | D28: GIN | G28: 0 | H28: 0 | J28: ※詰め替えのため、生産作業として使用されていない
A29: (空白) | E29: 20231100020 | F29: 原料 ひと粒のちから BHA(混合品) | G29: 0 | H29: 0
E30: 20040500003 | F30: ﾏﾝﾀﾞFｷｭｰﾌﾞ 5ﾘｯﾄﾙ | G30: 0 | H30: 0
E31: 20061000003 | F31: 海苔養殖用｢おやじの海｣(ﾖﾓｷﾞ) | G31: 0 | H31: 0
F35: 合計 | G35: 63233 | H35: 65228 | I35: 34655
F36: 製造部製造品目合計 | G36: 63233
F37: チェック | G37: 0

Sheet 1.3②原材料使用
A1: 原液コード | B1: 原液名 | C1: 原料コード | D1: 原料名 | E1: 原料量 | F1: 工程コード | G1: 工程名
A2: 1-00-09 | B2: GIN | C2: 055 | D2: ｼｮｳｶﾞ | E2: 1272.5 | F2: 002 | G2: 仕込工程 | H2: 製造使用分
A3: 1-00-09 | B3: GIN | C3: 201 | D3: 黒糖 | E3: 425.6 | F3: 002 | G3: 仕込工程 | H3: 製造使用分
A4: 1-41-1-01 | B4: 41Rﾘ | C4: 001 | D4: ﾘﾝｺﾞ | E4: 47 | F4: 006 | G4: 添加･混合工程 | H4: 製造使用分
A5: 1-42-1-01 | B5: 42Rﾘ | C5: 001 | D5: ﾘﾝｺﾞ | E5: 1897.54 | F5: 006 | G5: 添加･混合工程 | H5: 製造使用分
A6: 1-49-1 | B6: 49R | C6: 008 | D6: ｲﾁｺﾞ | E6: 0.24 | F6: 002 | G6: 仕込工程 | H6: 製造使用分
A7: 1-49-1 | B7: 49R | C7: 025 | D7: ﾆﾝｼﾞﾝ（西洋） | E7: 40.8 | F7: 002 | G7: 仕込工程 | H7: 製造使用分
A8: 1-49-1 | B8: 49R | C8: 027 | D8: ﾆﾝﾆｸ | E8: 6 | F8: 002 | G8: 仕込工程 | H8: 製造使用分
A9: 1-49-1 | B9: 49R | C9: 030 | D9: 玄米 | E9: 949.2 | F9: 002 | G9: 仕込工程 | H9: 製造使用分
A10: 1-49-1 | B10: 49R | C10: 039 | D10: 黒ｺﾞﾏ | E10: 1562 | F10: 002 | G10: 仕込工程 | H10: 製造使用分
A11: 1-49-1 | B11: 49R | C11: 040 | D11: 白ｺﾞﾏ | E11: 1562 | F11: 002 | G11: 仕込工程 | H11: 製造使用分
A12: 1-49-1 | B12: 49R | C12: 046 | D12: ｷｭｳﾘ | E12: 31.24 | F12: 002 | G12: 仕込工程 | H12: 製造使用分
A13: 1-49-1 | B13: 49R | C13: 047 | D13: ｼｿ | E13: 3.124 | F13: 002 | G13: 仕込工程 | H13: 製造使用分
... A111: 7-11 | B111: 黒西 | C111: 201 | D111: 黒糖 | E111: 267.5 | F111: 002 | G111: 仕込工程 | H111: 製造使用分

Sheet 2.10原液別作業時間
A1: ↓バルク充填、間接費および直接費の空白を除いた
A3: 行ラベル | B3: 合計 / 延時間(分) | D3: 行ラベル | E3: 合計 / 延時間(分) | F3: 製造部労務費
A4: 直接費 | B4: 246945 | D4: 間接費 | E4: 1810915 | F4: 99975815
A5: FEB | B5: 17700 | D5: 直接費 | E5: 246945 | F5: 13633179
A6: 19G | B6: 900 | D6: バルク充填 | E6: 36240 | F6: 2000714.3
A7: 19HI | B7: 5845 | D7: 総計 | E7: 2094100 | F7: 115609708
A8: 19HIA | B8: 440
A9: 21HI海 | B9: 1740
A10: 22Rﾊﾟ | B10: 150
A11: 39R | B11: 525
A12: 40Rｼ | B12: 240
A13: 40Rﾏ | B13: 390
A14: 41R | B14: 2825
A15: 41RB | B15: 30 | E15: 間接費 | F15: 99975815
A16: 41RG | B16: 7380 | E16: 直接費 | F16: 13633179
A17: 41RGI | B17: 9790 | E17: 総計 | F17: 1.1360899e+08
A18: 41Rｼ | B18: 19795 | F18: ↑バルク除き
A19: 41Rﾏ | B19: 8030
A20: 41Rﾘ | B20: 21280
A21: 42Rﾘ | B21: 2185
A22: 49R | B22: 200
A23: 50R | B23: 15970
A24: 51R | B24: 12755
A25: 5A | B25: 195
A26: B | B26: 1295
A27: BG | B27: 335
A28: BM | B28: 1820
A29: C | B29: 370
A30: D | B30: 180
... A60: Y | B60: 300

Sheet 2.2⑤純増減→前工程費
A1: 原液コード | B1: 原液名 | C1: 当期の原液入庫 ① | D1: うち同原液の混合による 入庫② | E1: 原液工程のみで純増減となる 原液入庫(①－②)
A2: 10-07 | B2: 試作品 | C2: 663.5 | D2: 0 | E2: =C2-D2 -> 663.5
A3: 1-19-2 | B3: 19HI | C3: 15343 | D3: 15498.5 | E3: =C3-D3 -> -155.5
A4: 1-19-2A | B4: 19HIA | C4: 5715.5 | D4: 2305 | E4: =C4-D4 -> 3410.5
A5: 1-19-3 | B5: 19G | C5: 3320 | D5: 3357 | E5: =C5-D5 -> -37
A6: 1-19-3A | B6: 19GA | C6: 3488 | D6: 0 | E6: =C6-D6 -> 3488
A7: 1-21-6 | B7: 21HI海 | C7: 5590 | D7: 5595.7 | E7: =C7-D7 -> -5.7
A8: 1-22-1-01 | B8: 22Rﾊﾟ | C8: 396 | D8: 398.5 | E8: =C8-D8 -> -2.5
A9: 1-39-1 | B9: 39R | C9: 1166.5 | D9: 1176 | E9: =C9-D9 -> -9.5
A10: 1-41-1 | B10: 41R | C10: 7344.5 | D10: 7418.7 | E10: =C10-D10 -> -74.2
A11: 1-41-1-00 | B11: 41RG | C11: 33370.5 | D11: 21593.4 | E11: =C11-D11 -> 11777.1
A12: 1-41-1-00-01 | B12: 41RGI | C12: 17755 | D12: 0 | E12: =C12-D12 -> 17755
A13: 1-41-1-01 | B13: 41Rﾘ | C13: 67339 | D13: 67787.3 | E13: =C13-D13 -> -448.3
... A64: 8-01 | B64: 圧搾ｶｽ | C64: 5481 | D64: 0 | E64: =C64-D64 -> 5481
D65: 0 | E65: =C65-D65 -> 0
D66: 0 | E66: =C66-D66 -> 0
D67: 0 | E67: =C67-D67 -> 0
D68: 0 | E68: =C68-D68 -> 0
D69: 0 | E69: =C69-D69 -> 0
D70: 0 | E70: =C70-D70 -> 0
D71: 0 | E71: =C71-D71 -> 0
D72: 0 | E72: =C72-D72 -> 0
D73: 0 | E73: =C73-D73 -> 0
D74: 0 | E74: =C74-D74 -> 0
D75: 0 | E75: =C75-D75 -> 0
D76: 0 | E76: =C76-D76 -> 0
... D94: 0 | E94: =C94-D94 -> 0

Sheet 2.3研究費
A1: 製造部DBより | C1: 工程名 | D1: 原液名 | E1: 合計 / 原液量
C2: 検査･分析 | D2: 29R | E2: 4
C3: 検査･分析 | D3: 41Rﾘ | E3: 5
C4: 検査･分析 | D4: GIN | E4: 0.2
C5: 検査･分析 | D5: MKA | E5: 0.1
C6: 検査･分析 | D6: MKB | E6: 0.1
C7: 検査･分析 | D7: MKC | E7: 0.1
C8: 検査･分析 | D8: MGA | E8: 0.1
C9: 検査･分析 | D9: MGB | E9: 0.1
G10: SCより↓
A12: No | B12: SOUCD | C12: HINCD | D12: HINNMA | E12: SUM(A."FURSU") | F12: LINCMA | G12: LINCMB
A13: 1 | B13: 0000000000003 | C13: 0120110900019 | D13: FB | E13: 0.2 | F13: 無償出庫 品質保証部 | H13: 研究
A14: 4 | B14: 0000000000003 | C14: 0120110900030 | D14: PE | E14: 4.3 | F14: 無償出庫 品質保証部 | H14: 研究
A15: 5 | B15: 0000000000003 | C15: 0120110900045 | D15: X | E15: 5 | F15: 無償出庫 研究開発部 | H15: 研究
A16: 6 | B16: 0000000000003 | C16: 0120110900045 | D16: X | E16: 15 | F16: 無償出庫 商品開発部 | H16: 研究
A17: 7 | B17: 0000000000003 | C17: 0120110900048 | D17: YA | E17: 0.2 | F17: 無償出庫 品質保証部 | H17: 研究
A18: 8 | B18: 0000000000003 | C18: 0120110900049 | D18: YC | E18: 0.2 | F18: 無償出庫 品質保証部 | H18: 研究
A19: 9 | B19: 0000000000003 | C19: 0120170500055 | D19: PX | E19: 0.2 | F19: 無償出庫 品質保証部 | H19: 研究
A20: 10 | B20: 0000000000003 | C20: 0120200900080 | D20: KOL | E20: 0.1 | F20: 無償出庫 品質保証部 | H20: 研究
A21: 12 | B21: 0000000000003 | C21: 0120110900045 | D21: X | E21: 1.5 | F21: ﾃｽﾄ充填 | G21: HARVEST 0.5ml | H21: 研究
A22: 13 | B22: 0000000000003 | C22: 0120171100007 | D22: MP | E22: 8.7 | F22: ﾃｽﾄ生産 20g用 | G22: MULBERRY2.5g | H22: 研究
A23: 14 | B23: 0000000000003 | C23: 0120110900027 | D23: P | E23: 5.4 | F23: 生産・作業依頼書 | G23: P2.5g×2研究検討研開 | H23: 研究
A24: 16 | B24: 0000000000003 | C24: 0120110900003 | D24: B | E24: 1 | F24: 商品開発部依頼分 | G24: 撮影用ｻﾝﾌﾟﾙ | H24: 研究
A25: 17 | B25: 0000000000003 | C25: 0120110900040 | D25: T | E25: 23.5 | F25: ﾃｽﾄ生産 馬用万田酵素 | G25: 商品開発部依頼 | H25: 研究
A26: 18 | B26: 0000000000003 | C26: 0120110900045 | D26: X | E26: 0.2 | F26: 商品化想定保存試験用 | G26: 商品開発部依頼分 | H26: 研究
A27: 19 | B27: 0000000000003 | C27: 0120110900027 | D27: P | E27: 2.7 | F27: E-100白Sｷｬｯﾌﾟ篏合性 | G27: 生産管理依頼分 | H27: 研究
A28: 20 | B28: 0000000000003 | C28: 0120110900030 | D28: PE | E28: 16.8 | F28: ﾃｽﾄ生産 20g | G28: 発酵しょうが2.5g | H28: 研究
A29: 21 | B29: 0000000000003 | C29: 0120170500055 | D29: PX | E29: 5 | F29: ﾃｽﾄ生産 | G29: 発酵しょうが20g用 | H29: 研究
A30: 22 | B30: 0000000000003 | C30: 0120230400008 | D30: GP | E30: 30 | F30: ﾃｽﾄ充填 | G30: 発酵しょうが5.0g | H30: 研究
A31: 23 | B31: 0000000000003 | C31: 0120110900027 | D31: P | E31: 0.15 | F31: ﾋﾞﾝ自動充填機内検査 | G31: 品質保証部依頼分 | H31: 研究
A32: 25 | B32: 0000000000003 | C32: 0120110900045 | D32: X | E32: 14.5 | F32: テスト生産 | G32: ｸﾞﾘｰﾝｷｰﾊﾟｰ新商品 | H32: 研究
A33: 26 | B33: 0000000000003 | C33: 0120110900030 | D33: PE | E33: 17.9 | F33: GINGER2.5g(20g用) | G33: ﾃｽﾄ生産2号ﾗｲﾝ | H33: 研究

Sheet 2.4販促費
A1: 製造部DBより | C1: 工程名 | D1: 原液名 | E1: 合計 / 原液量
C2: 試用 | D2: 39R | E2: 100
C3: 試用 | D3: 41Rﾘ | E3: 20
C4: 試用 | D4: 49R | E4: 160
C5: 試用 | D5: LP | E5: 5
C6: 試用 | D6: 21HI海 | E6: 5
C7: 試用 | D7: 15R海 | E7: 10
G8: SCより↓
A10: No | B10: SOUCD | C10: HINCD | D10: HINNMA | E10: SUM(A."FURSU") | F10: LINCMA | G10: LINCMB
A11: 2 | B11: 0000000000003 | C11: 0120110900024 | D11: O | E11: 0.2 | F11: 無償出庫 CX部 | H11: 販促
A12: 3 | B12: 0000000000003 | C12: 0120110900030 | D12: PE | E12: 0.2 | F12: 無償出庫 CX部 | H12: 販促
A13: 11 | B13: 0000000000003 | C13: 0120230400008 | D13: GP | E13: 0.2 | F13: 無償出庫 CX部 | H13: 販促
A14: 15 | B14: 0000000000003 | C14: 0120110900045 | D14: X | E14: 5.3 | F14: ﾃｽﾄﾏｰｹﾃｨﾝｸﾞ用 | G14: 国際部(商開部)依頼分 | H14: 販促
A15: 24 | B15: 0000000000003 | C15: 0120110900045 | D15: X | E15: 0.8 | F15: 商談時ｻﾝﾌﾟﾙ用 | G15: ｸﾞﾘｰﾝｷｰﾊﾟｰ商開依頼分 | H15: 販促

Sheet 2.5廃棄処分
A1: 製造部DBより | C1: 工程名 | D1: 原液名 | E1: 合計 / 原液量
C2: 廃棄処分 | D2: GIN | E2: 44.8
C3: 廃棄処分 | D3: マタ | E3: 12.8
C4: 廃棄処分 | D4: 50R | E4: 4
C5: 廃棄処分 | D5: ろ過ｶｽ | E5: 6056.5

Sheet 2.6完成品
A1: No | B1: HINCD | C1: HINNMA | D1: SUM(B."FURSU") | E1: HINCLBID | F1: DENKB | H1: ←SCより
A2: 124 | B2: 0120110900002 | C2: 5A | D2: 187.6 | E2: 02 | F2: S
A3: 125 | B3: 0120110900003 | C3: B | D3: 548.9 | E3: 02 | F3: S
A4: 126 | B4: 0120110900005 | C4: BE | D4: 278 | E4: 02 | F4: S
A5: 127 | B5: 0120110900011 | C5: C | D5: 28.1 | E5: 02 | F5: S
A6: 128 | B6: 0120110900014 | C6: D | D6: 185 | E6: 02 | F6: S
A7: 129 | B7: 0120110900015 | C7: DC | D7: 987.5 | E7: 02 | F7: S
A8: 130 | B8: 0120110900017 | C8: EB | D8: 661.2 | E8: 02 | F8: S
A9: 131 | B9: 0120110900019 | C9: FB | D9: 584.4 | E9: 02 | F9: S
A10: 132 | B10: 0120110900020 | C10: G | D10: 59.3 | E10: 02 | F10: S
A11: 133 | B11: 0120110900024 | C11: O | D11: 255.6 | E11: 02 | F11: S
A12: 134 | B12: 0120110900027 | C12: P | D12: 4697.6 | E12: 02 | F12: S
A13: 135 | B13: 0120110900030 | C13: PE | D13: 37048.5 | E13: 02 | F13: S
... A33: 447 | B33: 0120240100048 | C33: BM | D33: 1288.1 | E33: 02 | F33: S

Sheet 2.8SC戻り
A1: 原液コード | B1: 原液名 | C1: 原液量 | D1: 工程名
D2: SC移動処理
A3: 3-00 | B3: GP | D3: SC移動処理
A4: 3-02 | B4: B | D4: SC移動処理
A5: 3-03 | B5: C | D5: SC移動処理
A6: 3-04 | B6: D | D6: SC移動処理
A7: 3-05 | B7: E | D7: SC移動処理
A8: 3-15 | B8: O | D8: SC移動処理
A9: 3-16 | B9: P | D9: SC移動処理
A10: 3-16-05 | B10: PE | D10: SC移動処理
A11: 3-16-24 | B11: PX | D11: SC移動処理
A12: 3-20 | B12: T | D12: SC移動処理
A13: 3-25-01 | B13: YA | D13: SC移動処理
A14: 3-30 | B14: MP | D14: SC移動処理
... A16: 5-20-1A | B16: LPA | D16: SC移動処理

Sheet 2.9原液在庫
A1: 原液コード | B1: 原液名 | C1: 番手 | D1: 種類 | E1: 備考 | F1: 受入数量 | G1: 使用数量 | H1: 在庫数量 | I1: タル数 | J1: オレンジ | K1: サンバルク
A2: 1-00-01 | B2: GIN100 | F2: 300 | G2: 300 | H2: 0 | I2: 0
A3: 1-00-02 | B3: GIN30 | F3: 150 | G3: 150 | H3: 2.8421709e-14 | I3: 0
A4: 1-00-03 | B4: GIN130 | F4: 385 | G4: 385 | H4: -5.6843419e-14 | I4: 0
A5: 1-00-09 | B5: GIN | F5: 3736.3 | G5: 2492.4 | H5: 1243.9 | I5: 4
A6: 10-01-01 | B6: 18HI39Rﾘ | D6: 18HI：39Rﾘ＝4：1 | F6: 500 | G6: 500 | H6: 0 | I6: 0
A7: 10-03 | B7: 研究室用 | G7: 0 | H7: 0 | I7: 0
A8: 10-07 | B8: 試作品 | F8: 684.394 | G8: 20.894 | H8: 663.5 | I8: 2
A9: 10-6 | B9: 植物用ブレンド | E9: ﾐｬﾝﾏｰ用 | F9: 113110 | G9: 11588.8 | H9: 101521.2 | I9: 92
A10: 10-6-01 | B10: 植物用ﾌﾞﾚﾝﾄﾞ(海) | D10: 海藻入り | E10: ﾐｬﾝﾏｰ用 | F10: 19954.1 | G10: 18133.1 | H10: 1821 | I10: 7
A11: 10-6-02 | B11: 植物用ﾌﾞﾚﾝﾄﾞB(海) | F11: 11579.5 | G11: 11579.5 | H11: 0 | I11: 0
A12: 1-100-01 | B12: HIE | D12: ハイエンド | F12: 4213.7 | G12: 3836.7 | H12: 377 | I12: 2
A13: 1-101-01 | B13: USA | D13: オーガニック | F13: 1223.48 | G13: 396.57 | H13: 826.91 | I13: 8
A14: 1-13-1 | B14: 13R | C14: 13番手 | D14: ﾚｷﾞｭﾗｰ | E14: S62仕込み | F14: 510 | G14: 0 | H14: 510 | I14: 1
A15: 1-14-1 | B15: 14R | C15: 14番手 | D15: ﾚｷﾞｭﾗｰ | E15: S63仕込み | F15: 840.5 | G15: 0 | H15: 840.5 | I15: 1
A16: 1-14-3 | B16: 14G | C16: 14番手 | D16: ｺﾞｰﾙﾄﾞ | E16: S63仕込み | F16: 371 | G16: 0 | H16: 371 | I16: 1
A17: 1-15-1 | B17: 15R | C17: 15番手 | D17: ﾚｷﾞｭﾗｰ | E17: H1仕込み | F17: 612 | G17: 0 | H17: 612 | I17: 2
A18: 1-15-1-01 | B18: 15R納 | C18: 15番手 | D18: ﾚｷﾞｭﾗｰ(納豆入り) | E18: H1仕込み | F18: 708 | G18: 0 | H18: 708 | I18: 1
A19: 1-15-1-02 | B19: 15R花 | C19: 15番手 | D19: ﾚｷﾞｭﾗｰ(花粉入り) | E19: H1仕込み | F19: 329 | G19: 0 | H19: 329 | I19: 1
A20: 1-15-1-03 | B20: 15Rｶ | C20: 15番手 | D20: ﾚｷﾞｭﾗｰ(ｶﾘﾝ入り) | E20: H1仕込み | F20: 286.5 | G20: 0 | H20: 286.5 | I20: 1
A21: 1-15-1-04 | B21: 15R海 | C21: 15番手 | D21: ﾚｷﾞｭﾗｰ(海藻入り) | F21: 314.5 | G21: 35 | H21: 279.5 | I21: 1
A22: 1-15-2 | B22: 15HI | C22: 15番手 | D22: ﾊｲ | E22: H1仕込み | F22: 892 | G22: 0 | H22: 892 | I22: 1
A23: 1-15-2-02 | B23: 15HIﾆ | C23: 15番手 | D23: ﾊｲ(ﾆﾝﾆｸ入り) | E23: H1仕込み | F23: 1154.5 | G23: 0 | H23: 1154.5 | I23: 2
A24: 1-15-3 | B24: 15G | C24: 15番手 | D24: ｺﾞｰﾙﾄﾞ | E24: H1仕込み | F24: 863.5 | G24: 0 | H24: 863.5 | I24: 2
A25: 1-16-1 | B25: 16R | C25: 16番手 | D25: ﾚｷﾞｭﾗｰ | E25: H2仕込み | F25: 446 | G25: 0 | H25: 446 | I25: 1
A26: 1-16-1-01 | B26: 16Rﾊﾟ | C26: 16番手 | D26: ﾚｷﾞｭﾗｰ(ﾊﾟﾊﾟｲﾔ入り) | E26: H2仕込み | F26: 531.5 | G26: 0 | H26: 531.5 | I26: 1
A27: 1-16-2 | B27: 16HI | C27: 16番手 | D27: ﾊｲ | E27: H2仕込み | F27: 1839.5 | G27: 0 | H27: 1839.5 | I27: 3
A28: 1-16-2-02 | B28: 16HIｸ | C28: 16番手 | D28: ﾊｲ(桑の実入り) | E28: H2仕込み | F28: 1761.5 | G28: 1646.5 | H28: 115 | I28: 1
A29: 1-16-3 | B29: 16G | C29: 16番手 | D29: ｺﾞｰﾙﾄﾞ | E29: H2仕込み | F29: 36.5 | G29: 0 | H29: 36.5 | I29: 1
A30: 1-17-1 | B30: 17R | C30: 17番手 | D30: ﾚｷﾞｭﾗｰ | E30: H3仕込み | F30: 521.5 | G30: 0 | H30: 521.5 | I30: 1
A31: 1-17-1-01 | B31: 17Rﾊﾟ | C31: 17番手 | D31: ﾚｷﾞｭﾗｰ(ﾊﾟﾊﾟｲﾔ入り) | E31: H3仕込み | F31: 58641.5 | G31: 58641.5 | H31: 0 | I31: 0
A32: 1-17-1-03 | B32: 17R納 | C32: 17番手 | D32: ﾚｷﾞｭﾗｰ(納豆入り) | E32: H3仕込み | F32: 1099.5 | G32: 0 | H32: 1099.5 | I32: 2
A33: 1-17-1-04 | B33: 17Rﾊﾟ海 | D33: 植物用 | F33: 59.43 | G33: 59.43 | H33: 0 | I33: 0
A34: 1-17-2 | B34: 17HI | C34: 17番手 | D34: ﾊｲ | E34: H3仕込み | F34: 419.5 | G34: 0 | H34: 419.5 | I34: 1
A35: 1-17-2-01 | B35: 17HIﾊﾟ | C35: 17番手 | D35: ﾊｲ(ﾊﾟﾊﾟｲﾔ入り) | E35: H3仕込み | F35: 28857.5 | G35: 27487 | H35: 1370.5 | I35: 2
A36: 1-17-2-05 | B36: 17HI(231) | C36: 17番手 | D36: 231用 | E36: H3仕込み | F36: 11348 | G36: 4548.5 | H36: 6799.5 | I36: 6
A37: 1-17-2A | B37: 17HIA | C37: 17番手 | D37: ﾊｲ30R混合 | E37: H3仕込み(30R5ℓ混合) | F37: 4662.5 | G37: 3878.5 | H37: 784 | I37: 2
A38: 1-17-2A-01 | B38: 17HIAｼ | C38: 17番手 | D38: ﾊｲ30R混合(桑の実入り) | E38: H3仕込み(30R5ℓ混合) | F38: 578.5 | G38: 0 | H38: 578.5 | I38: 1
A39: 1-17-4-01 | B39: 17R海 | C39: 17番手 | D39: 植物用（海藻入り） | E39: H3仕込み | F39: 527 | G39: 0 | H39: 527 | I39: 1
A40: 1-17-6-01 | B40: 17HIﾊﾟ海 | C40: 17番手 | D40: ﾊｲ(ﾊﾟﾊﾟｲﾔ入り) 植物用 アルギット入り | E40: H3仕込み | F40: 3872 | G40: 0 | H40: 3872 | I40: 14
...
