Workbook

Sheet SC決算仕訳 原料
D2: 借方 | H2: 貸方
B3: 原価計算仕訳 | D3: 科目番号 | E3: 科目 | F3: 補助科目 | G3: 金額 | H3: 科目番号 | I3: 科目 | J3: 補助科目 | K3: 金額 | L3: 摘要
B4: ＃4 | D4: 500 | E4: 期首材料棚卸高 | G4: =K4 -> 20567620 | H4: 114 | I4: 原材料 | K4: =原材料SC総括!C14 -> 20567620 | L4: 期首原料振替 原料（製造部）
B5: ＃4 | D5: 500 | E5: 期首材料棚卸高 | G5: =K5 -> 6251400 | H5: 114 | I5: 原材料 | K5: 6251400 | L5: 期首原料振替 産品部玄米在庫
B6: ＃4 | D6: 500 | E6: 期首材料棚卸高 | G6: =K6 -> 5685886 | H6: 114 | I6: 原材料 | K6: 5685886 | L6: 期首原料振替 支給原液分
B8: ＃4 | D8: 134 | E8: 原材料 | G8: =K8 -> 22976280 | H8: 505 | I8: 期末材料棚卸高 | K8: =原材料SC総括!E21 -> 22976280 | L8: 期末原料振替 原料（製造部）
B9: ＃4 | D9: 676 | E9: 試験研究費 | G9: =K9 -> 214213.12 | H9: 505 | I9: 期末材料棚卸高 | K9: =原材料SC総括!E15 -> 214213.12 | L9: 期末原料振替 検査分析
B10: ＃4 | D10: 672 | E10: 販売促進費 | G10: =K10 -> 27436.781 | H10: 505 | I10: 期末材料棚卸高 | K10: =原材料SC総括!E16 -> 27436.781 | L10: 期末原料振替 試用
B11: ＃4 | D11: 553 | E11: 他勘定振替 | G11: =K11 -> 70150.763 | H11: 505 | I11: 期末材料棚卸高 | K11: =原材料SC総括!E17 -> 70150.763 | L11: 期末原料振替 原料返品
B12: ＃4 | D12: 712 | E12: 雑損失 | G12: =K12 -> 1329811.3 | H12: 505 | I12: 期末材料棚卸高 | K12: =原材料SC総括!E18+原材料SC総括!E19+原材料SC総括!E20 -> 1329811.3 | L12: 期末原料振替 ロス廃棄在庫調整
B13: ＃4 | D13: 134 | E13: 原材料 | G13: =K13 -> 2253988 | H13: 505 | I13: 期末材料棚卸高 | K13: 2253988 | L13: 期末原料振替 支給原液分 | M13: 従来山田原価計算3外注加工費にて集計していたが、外注加工費NEWでは集計されなくなった。青山さんにて外注先の期末数量を集計するので、それを基にSC単価をかけて期末外注先現役在庫を集計することとした。
B14: ＃4 | D14: 134 | E14: 原材料 | G14: =K14 -> 4789200 | H14: 505 | I14: 期末材料棚卸高 | K14: 4789200 | L14: 期末原料振替 産品部玄米在庫 | M14: ○○期末玄米在庫シートから（玄米シート作成担当要確認）

Sheet 原材料SC総括
B2: 数量ベース
B3: 期首 | C3: =原材料SC明細!E393 -> 8596.0218 | D3: 当期投入 | E3: =原材料SC明細!G393 -> 114478.11
B4: 当期仕入 | C4: =原材料SC明細!F393 -> 114889.79 | D4: 検査分析 | E4: =原材料SC明細!H393 -> 173.3
D5: 試用 | E5: =原材料SC明細!I393 -> 39.1
D6: 返品 | E6: =原材料SC明細!J393 -> 51.8
D7: ロス分 | E7: =原材料SC明細!K393 -> 224.841
D8: 廃棄処分 | E8: =原材料SC明細!L393 -> 882.879
B9: その他調整 | C9: =原材料SC明細!N393 -> -1150.758 | D9: 在庫調整 | E9: =原材料SC明細!M393 -> 528.336
D10: 期末在庫 | E10: =原材料SC明細!O393 -> 5956.6868
C11: =SUM(C3:C10) -> 122335.05 | E11: =SUM(E3:E10) -> 122335.05 | F11: =C11-E11 -> 0
B13: 金額ベース
B14: 期首（AC） | C14: =原材料SC明細!E394 -> 20567620 | D14: 当期投入（仕掛品へ） | E14: =原材料SC明細!G394 -> 83005480
B15: 当期仕入 | C15: =原材料SC明細!F394 -> 86984824 | D15: 試験研究費 | E15: =原材料SC明細!H394 -> 214213.12
D16: 販促費 | E16: =原材料SC明細!I394 -> 27436.781
D17: 他勘定振替 | E17: =原材料SC明細!J394 -> 70150.763
D18: 雑損（ロス） | E18: =原材料SC明細!K394 -> 154576.65
D19: 雑損（廃棄） | E19: =原材料SC明細!L394 -> 1052777.9
B20: その他調整 | C20: =原材料SC明細!N394 -> -0.32090711 | D20: 雑損（在庫調整） | E20: =原材料SC明細!M394 -> 122456.79
D21: 期末在庫 | E21: =原材料SC明細!O394 -> 22976280
C22: =SUM(C14:C21) -> 1.0755244e+08 | E22: =SUM(E14:E21) -> 1.0762337e+08 | F22: =C22-E22 -> -70927.996

Sheet 原材料SC明細
A1: 第38期 原材料
A3: ｺｰﾄﾞ | B3: 原料名 | C3: SC単価 | D3: 単位 | E3: 期首棚卸 | F3: 当期仕入高 | G3: 当期投入高 | H3: 検査・分析 | I3: 試用 | J3: 返品 | K3: ロス分 | L3: 廃棄処分 | M3: 在庫調整 | N3: その他調整 | O3: 期末棚卸
N4: （マイナス＝貸方）
A5: 1 | B5: ﾘﾝｺﾞ | C5: =IFERROR(VLOOKUP(A5,'原料標準単価（貼付）'!B:E,3,FALSE),0) -> 321.14552 | D5: 数量(㎏) | E5: 1.1297629e-12 | F5: =IFERROR(VLOOKUP(A5,'1.2①原材料受入'!A:E,3,FALSE),0) -> 8226.8 | G5: =SUMIF('1.3②原材料使用'!C:E,A5,'1.3②原材料使用'!E:E) -> 7944.54 | H5: =SUMIFS('1.4原材料(その他)'!E:E,'1.4原材料(その他)'!C:C,A:A,'1.4原材料(その他)'!H:H,H$3) -> 6 | I5: =SUMIFS('1.4原材料(その他)'!E:E,'1.4原材料(その他)'!C:C,A:A,'1.4原材料(その他)'!H:H,I$3) -> 0 | J5: =SUMIFS('1.4原材料(その他)'!E:E,'1.4原材料(その他)'!C:C,A:A,'1.4原材料(その他)'!H:H,J$3) -> 0 | K5: =SUMIFS('1.4原材料(その他)'!E:E,'1.4原材料(その他)'!C:C,A:A,'1.4原材料(その他)'!H:H,K$3) -> 15.58 | L5: =SUMIFS('1.4原材料(その他)'!E:E,'1.4原材料(その他)'!C:C,A:A,'1.4原材料(その他)'!H:H,L$3) -> 13.48 | M5: =SUMIFS('1.4原材料(その他)'!E:E,'1.4原材料(その他)'!C:C,A:A,'1.4原材料(その他)'!H:H,M$3) -> 247.2 | N5: =O5-(E5+F5-SUM(G5:M5)) -> -2.0534685e-12 | O5: =SUMIF('1.5原材料在庫'!A:A,原材料SC明細!A5,'1.5原材料在庫'!D:D) -> -2.344791e-13
D6: 金額(円) | E6: 2.3994578e-10 | F6: =F5*$C5 -> 2642000 | G6: =G5*$C5 -> 2551353.5 | H6: =H5*$C5 -> 1926.8731 | I6: =I5*$C5 -> 0 | J6: =J5*$C5 -> 0 | K6: =K5*$C5 -> 5003.4473 | L6: =L5*$C5 -> 4329.0417 | M6: =M5*$C5 -> 79387.174 | N6: =IFERROR(N5/SUM($E5:$F5)*SUM($E6:$F6),"") -> -6.5946222e-10 | O6: =O5*$C5 -> -7.5301914e-11
A7: 2 | B7: ｶｷ | C7: =IFERROR(VLOOKUP(A7,'原料標準単価（貼付）'!B:E,3,FALSE),0) -> 510.48639 | D7: 数量(㎏) | E7: 5.595524e-14 | F7: =IFERROR(VLOOKUP(A7,'1.2①原材料受入'!A:E,3,FALSE),0) -> 224.1 | G7: =SUMIF('1.3②原材料使用'!C:E,A7,'1.3②原材料使用'!E:E) -> 210 | H7: =SUMIFS('1.4原材料(その他)'!E:E,'1.4原材料(その他)'!C:C,A:A,'1.4原材料(その他)'!H:H,H$3) -> 2.2 | I7: =SUMIFS('1.4原材料(その他)'!E:E,'1.4原材料(その他)'!C:C,A:A,'1.4原材料(その他)'!H:H,I$3) -> 0 | J7: =SUMIFS('1.4原材料(その他)'!E:E,'1.4原材料(その他)'!C:C,A:A,'1.4原材料(その他)'!H:H,J$3) -> 0 | K7: =SUMIFS('1.4原材料(その他)'!E:E,'1.4原材料(その他)'!C:C,A:A,'1.4原材料(その他)'!H:H,K$3) -> 4.49 | L7: =SUMIFS('1.4原材料(その他)'!E:E,'1.4原材料(その他)'!C:C,A:A,'1.4原材料(その他)'!H:H,L$3) -> 7.48 | M7: =SUMIFS('1.4原材料(その他)'!E:E,'1.4原材料(その他)'!C:C,A:A,'1.4原材料(その他)'!H:H,M$3) -> -0.07 | N7: =O7-(E7+F7-SUM(G7:M7)) -> -2.9309888e-14 | O7: =SUMIF('1.5原材料在庫'!A:A,原材料SC明細!A7,'1.5原材料在庫'!D:D) -> 2.7533531e-14
D8: 金額(円) | E8: 2.366298e-11 | F8: =F7*$C7 -> 114400 | G8: =G7*$C7 -> 107202.14 | H8: =H7*$C7 -> 1123.0701 | I8: =I7*$C7 -> 0 | J8: =J7*$C7 -> 0 | K8: =K7*$C7 -> 2292.0839 | L8: =L7*$C7 -> 3818.4382 | M8: =M7*$C7 -> -35.734047 | N8: =IFERROR(N7/SUM($E7:$F7)*SUM($E8:$F8),"") -> -1.4962299e-11 | O8: =O7*$C7 -> 1.4055493e-11
A9: 3 | B9: ﾊﾞﾅﾅ | C9: =IFERROR(VLOOKUP(A9,'原料標準単価（貼付）'!B:E,3,FALSE),0) -> 280.83162 | D9: 数量(㎏) | E9: 8.5265128e-14 | F9: =IFERROR(VLOOKUP(A9,'1.2①原材料受入'!A:E,3,FALSE),0) -> 3119.2 | G9: =SUMIF('1.3②原材料使用'!C:E,A9,'1.3②原材料使用'!E:E) -> 3000 | H9: =SUMIFS('1.4原材料(その他)'!E:E,'1.4原材料(その他)'!C:C,A:A,'1.4原材料(その他)'!H:H,H$3) -> 4 | I9: =SUMIFS('1.4原材料(その他)'!E:E,'1.4原材料(その他)'!C:C,A:A,'1.4原材料(その他)'!H:H,I$3) -> 0 | J9: =SUMIFS('1.4原材料(その他)'!E:E,'1.4原材料(その他)'!C:C,A:A,'1.4原材料(その他)'!H:H,J$3) -> 0 | K9: =SUMIFS('1.4原材料(その他)'!E:E,'1.4原材料(その他)'!C:C,A:A,'1.4原材料(その他)'!H:H,K$3) -> 0 | L9: =SUMIFS('1.4原材料(その他)'!E:E,'1.4原材料(その他)'!C:C,A:A,'1.4原材料(その他)'!H:H,L$3) -> 17.8 | M9: =SUMIFS('1.4原材料(その他)'!E:E,'1.4原材料(その他)'!C:C,A:A,'1.4原材料(その他)'!H:H,M$3) -> 97.4 | N9: =O9-(E9+F9-SUM(G9:M9)) -> 3.1086245e-13 | O9: =SUMIF('1.5原材料在庫'!A:A,原材料SC明細!A9,'1.5原材料在庫'!D:D) -> -1.438849e-13
D10: 金額(円) | E10: 2.7317029e-11 | F10: =F9*$C9 -> 875970 | G10: =G9*$C9 -> 842494.87 | H10: =H9*$C9 -> 1123.3265 | I10: =I9*$C9 -> 0 | J10: =J9*$C9 -> 0 | K10: =K9*$C9 -> 0 | L10: =L9*$C9 -> 4998.8029 | M10: =M9*$C9 -> 27353 | N10: =IFERROR(N9/SUM($E9:$F9)*SUM($E10:$F10),"") -> 8.7300006e-11 | O10: =O9*$C9 -> -4.0407431e-11
A11: 4 | B11: ﾊﾟｲﾝｱｯﾌﾟﾙ | C11: =IFERROR(VLOOKUP(A11,'原料標準単価（貼付）'!B:E,3,FALSE),0) -> 352.15661 | D11: 数量(㎏) | E11: 5.6488147e-13 | F11: =IFERROR(VLOOKUP(A11,'1.2①原材料受入'!A:E,3,FALSE),0) -> 3141.5 | G11: =SUMIF('1.3②原材料使用'!C:E,A11,'1.3②原材料使用'!E:E) -> 3024 | H11: =SUMIFS('1.4原材料(その他)'!E:E,'1.4原材料(その他)'!C:C,A:A,'1.4原材料(その他)'!H:H,H$3) -> 4 | I11: =SUMIFS('1.4原材料(その他)'!E:E,'1.4原材料(その他)'!C:C,A:A,'1.4原材料(その他)'!H:H,I$3) -> 0 | J11: =SUMIFS('1.4原材料(その他)'!E:E,'1.4原材料(その他)'!C:C,A:A,'1.4原材料(その他)'!H:H,J$3) -> 0 | K11: =SUMIFS('1.4原材料(その他)'!E:E,'1.4原材料(その他)'!C:C,A:A,'1.4原材料(その他)'!H:H,K$3) -> 0 | L11: =SUMIFS('1.4原材料(その他)'!E:E,'1.4原材料(その他)'!C:C,A:A,'1.4原材料(その他)'!H:H,L$3) -> 102.35 | M11: =SUMIFS('1.4原材料(その他)'!E:E,'1.4原材料(その他)'!C:C,A:A,'1.4原材料(その他)'!H:H,M$3) -> 11.15 | N11: =O11-(E11+F11-SUM(G11:M11)) -> 1.6697754e-13 | O11: =SUMIF('1.5原材料在庫'!A:A,原材料SC明細!A11,'1.5原材料在庫'!D:D) -> 6.2172489e-13
D12: 金額(円) | E12: 2.2197078e-10 | F12: =F11*$C11 -> 1106300 | G12: =G11*$C11 -> 1064921.6 | H12: =H11*$C11 -> 1408.6265 | I12: =I11*$C11 -> 0 | J12: =J11*$C11 -> 0 | K12: =K11*$C11 -> 0 | L12: =L11*$C11 -> 36043.229 | M12: =M11*$C11 -> 3926.5462 | N12: =IFERROR(N11/SUM($E11:$F11)*SUM($E12:$F12),"") -> 5.8802246e-11 | O12: =O11*$C11 -> 2.1894453e-10
A13: 5 | B13: ｱｹﾋﾞ | C13: =IFERROR(VLOOKUP(A13,'原料標準単価（貼付）'!B:E,3,FALSE),0) -> 2148.4375 | D13: 数量(㎏) | E13: 2.8421709e-13 | F13: =IFERROR(VLOOKUP(A13,'1.2①原材料受入'!A:E,3,FALSE),0) -> 230.4 | G13: =SUMIF('1.3②原材料使用'!C:E,A13,'1.3②原材料使用'!E:E) -> 210 | H13: =SUMIFS('1.4原材料(その他)'!E:E,'1.4原材料(その他)'!C:C,A:A,'1.4原材料(その他)'!H:H,H$3) -> 2.4 | I13: =SUMIFS('1.4原材料(その他)'!E:E,'1.4原材料(その他)'!C:C,A:A,'1.4原材料(その他)'!H:H,I$3) -> 0 | J13: =SUMIFS('1.4原材料(その他)'!E:E,'1.4原材料(その他)'!C:C,A:A,'1.4原材料(その他)'!H:H,J$3) -> 13 | K13: =SUMIFS('1.4原材料(その他)'!E:E,'1.4原材料(その他)'!C:C,A:A,'1.4原材料(その他)'!H:H,K$3) -> 1.5 | L13: =SUMIFS('1.4原材料(その他)'!E:E,'1.4原材料(その他)'!C:C,A:A,'1.4原材料(その他)'!H:H,L$3) -> 0 | M13: =SUMIFS('1.4原材料(その他)'!E:E,'1.4原材料(その他)'!C:C,A:A,'1.4原材料(その他)'!H:H,M$3) -> 3.5 | N13: =O13-(E13+F13-SUM(G13:M13)) -> 2.8421709e-14 | O13: =SUMIF('1.5原材料在庫'!A:A,原材料SC明細!A13,'1.5原材料在庫'!D:D) -> 3.126388e-13
D14: 金額(円) | E14: 5.6005332e-10 | F14: =F13*$C13 -> 495000 | G14: =G13*$C13 -> 451171.88 | H14: =H13*$C13 -> 5156.25 | I14: =I13*$C13 -> 0 | J14: =J13*$C13 -> 27929.688 | K14: =K13*$C13 -> 3222.6562 | L14: =L13*$C13 -> 0 | M14: =M13*$C13 -> 7519.5312 | N14: =IFERROR(N13/SUM($E13:$F13)*SUM($E14:$F14),"") -> 6.1062266e-11 | O14: =O13*$C13 -> 6.7168493e-10
A15: 6 | B15: ﾏﾀﾀﾋﾞ | C15: =IFERROR(VLOOKUP(A15,'原料標準単価（貼付）'!B:E,3,FALSE),0) -> 1852.6 | D15: 数量(㎏) | E15: 623.8 | F15: =IFERROR(VLOOKUP(A15,'1.2①原材料受入'!A:E,3,FALSE),0) -> 0 | G15: =SUMIF('1.3②原材料使用'!C:E,A15,'1.3②原材料使用'!E:E) -> 230 | H15: =SUMIFS('1.4原材料(その他)'!E:E,'1.4原材料(その他)'!C:C,A:A,'1.4原材料(その他)'!H:H,H$3) -> 0 | I15: =SUMIFS('1.4原材料(その他)'!E:E,'1.4原材料(その他)'!C:C,A:A,'1.4原材料(その他)'!H:H,I$3) -> 0 | J15: =SUMIFS('1.4原材料(その他)'!E:E,'1.4原材料(その他)'!C:C,A:A,'1.4原材料(その他)'!H:H,J$3) -> 0 | K15: =SUMIFS('1.4原材料(その他)'!E:E,'1.4原材料(その他)'!C:C,A:A,'1.4原材料(その他)'!H:H,K$3) -> 0.16 | L15: =SUMIFS('1.4原材料(その他)'!E:E,'1.4原材料(その他)'!C:C,A:A,'1.4原材料(その他)'!H:H,L$3) -> 0 | M15: =SUMIFS('1.4原材料(その他)'!E:E,'1.4原材料(その他)'!C:C,A:A,'1.4原材料(その他)'!H:H,M$3) -> 3.74 | N15: =O15-(E15+F15-SUM(G15:M15)) -> 0 | O15: =SUMIF('1.5原材料在庫'!A:A,原材料SC明細!A15,'1.5原材料在庫'!D:D) -> 389.9
D16: 金額(円) | E16: 1156080.7 | F16: =F15*$C15 -> 0 | G16: =G15*$C15 -> 426098 | H16: =H15*$C15 -> 0 | I16: =I15*$C15 -> 0 | J16: =J15*$C15 -> 0 | K16: =K15*$C15 -> 296.416 | L16: =L15*$C15 -> 0 | M16: =M15*$C15 -> 6928.724 | N16: =IFERROR(N15/SUM($E15:$F15)*SUM($E16:$F16),"") -> 0 | O16: =O15*$C15 -> 722328.74
A17: 7 | B17: ｲﾁｼﾞｸ | C17: =IFERROR(VLOOKUP(A17,'原料標準単価（貼付）'!B:E,3,FALSE),0) -> 1215.2565 | D17: 数量(㎏) | E17: 1.7097435e-13 | F17: =IFERROR(VLOOKUP(A17,'1.2①原材料受入'!A:E,3,FALSE),0) -> 228.1 | G17: =SUMIF('1.3②原材料使用'!C:E,A17,'1.3②原材料使用'!E:E) -> 210 | H17: =SUMIFS('1.4原材料(その他)'!E:E,'1.4原材料(その他)'!C:C,A:A,'1.4原材料(その他)'!H:H,H$3) -> 2.2 | I17: =SUMIFS('1.4原材料(その他)'!E:E,'1.4原材料(その他)'!C:C,A:A,'1.4原材料(その他)'!H:H,I$3) -> 0 | J17: =SUMIFS('1.4原材料(その他)'!E:E,'1.4原材料(その他)'!C:C,A:A,'1.4原材料(その他)'!H:H,J$3) -> 0 | K17: =SUMIFS('1.4原材料(その他)'!E:E,'1.4原材料(その他)'!C:C,A:A,'1.4原材料(その他)'!H:H,K$3) -> 1.9 | L17: =SUMIFS('1.4原材料(その他)'!E:E,'1.4原材料(その他)'!C:C,A:A,'1.4原材料(その他)'!H:H,L$3) -> 0 | M17: =SUMIFS('1.4原材料(その他)'!E:E,'1.4原材料(その他)'!C:C,A:A,'1.4原材料(その他)'!H:H,M$3) -> 1.6 | N17: =O17-(E17+F17-SUM(G17:M17)) -> 0 | O17: =SUMIF('1.5原材料在庫'!A:A,原材料SC明細!A17,'1.5原材料在庫'!D:D) -> 12.4
D18: 金額(円) | E18: 1.9411078e-10 | F18: =F17*$C17 -> 277200 | G18: =G17*$C17 -> 255203.86 | H18: =H17*$C17 -> 2673.5642 | I18: =I17*$C17 -> 0 | J18: =J17*$C17 -> 0 | K18: =K17*$C17 -> 2308.9873 | L18: =L17*$C17 -> 0 | M18: =M17*$C17 -> 1944.4103 | N18: =IFERROR(N17/SUM($E17:$F17)*SUM($E18:$F18),"") -> 0 | O18: =O17*$C17 -> 15069.18
A19: 8 | B19: ｲﾁｺﾞ | C19: =IFERROR(VLOOKUP(A19,'原料標準単価（貼付）'!B:E,3,FALSE),0) -> 2249.1039 | D19: 数量(㎏) | E19: 1.4876989e-14 | F19: =IFERROR(VLOOKUP(A19,'1.2①原材料受入'!A:E,3,FALSE),0) -> 27.9 | G19: =SUMIF('1.3②原材料使用'!C:E,A19,'1.3②原材料使用'!E:E) -> 21.22 | H19: =SUMIFS('1.4原材料(その他)'!E:E,'1.4原材料(その他)'!C:C,A:A,'1.4原材料(その他)'!H:H,H$3) -> 2.5 | I19: =SUMIFS('1.4原材料(その他)'!E:E,'1.4原材料(その他)'!C:C,A:A,'1.4原材料(その他)'!H:H,I$3) -> 0 | J19: =SUMIFS('1.4原材料(その他)'!E:E,'1.4原材料(その他)'!C:C,A:A,'1.4原材料(その他)'!H:H,J$3) -> 0 | K19: =SUMIFS('1.4原材料(その他)'!E:E,'1.4原材料(その他)'!C:C,A:A,'1.4原材料(その他)'!H:H,K$3) -> 0.835 | L19: =SUMIFS('1.4原材料(その他)'!E:E,'1.4原材料(その他)'!C:C,A:A,'1.4原材料(その他)'!H:H,L$3) -> 2.3 | M19: =SUMIFS('1.4原材料(その他)'!E:E,'1.4原材料(その他)'!C:C,A:A,'1.4原材料(その他)'!H:H,M$3) -> 1.05 | N19: =O19-(E19+F19-SUM(G19:M19)) -> -4.4408921e-16 | O19: =SUMIF('1.5原材料在庫'!A:A,原材料SC明細!A19,'1.5原材料在庫'!D:D) -> -0.005
D20: 金額(円) | E20: 3.3895632e-11 | F20: =F19*$C19 -> 62750 | G20: =G19*$C19 -> 47725.986 | H20: =H19*$C19 -> 5622.7599 | I20: =I19*$C19 -> 0 | J20: =J19*$C19 -> 0 | K20: =K19*$C19 -> 1878.0018 | L20: =L19*$C19 -> 5172.9391 | M20: =M19*$C19 -> 2361.5591 | N20: =IFERROR(N19/SUM($E19:$F19)*SUM($E20:$F20),"") -> -9.9880279e-13 | O20: =O19*$C19 -> -11.24552
A21: 9 | B21: 山ﾌﾞﾄﾞｳ | C21: =IFERROR(VLOOKUP(A21,'原料標準単価（貼付）'!B:E,3,FALSE),0) -> 1106.6425 | D21: 数量(㎏) | E21: -8.5265128e-14 | F21: =IFERROR(VLOOKUP(A21,'1.2①原材料受入'!A:E,3,FALSE),0) -> 248.4 | G21: =SUMIF('1.3②原材料使用'!C:E,A21,'1.3②原材料使用'!E:E) -> 210 | H21: =SUMIFS('1.4原材料(その他)'!E:E,'1.4原材料(その他)'!C:C,A:A,'1.4原材料(その他)'!H:H,H$3) -> 4 | I21: =SUMIFS('1.4原材料(その他)'!E:E,'1.4原材料(その他)'!C:C,A:A,'1.4原材料(その他)'!H:H,I$3) -> 3 | J21: =SUMIFS('1.4原材料(その他)'!E:E,'1.4原材料(その他)'!C:C,A:A,'1.4原材料(その他)'!H:H,J$3) -> 0 | K21: =SUMIFS('1.4原材料(その他)'!E:E,'1.4原材料(その他)'!C:C,A:A,'1.4原材料(その他)'!H:H,K$3) -> 7.8 | L21: =SUMIFS('1.4原材料(その他)'!E:E,'1.4原材料(その他)'!C:C,A:A,'1.4原材料(その他)'!H:H,L$3) -> 23.6 | M21: =SUMIFS('1.4原材料(その他)'!E:E,'1.4原材料(その他)'!C:C,A:A,'1.4原材料(その他)'!H:H,M$3) -> 0 | N21: =O21-(E21+F21-SUM(G21:M21)) -> 2.8421709e-14 | O21: =SUMIF('1.5原材料在庫'!A:A,原材料SC明細!A21,'1.5原材料在庫'!D:D) -> -5.6843419e-14
D22: 金額(円) | E22: -8.4820827e-11 | F22: =F21*$C21 -> 274890 | G22: =G21*$C21 -> 232394.93 | H22: =H21*$C21 -> 4426.57 | I22: =I21*$C21 -> 3319.9275 | J22: =J21*$C21 -> 0 | K22: =K21*$C21 -> 8631.8116 | L22: =L21*$C21 -> 26116.763 | M22: =M21*$C21 -> 0 | N22: =IFERROR(N21/SUM($E21:$F21)*SUM($E22:$F22),"") -> 3.1452672e-11 | O22: =O21*$C21 -> -6.2905344e-11
A23: 10 | B23: ﾌﾞﾄﾞｳ | C23: =IFERROR(VLOOKUP(A23,'原料標準単価（貼付）'!B:E,3,FALSE),0) -> 1088.172 | D23: 数量(㎏) | E23: 1.7763568e-15 | F23: =IFERROR(VLOOKUP(A23,'1.2①原材料受入'!A:E,3,FALSE),0) -> 1162.5 | G23: =SUMIF('1.3②原材料使用'!C:E,A23,'1.3②原材料使用'!E:E) -> 1050 | H23: =SUMIFS('1.4原材料(その他)'!E:E,'1.4原材料(その他)'!C:C,A:A,'1.4原材料(その他)'!H:H,H$3) -> 3 | I23: =SUMIFS('1.4原材料(その他)'!E:E,'1.4原材料(その他)'!C:C,A:A,'1.4原材料(その他)'!H:H,I$3) -> 15.34 | J23: =SUMIFS('1.4原材料(その他)'!E:E,'1.4原材料(その他)'!C:C,A:A,'1.4原材料(その他)'!H:H,J$3) -> 38.8 | K23: =SUMIFS('1.4原材料(その他)'!E:E,'1.4原材料(その他)'!C:C,A:A,'1.4原材料(その他)'!H:H,K$3) -> 6.34 | L23: =SUMIFS('1.4原材料(その他)'!E:E,'1.4原材料(その他)'!C:C,A:A,'1.4原材料(その他)'!H:H,L$3) -> 27.7 | M23: =SUMIFS('1.4原材料(その他)'!E:E,'1.4原材料(その他)'!C:C,A:A,'1.4原材料(その他)'!H:H,M$3) -> 21.32 | N23: =O23-(E23+F23-SUM(G23:M23)) -> 1.7763568e-15 | O23: =SUMIF('1.5原材料在庫'!A:A,原材料SC明細!A23,'1.5原材料在庫'!D:D) -> 2.2915003e-13
D24: 金額(円) | E24: 1.8045989e-12 | F24: =F23*$C23 -> 1265000 | G24: =G23*$C23 -> 1142580.6 | H24: =H23*$C23 -> 3264.5161 | I24: =I23*$C23 -> 16692.559 | J24: =J23*$C23 -> 42221.075 | K24: =K23*$C23 -> 6899.0108 | L24: =L23*$C23 -> 30142.366 | M24: =M23*$C23 -> 23199.828 | N24: =IFERROR(N23/SUM($E23:$F23)*SUM($E24:$F24),"") -> 1.9329819e-12 | O24: =O23*$C23 -> 2.4935466e-10
A25: 11 | B25: 山桃 | C25: =IFERROR(VLOOKUP(A25,'原料標準単価（貼付）'!B:E,3,FALSE),0) -> 3806.4972 | D25: 数量(㎏) | E25: 45.82 | F25: =IFERROR(VLOOKUP(A25,'1.2①原材料受入'!A:E,3,FALSE),0) -> 141.6 | G25: =SUMIF('1.3②原材料使用'!C:E,A25,'1.3②原材料使用'!E:E) -> 168 | H25: =SUMIFS('1.4原材料(その他)'!E:E,'1.4原材料(その他)'!C:C,A:A,'1.4原材料(その他)'!H:H,H$3) -> 2.1 | I25: =SUMIFS('1.4原材料(その他)'!E:E,'1.4原材料(その他)'!C:C,A:A,'1.4原材料(その他)'!H:H,I$3) -> 0 | J25: =SUMIFS('1.4原材料(その他)'!E:E,'1.4原材料(その他)'!C:C,A:A,'1.4原材料(その他)'!H:H,J$3) -> 0 | K25: =SUMIFS('1.4原材料(その他)'!E:E,'1.4原材料(その他)'!C:C,A:A,'1.4原材料(その他)'!H:H,K$3) -> 9.8 | L25: =SUMIFS('1.4原材料(その他)'!E:E,'1.4原材料(その他)'!C:C,A:A,'1.4原材料(その他)'!H:H,L$3) -> 0.21 | M25: =SUMIFS('1.4原材料(その他)'!E:E,'1.4原材料(その他)'!C:C,A:A,'1.4原材料(その他)'!H:H,M$3) -> -0.59 | N25: =O25-(E25+F25-SUM(G25:M25)) -> 2.3092639e-14 | O25: =SUMIF('1.5原材料在庫'!A:A,原材料SC明細!A25,'1.5原材料在庫'!D:D) -> 7.9
D26: 金額(円) | E26: 140990.43 | F26: =F25*$C25 -> 539000 | G26: =G25*$C25 -> 639491.53 | H26: =H25*$C25 -> 7993.6441 | I26: =I25*$C25 -> 0 | J26: =J25*$C25 -> 0 | K26: =K25*$C25 -> 37303.672 | L26: =L25*$C25 -> 799.36441 | M26: =M25*$C25 -> -2245.8333 | N26: =IFERROR(N25/SUM($E25:$F25)*SUM($E26:$F26),"") -> 8.3783873e-11 | O26: =O25*$C25 -> 30071.328
A27: 12 | B27: 梅 | C27: =IFERROR(VLOOKUP(A27,'原料標準単価（貼付）'!B:E,3,FALSE),0) -> 0 | D27: 数量(㎏) | E27: 4.458 | F27: =IFERROR(VLOOKUP(A27,'1.2①原材料受入'!A:E,3,FALSE),0) -> 16.6 | G27: =SUMIF('1.3②原材料使用'!C:E,A27,'1.3②原材料使用'!E:E) -> 6.3 | H27: =SUMIFS('1.4原材料(その他)'!E:E,'1.4原材料(その他)'!C:C,A:A,'1.4原材料(その他)'!H:H,H$3) -> 2.1 | I27: =SUMIFS('1.4原材料(その他)'!E:E,'1.4原材料(その他)'!C:C,A:A,'1.4原材料(その他)'!H:H,I$3) -> 0 | J27: =SUMIFS('1.4原材料(その他)'!E:E,'1.4原材料(その他)'!C:C,A:A,'1.4原材料(その他)'!H:H,J$3) -> 0 | K27: =SUMIFS('1.4原材料(その他)'!E:E,'1.4原材料(その他)'!C:C,A:A,'1.4原材料(その他)'!H:H,K$3) -> 5.28 | L27: =SUMIFS('1.4原材料(その他)'!E:E,'1.4原材料(その他)'!C:C,A:A,'1.4原材料(その他)'!H:H,L$3) -> 6.6 | M27: =SUMIFS('1.4原材料(その他)'!E:E,'1.4原材料(その他)'!C:C,A:A,'1.4原材料(その他)'!H:H,M$3) -> 0.72 | N27: =O27-(E27+F27-SUM(G27:M27)) -> -0.058 | O27: =SUMIF('1.5原材料在庫'!A:A,原材料SC明細!A27,'1.5原材料在庫'!D:D) -> 0
D28: 金額(円) | E28: 116.51141 | F28: =F27*$C27 -> 0 | G28: =G27*$C27 -> 0 | H28: =H27*$C27 -> 0 | I28: =I27*$C27 -> 0 | J28: =J27*$C27 -> 0 | K28: =K27*$C27 -> 0 | L28: =L27*$C27 -> 0 | M28: =M27*$C27 -> 0 | N28: =IFERROR(N27/SUM($E27:$F27)*SUM($E28:$F28),"") -> -0.32090711 | O28: =O27*$C27 -> 0
A29: 13 | B29: ﾈｰﾌﾞﾙ | C29: =IFERROR(VLOOKUP(A29,'原料標準単価（貼付）'!B:E,3,FALSE),0) -> 0 | D29: 数量(㎏) | E29: -5.6843419e-14 | F29: =IFERROR(VLOOKUP(A29,'1.2①原材料受入'!A:E,3,FALSE),0) -> 673.4 | G29: =SUMIF('1.3②原材料使用'!C:E,A29,'1.3②原材料使用'!E:E) -> 600 | H29: =SUMIFS('1.4原材料(その他)'!E:E,'1.4原材料(その他)'!C:C,A:A,'1.4原材料(その他)'!H:H,H$3) -> 4 | I29: =SUMIFS('1.4原材料(その他)'!E:E,'1.4原材料(その他)'!C:C,A:A,'1.4原材料(その他)'!H:H,I$3) -> 0 | J29: =SUMIFS('1.4原材料(その他)'!E:E,'1.4原材料(その他)'!C:C,A:A,'1.4原材料(その他)'!H:H,J$3) -> 0 | K29: =SUMIFS('1.4原材料(その他)'!E:E,'1.4原材料(その他)'!C:C,A:A,'1.4原材料(その他)'!H:H,K$3) -> 0 | L29: =SUMIFS('1.4原材料(その他)'!E:E,'1.4原材料(その他)'!C:C,A:A,'1.4原材料(その他)'!H:H,L$3) -> 31.5 | M29: =SUMIFS('1.4原材料(その他)'!E:E,'1.4原材料(その他)'!C:C,A:A,'1.4原材料(その他)'!H:H,M$3) -> 37.9 | N29: =O29-(E29+F29-SUM(G29:M29)) -> 1.1368684e-13 | O29: =SUMIF('1.5原材料在庫'!A:A,原材料SC明細!A29,'1.5原材料在庫'!D:D) -> 0
D30: 金額(円) | E30: 0 | F30: =F29*$C29 -> 0 | G30: =G29*$C29 -> 0 | H30: =H29*$C29 -> 0 | I30: =I29*$C29 -> 0 | J30: =J29*$C29 -> 0 | K30: =K29*$C29 -> 0 | L30: =L29*$C29 -> 0 | M30: =M29*$C29 -> 0 | N30: =IFERROR(N29/SUM($E29:$F29)*SUM($E30:$F30),"") -> 0 | O30: =O29*$C29 -> 0
A31: 14 | B31: ﾊｯｻｸ | C31: =IFERROR(VLOOKUP(A31,'原料標準単価（貼付）'!B:E,3,FALSE),0) -> 0 | D31: 数量(㎏) | E31: 2.1316282e-14 | F31: =IFERROR(VLOOKUP(A31,'1.2①原材料受入'!A:E,3,FALSE),0) -> 1510.5 | G31: =SUMIF('1.3②原材料使用'!C:E,A31,'1.3②原材料使用'!E:E) -> 1411.2 | H31: =SUMIFS('1.4原材料(その他)'!E:E,'1.4原材料(その他)'!C:C,A:A,'1.4原材料(その他)'!H:H,H$3) -> 4 | I31: =SUMIFS('1.4原材料(その他)'!E:E,'1.4原材料(その他)'!C:C,A:A,'1.4原材料(その他)'!H:H,I$3) -> 0 | J31: =SUMIFS('1.4原材料(その他)'!E:E,'1.4原材料(その他)'!C:C,A:A,'1.4原材料(その他)'!H:H,J$3) -> 0 | K31: =SUMIFS('1.4原材料(その他)'!E:E,'1.4原材料(その他)'!C:C,A:A,'1.4原材料(その他)'!H:H,K$3) -> 0 | L31: =SUMIFS('1.4原材料(その他)'!E:E,'1.4原材料(その他)'!C:C,A:A,'1.4原材料(その他)'!H:H,L$3) -> 60.9 | M31: =SUMIFS('1.4原材料(その他)'!E:E,'1.4原材料(その他)'!C:C,A:A,'1.4原材料(その他)'!H:H,M$3) -> 34.4 | N31: =O31-(E31+F31-SUM(G31:M31)) -> 1.3500312e-13 | O31: =SUMIF('1.5原材料在庫'!A:A,原材料SC明細!A31,'1.5原材料在庫'!D:D) -> 1.3500312e-13
D32: 金額(円) | E32: 0 | F32: =F31*$C31 -> 0 | G32: =G31*$C31 -> 0 | H32: =H31*$C31 -> 0 | I32: =I31*$C31 -> 0 | J32: =J31*$C31 -> 0 | K32: =K31*$C31 -> 0 | L32: =L31*$C31 -> 0 | M32: =M31*$C31 -> 0 | N32: =IFERROR(N31/SUM($E31:$F31)*SUM($E32:$F32),"") -> 0 | O32: =O31*$C31 -> 0
A33: 15 | B33: 温州みかん | C33: =IFERROR(VLOOKUP(A33,'原料標準単価（貼付）'!B:E,3,FALSE),0) -> 0 | D33: 数量(㎏) | E33: -1.0444978e-12 | F33: =IFERROR(VLOOKUP(A33,'1.2①原材料受入'!A:E,3,FALSE),0) -> 3933.3 | G33: =SUMIF('1.3②原材料使用'!C:E,A33,'1.3②原材料使用'!E:E) -> 3835.2 | H33: =SUMIFS('1.4原材料(その他)'!E:E,'1.4原材料(その他)'!C:C,A:A,'1.4原材料(その他)'!H:H,H$3) -> 4 | I33: =SUMIFS('1.4原材料(その他)'!E:E,'1.4原材料(その他)'!C:C,A:A,'1.4原材料(その他)'!H:H,I$3) -> 0 | J33: =SUMIFS('1.4原材料(その他)'!E:E,'1.4原材料(その他)'!C:C,A:A,'1.4原材料(その他)'!H:H,J$3) -> 0 | K33: =SUMIFS('1.4原材料(その他)'!E:E,'1.4原材料(その他)'!C:C,A:A,'1.4原材料(その他)'!H:H,K$3) -> 0 | L33: =SUMIFS('1.4原材料(その他)'!E:E,'1.4原材料(その他)'!C:C,A:A,'1.4原材料(その他)'!H:H,L$3) -> 30.24 | M33: =SUMIFS('1.4原材料(その他)'!E:E,'1.4原材料(その他)'!C:C,A:A,'1.4原材料(その他)'!H:H,M$3) -> 63.86 | N33: =O33-(E33+F33-SUM(G33:M33)) -> 7.1764816e-13 | O33: =SUMIF('1.5原材料在庫'!A:A,原材料SC明細!A33,'1.5原材料在庫'!D:D) -> -6.4659389e-13
D34: 金額(円) | E34: -2.1750925e-12 | F34: =F33*$C33 -> 0 | G34: =G33*$C33 -> 0 | H34: =H33*$C33 -> 0 | I34: =I33*$C33 -> 0 | J34: =J33*$C33 -> 0 | K34: =K33*$C33 -> 0 | L34: =L33*$C33 -> 0 | M34: =M33*$C33 -> 0 | N34: =IFERROR(N33/SUM($E33:$F33)*SUM($E34:$F34),"") -> -3.9685536e-28 | O34: =O33*$C33 -> 0
A35: 16 | B35: 夏みかん | C35: =IFERROR(VLOOKUP(A35,'原料標準単価（貼付）'!B:E,3,FALSE),0) -> 0 | D35: 数量(㎏) | E35: 8.8817842e-14 | F35: =IFERROR(VLOOKUP(A35,'1.2①原材料受入'!A:E,3,FALSE),0) -> 111.8 | G35: =SUMIF('1.3②原材料使用'!C:E,A35,'1.3②原材料使用'!E:E) -> 100.8 | H35: =SUMIFS('1.4原材料(その他)'!E:E,'1.4原材料(その他)'!C:C,A:A,'1.4原材料(その他)'!H:H,H$3) -> 4 | I35: =SUMIFS('1.4原材料(その他)'!E:E,'1.4原材料(その他)'!C:C,A:A,'1.4原材料(その他)'!H:H,I$3) -> 0 | J35: =SUMIFS('1.4原材料(その他)'!E:E,'1.4原材料(その他)'!C:C,A:A,'1.4原材料(その他)'!H:H,J$3) -> 0 | K35: =SUMIFS('1.4原材料(その他)'!E:E,'1.4原材料(その他)'!C:C,A:A,'1.4原材料(その他)'!H:H,K$3) -> 0 | L35: =SUMIFS('1.4原材料(その他)'!E:E,'1.4原材料(その他)'!C:C,A:A,'1.4原材料(その他)'!H:H,L$3) -> 5.1 | M35: =SUMIFS('1.4原材料(その他)'!E:E,'1.4原材料(その他)'!C:C,A:A,'1.4原材料(その他)'!H:H,M$3) -> 1.9 | N35: =O35-(E35+F35-SUM(G35:M35)) -> 2.4868996e-14 | O35: =SUMIF('1.5原材料在庫'!A:A,原材料SC明細!A35,'1.5原材料在庫'!D:D) -> 1.1013412e-13
D36: 金額(円) | E36: 0 | F36: =F35*$C35 -> 0 | G36: =G35*$C35 -> 0 | H36: =H35*$C35 -> 0 | I36: =I35*$C35 -> 0 | J36: =J35*$C35 -> 0 | K36: =K35*$C35 -> 0 | L36: =L35*$C35 -> 0 | M36: =M35*$C35 -> 0 | N36: =IFERROR(N35/SUM($E35:$F35)*SUM($E36:$F36),"") -> 0 | O36: =O35*$C35 -> 0
A37: 17 | B37: 伊予柑 | C37: =IFERROR(VLOOKUP(A37,'原料標準単価（貼付）'!B:E,3,FALSE),0) -> 0 | D37: 数量(㎏) | E37: 8.5265128e-14 | F37: =IFERROR(VLOOKUP(A37,'1.2①原材料受入'!A:E,3,FALSE),0) -> 222 | G37: =SUMIF('1.3②原材料使用'!C:E,A37,'1.3②原材料使用'!E:E) -> 201.6 | H37: =SUMIFS('1.4原材料(その他)'!E:E,'1.4原材料(その他)'!C:C,A:A,'1.4原材料(その他)'!H:H,H$3) -> 2 | I37: =SUMIFS('1.4原材料(その他)'!E:E,'1.4原材料(その他)'!C:C,A:A,'1.4原材料(その他)'!H:H,I$3) -> 0 | J37: =SUMIFS('1.4原材料(その他)'!E:E,'1.4原材料(その他)'!C:C,A:A,'1.4原材料(その他)'!H:H,J$3) -> 0 | K37: =SUMIFS('1.4原材料(その他)'!E:E,'1.4原材料(その他)'!C:C,A:A,'1.4原材料(その他)'!H:H,K$3) -> 0 | L37: =SUMIFS('1.4原材料(その他)'!E:E,'1.4原材料(その他)'!C:C,A:A,'1.4原材料(その他)'!H:H,L$3) -> 15.3 | M37: =SUMIFS('1.4原材料(その他)'!E:E,'1.4原材料(その他)'!C:C,A:A,'1.4原材料(その他)'!H:H,M$3) -> 3.1 | N37: =O37-(E37+F37-SUM(G37:M37)) -> 0 | O37: =SUMIF('1.5原材料在庫'!A:A,原材料SC明細!A37,'1.5原材料在庫'!D:D) -> 5.6843419e-14
D38: 金額(円) | E38: 1.5935113e-13 | F38: =F37*$C37 -> 0 | G38: =G37*$C37 -> 0 | H38: =H37*$C37 -> 0 | I38: =I37*$C37 -> 0 | J38: =J37*$C37 -> 0 | K38: =K37*$C37 -> 0 | L38: =L37*$C37 -> 0 | M38: =M37*$C37 -> 0 | N38: =IFERROR(N37/SUM($E37:$F37)*SUM($E38:$F38),"") -> 0 | O38: =O37*$C37 -> 0
A39: 18 | B39: ｷﾝｶﾝ | C39: =IFERROR(VLOOKUP(A39,'原料標準単価（貼付）'!B:E,3,FALSE),0) -> 0 | D39: 数量(㎏) | E39: 0 | F39: =IFERROR(VLOOKUP(A39,'1.2①原材料受入'!A:E,3,FALSE),0) -> 25.1 | G39: =SUMIF('1.3②原材料使用'!C:E,A39,'1.3②原材料使用'!E:E) -> 20.16 | H39: =SUMIFS('1.4原材料(その他)'!E:E,'1.4原材料(その他)'!C:C,A:A,'1.4原材料(その他)'!H:H,H$3) -> 2 | I39: =SUMIFS('1.4原材料(その他)'!E:E,'1.4原材料(その他)'!C:C,A:A,'1.4原材料(その他)'!H:H,I$3) -> 0 | J39: =SUMIFS('1.4原材料(その他)'!E:E,'1.4原材料(その他)'!C:C,A:A,'1.4原材料(その他)'!H:H,J$3) -> 0 | K39: =SUMIFS('1.4原材料(その他)'!E:E,'1.4原材料(その他)'!C:C,A:A,'1.4原材料(その他)'!H:H,K$3) -> 0 | L39: =SUMIFS('1.4原材料(その他)'!E:E,'1.4原材料(その他)'!C:C,A:A,'1.4原材料(その他)'!H:H,L$3) -> 2.4 | M39: =SUMIFS('1.4原材料(その他)'!E:E,'1.4原材料(その他)'!C:C,A:A,'1.4原材料(その他)'!H:H,M$3) -> 0.54 | N39: =O39-(E39+F39-SUM(G39:M39)) -> -3.5527137e-15 | O39: =SUMIF('1.5原材料在庫'!A:A,原材料SC明細!A39,'1.5原材料在庫'!D:D) -> 3.5527137e-15
D40: 金額(円) | E40: 0 | F40: =F39*$C39 -> 0 | G40: =G39*$C39 -> 0 | H40: =H39*$C39 -> 0 | I40: =I39*$C39 -> 0 | J40: =J39*$C39 -> 0 | K40: =K39*$C39 -> 0 | L40: =L39*$C39 -> 0 | M40: =M39*$C39 -> 0 | N40: =IFERROR(N39/SUM($E39:$F39)*SUM($E40:$F40),"") -> 0 | O40: =O39*$C39 -> 0
A41: 19 | B41: ﾕｽﾞ | C41: =IFERROR(VLOOKUP(A41,'原料標準単価（貼付）'!B:E,3,FALSE),0) -> 0 | D41: 数量(㎏) | E41: 7.1054274e-15 | F41: =IFERROR(VLOOKUP(A41,'1.2①原材料受入'!A:E,3,FALSE),0) -> 30 | G41: =SUMIF('1.3②原材料使用'!C:E,A41,'1.3②原材料使用'!E:E) -> 20.16 | H41: =SUMIFS('1.4原材料(その他)'!E:E,'1.4原材料(その他)'!C:C,A:A,'1.4原材料(その他)'!H:H,H$3) -> 2 | I41: =SUMIFS('1.4原材料(その他)'!E:E,'1.4原材料(その他)'!C:C,A:A,'1.4原材料(その他)'!H:H,I$3) -> 0 | J41: =SUMIFS('1.4原材料(その他)'!E:E,'1.4原材料(その他)'!C:C,A:A,'1.4原材料(その他)'!H:H,J$3) -> 0 | K41: =SUMIFS('1.4原材料(その他)'!E:E,'1.4原材料(その他)'!C:C,A:A,'1.4原材料(その他)'!H:H,K$3) -> 0 | L41: =SUMIFS('1.4原材料(その他)'!E:E,'1.4原材料(その他)'!C:C,A:A,'1.4原材料(その他)'!H:H,L$3) -> 8.1 | M41: =SUMIFS('1.4原材料(その他)'!E:E,'1.4原材料(その他)'!C:C,A:A,'1.4原材料(その他)'!H:H,M$3) -> -0.26 | N41: =O41-(E41+F41-SUM(G41:M41)) -> 0 | O41: =SUMIF('1.5原材料在庫'!A:A,原材料SC明細!A41,'1.5原材料在庫'!D:D) -> 1.0658141e-14
...

Sheet 原料標準単価（貼付）
D1: ↓38期1.2原材料受入より
D3: 38期実際 | E3: 39期標準
B4: 原料コード | C4: 原料名 | D4: 仕入単価(\/kg) | E4: 単価(\/kg)
B5: 1 | C5: ﾘﾝｺﾞ | D5: 321.14552 | E5: 320
B6: 2 | C6: ｶｷ | D6: 510.48639 | E6: 510
B7: 3 | C7: ﾊﾞﾅﾅ | D7: 280.83162 | E7: 280
B8: 4 | C8: ﾊﾟｲﾝｱｯﾌﾟﾙ | D8: 352.15661 | E8: 350
B9: 5 | C9: ｱｹﾋﾞ | D9: 2148.4375 | E9: 2150
B10: 6 | C10: ﾏﾀﾀﾋﾞ | D10: 1852.6 | E10: 1850
B11: 7 | C11: ｲﾁｼﾞｸ | D11: 1215.2565 | E11: 1220
B12: 8 | C12: ｲﾁｺﾞ | D12: 2249.1039 | E12: 2250
B13: 8 | C13: ｲﾁｺﾞ | D13: 2249.1039 | E13: 2250
B14: 9 | C14: 山ﾌﾞﾄﾞｳ | D14: 1106.6425 | E14: 1110
B15: 10 | C15: ﾌﾞﾄﾞｳ | D15: 1088.172 | E15: 1090
B16: 11 | C16: 山桃 | D16: 3806.4972 | E16: 3810
... B107: 927 | C107: えんどう豆 | D107: 0 | E107: 0

Sheet 1.2①原材料受入
A1: 原料コード | B1: 原料名 | C1: 原料量 | D1: 単位 | E1: 仕入金額 | F1: check | H1: 1 | I1: ﾘﾝｺﾞ
A2: 1 | B2: ﾘﾝｺﾞ | C2: 8226.8 | D2: ㎏ | E2: 2642000 | F2: =VLOOKUP(A2,$H:$H,1,FALSE) -> 1
A3: 2 | B3: ｶｷ | C3: 224.1 | D3: ㎏ | E3: 114400 | F3: =VLOOKUP(A3,$H:$H,1,FALSE) -> 2 | H3: 2 | I3: ｶｷ
A4: 3 | B4: ﾊﾞﾅﾅ | C4: 3119.2 | D4: ㎏ | E4: 875970 | F4: =VLOOKUP(A4,$H:$H,1,FALSE) -> 3
A5: 4 | B5: ﾊﾟｲﾝｱｯﾌﾟﾙ | C5: 3141.5 | D5: ㎏ | E5: 1106300 | F5: =VLOOKUP(A5,$H:$H,1,FALSE) -> 4 | H5: 3 | I5: ﾊﾞﾅﾅ
A6: 5 | B6: ｱｹﾋﾞ | C6: 230.4 | D6: ㎏ | E6: 495000 | F6: =VLOOKUP(A6,$H:$H,1,FALSE) -> 5
A7: 7 | B7: ｲﾁｼﾞｸ | C7: 228.1 | D7: ㎏ | E7: 277200 | F7: =VLOOKUP(A7,$H:$H,1,FALSE) -> 7 | H7: 4 | I7: ﾊﾟｲﾝｱｯﾌﾟﾙ
A8: 8 | B8: ｲﾁｺﾞ | C8: 27.9 | D8: ㎏ | E8: 62750 | F8: =VLOOKUP(A8,$H:$H,1,FALSE) -> 8
A9: 9 | B9: 山ﾌﾞﾄﾞｳ | C9: 248.4 | D9: ㎏ | E9: 274890 | F9: =VLOOKUP(A9,$H:$H,1,FALSE) -> 9 | H9: 5 | I9: ｱｹﾋﾞ
A10: 10 | B10: ﾌﾞﾄﾞｳ | C10: 1162.5 | D10: ㎏ | E10: 1265000 | F10: =VLOOKUP(A10,$H:$H,1,FALSE) -> 10
A11: 11 | B11: 山桃 | C11: 141.6 | D11: ㎏ | E11: 539000 | F11: =VLOOKUP(A11,$H:$H,1,FALSE) -> 11 | H11: 6 | I11: ﾏﾀﾀﾋﾞ
A12: 12 | B12: 梅 | C12: 16.6 | D12: ㎏ | E12: 0 | F12: =VLOOKUP(A12,$H:$H,1,FALSE) -> 12
A13: 13 | B13: ﾈｰﾌﾞﾙ | C13: 673.4 | D13: ㎏ | E13: 0 | F13: =VLOOKUP(A13,$H:$H,1,FALSE) -> 13 | H13: 7 | I13: ｲﾁｼﾞｸ
A14: 14 | B14: ﾊｯｻｸ | C14: 1510.5 | D14: ㎏ | E14: 0 | F14: =VLOOKUP(A14,$H:$H,1,FALSE) -> 14
A15: 15 | B15: みかん | C15: 3933.3 | D15: ㎏ | E15: 0 | F15: =VLOOKUP(A15,$H:$H,1,FALSE) -> 15 | H15: 8 | I15: ｲﾁｺﾞ
A16: 16 | B16: 夏みかん | C16: 111.8 | D16: ㎏ | E16: 0 | F16: =VLOOKUP(A16,$H:$H,1,FALSE) -> 16
A17: 17 | B17: 伊予柑 | C17: 222 | D17: ㎏ | E17: 0 | F17: =VLOOKUP(A17,$H:$H,1,FALSE) -> 17 | H17: 9 | I17: 山ﾌﾞﾄﾞｳ
A18: 18 | B18: ｷﾝｶﾝ | C18: 25.1 | D18: ㎏ | E18: 0 | F18: =VLOOKUP(A18,$H:$H,1,FALSE) -> 18
A19: 19 | B19: ﾕｽﾞ | C19: 30 | D19: ㎏ | E19: 0 | F19: =VLOOKUP(A19,$H:$H,1,FALSE) -> 19 | H19: 10 | I19: ﾌﾞﾄﾞｳ
A20: 20 | B20: ｶﾎﾞｽ | C20: 30.6 | D20: ㎏ | E20: 0 | F20: =VLOOKUP(A20,$H:$H,1,FALSE) -> 20
A21: 21 | B21: ｻﾞﾎﾞﾝ | C21: 31.1 | D21: ㎏ | E21: 0 | F21: =VLOOKUP(A21,$H:$H,1,FALSE) -> 21 | H21: 11 | I21: 山桃
A22: 22 | B22: ﾎﾟﾝｶﾝ | C22: 30.6 | D22: ㎏ | E22: 0 | F22: =VLOOKUP(A22,$H:$H,1,FALSE) -> 22
A23: 23 | B23: ﾚﾓﾝ | C23: 224 | D23: ㎏ | E23: 0 | F23: =VLOOKUP(A23,$H:$H,1,FALSE) -> 23 | H23: 12 | I23: 梅
A24: 24 | B24: ｺﾞﾎﾞｳ | C24: 31.3 | D24: ㎏ | E24: 13440 | F24: =VLOOKUP(A24,$H:$H,1,FALSE) -> 24
A25: 25 | B25: ﾆﾝｼﾞﾝ（西洋） | C25: 1150.6 | D25: ㎏ | E25: 5720 | F25: =VLOOKUP(A25,$H:$H,1,FALSE) -> 25 | H25: 13 | I25: ﾈｰﾌﾞﾙ
A26: 26 | B26: ﾆﾝｼﾞﾝ（金時） | C26: 862.5 | D26: ㎏ | E26: 211582 | F26: =VLOOKUP(A26,$H:$H,1,FALSE) -> 26
A27: 27 | B27: ﾆﾝﾆｸ | C27: 536.1 | D27: ㎏ | E27: 1639700 | F27: =VLOOKUP(A27,$H:$H,1,FALSE) -> 27 | H27: 14 | I27: ﾊｯｻｸ
A28: 28 | B28: ﾚﾝｺﾝ | C28: 31.9 | D28: ㎏ | E28: 19600 | F28: =VLOOKUP(A28,$H:$H,1,FALSE) -> 28
A29: 29 | B29: ﾕﾘ根 | C29: 36.4 | D29: ㎏ | E29: 66500 | F29: =VLOOKUP(A29,$H:$H,1,FALSE) -> 29 | H29: 15 | I29: 温州みかん
A30: 30 | B30: 玄米 | C30: 2430 | D30: ㎏ | E30: 1115370 | F30: =VLOOKUP(A30,$H:$H,1,FALSE) -> 30
A31: 31 | B31: もち米 | C31: 1530 | D31: ㎏ | E31: 976140 | F31: =VLOOKUP(A31,$H:$H,1,FALSE) -> 31 | H31: 16 | I31: 夏みかん
A32: 32 | B32: 白米 | C32: 3090 | D32: ㎏ | E32: 1418310 | F32: =VLOOKUP(A32,$H:$H,1,FALSE) -> 32
A33: 33 | B33: きび | C33: 20 | D33: ㎏ | E33: 40800 | F33: =VLOOKUP(A33,$H:$H,1,FALSE) -> 33 | H33: 17 | I33: 伊予柑
A34: 34 | B34: とうもろこし | C34: 42.8 | D34: ㎏ | E34: 0 | F34: =VLOOKUP(A34,$H:$H,1,FALSE) -> 34
A35: 35 | B35: 大麦 | C35: 40 | D35: ㎏ | E35: 11600 | F35: =VLOOKUP(A35,$H:$H,1,FALSE) -> 35 | H35: 18 | I35: ｷﾝｶﾝ
A36: 36 | B36: あわ | C36: 20 | D36: ㎏ | E36: 43200 | F36: =VLOOKUP(A36,$H:$H,1,FALSE) -> 36
A37: 37 | B37: 大豆 | C37: 630 | D37: ㎏ | E37: 157500 | F37: =VLOOKUP(A37,$H:$H,1,FALSE) -> 37 | H37: 19 | I37: ﾕｽﾞ
A38: 38 | B38: 黒豆 | C38: 960 | D38: ㎏ | E38: 384000 | F38: =VLOOKUP(A38,$H:$H,1,FALSE) -> 38
A39: 39 | B39: 黒ｺﾞﾏ | C39: 1575 | D39: ㎏ | E39: 1629600 | F39: =VLOOKUP(A39,$H:$H,1,FALSE) -> 39 | H39: 20 | I39: ｶﾎﾞｽ
A40: 40 | B40: 白ｺﾞﾏ | C40: 1575 | D40: ㎏ | E40: 1555350 | F40: =VLOOKUP(A40,$H:$H,1,FALSE) -> 40
...

Sheet 1.3②原材料使用
A1: 原液コード | B1: 原液名 | C1: 原料コード | D1: 原料名 | E1: 原料量 | F1: 工程コード | G1: 工程名
A2: 1-00-09 | B2: GIN | C2: 055 | D2: ｼｮｳｶﾞ | E2: 1272.5 | F2: 002 | G2: 仕込工程 | H2: 製造使用分
A3: 1-00-09 | B3: GIN | C3: 201 | D3: 黒糖 | E3: 425.6 | F3: 002 | G3: 仕込工程 | H3: 製造使用分
A4: 1-41-1-01 | B4: 41Rﾘ | C4: 001 | D4: ﾘﾝｺﾞ | E4: 47 | F4: 006 | G4: 添加･混合工程 | H4: 製造使用分
A5: 1-42-1-01 | B5: 42Rﾘ | C5: 001 | D5: ﾘﾝｺﾞ | E5: 1897.54 | F5: 006 | G5: 添加･混合工程 | H5: 製造使用分
A6: 1-49-1 | B6: 49R | C6: 008 | D6: ｲﾁｺﾞ | E6: 0.24 | F6: 002 | G6: 仕込工程 | H6: 製造使用分
A7: 1-49-1 | B7: 49R | C7: 025 | D7: ﾆﾝｼﾞﾝ（西洋） | E7: 40.8 | F7: 002 | G7: 仕込工程 | H7: 製造使用分
A8: 1-49-1 | B8: 49R | C8: 027 | D8: ﾆﾝﾆｸ | E8: 6 | F8: 002 | G8: 仕込工程 | H8: 製造使用分
A9: 1-49-1 | B9: 49R | C9: 030 | D9: 玄米 | E9: 949.2 | F9: 002 | G9: 仕込工程 | H9: 製造使用分
A10: 1-49-1 | B10: 49R | C10: 039 | D10: 黒ｺﾞﾏ | E10: 1562 | F10: 002 | G10: 仕込工程 | H10: 製造使用分
A11: 1-49-1 | B11: 49R | C11: 040 | D11: 白ｺﾞﾏ | E11: 1562 | F11: 002 | G11: 仕込工程 | H11: 製造使用分
A12: 1-49-1 | B12: 49R | C12: 046 | D12: ｷｭｳﾘ | E12: 31.24 | F12: 002 | G12: 仕込工程 | H12: 製造使用分
A13: 1-49-1 | B13: 49R | C13: 047 | D13: ｼｿ | E13: 3.124 | F13: 002 | G13: 仕込工程 | H13: 製造使用分
... A111: 7-11 | B111: 黒西 | C111: 201 | D111: 黒糖 | E111: 267.5 | F111: 002 | G111: 仕込工程 | H111: 製造使用分

Sheet 1.4原材料(その他)
A1: 原液コード | B1: 原液名 | C1: 原料コード | D1: 原料名 | E1: 原料量 | F1: 工程コード | G1: 工程名
C2: 001 | D2: ﾘﾝｺﾞ | E2: 15.58 | F2: 097 | G2: 工程ロス | H2: ロス分
C3: 002 | D3: ｶｷ | E3: 1 | F3: 096 | G3: 呼吸ロス | H3: ロス分
C4: 002 | D4: ｶｷ | E4: 3.49 | F4: 097 | G4: 工程ロス | H4: ロス分
C5: 005 | D5: ｱｹﾋﾞ | E5: 1.5 | F5: 097 | G5: 工程ロス | H5: ロス分
C6: 006 | D6: ﾏﾀﾀﾋﾞ | E6: 0.16 | F6: 097 | G6: 工程ロス | H6: ロス分
C7: 007 | D7: ｲﾁｼﾞｸ | E7: 1.9 | F7: 097 | G7: 工程ロス | H7: ロス分
C8: 008 | D8: ｲﾁｺﾞ | E8: 0.835 | F8: 097 | G8: 工程ロス | H8: ロス分
C9: 009 | D9: 山ﾌﾞﾄﾞｳ | E9: 5.4 | F9: 096 | G9: 呼吸ロス | H9: ロス分
C10: 009 | D10: 山ﾌﾞﾄﾞｳ | E10: 2.4 | F10: 097 | G10: 工程ロス | H10: ロス分
C11: 010 | D11: ﾌﾞﾄﾞｳ | E11: 6.34 | F11: 097 | G11: 工程ロス | H11: ロス分
C12: 011 | D12: 山桃 | E12: 4.37 | F12: 096 | G12: 呼吸ロス | H12: ロス分
C13: 011 | D13: 山桃 | E13: 5.43 | F13: 097 | G13: 工程ロス | H13: ロス分
... C278: 010 | D278: ﾌﾞﾄﾞｳ | E278: 38.8 | F278: 098 | G278: 返品 | H278: 返品

Sheet 1.5原材料在庫
A1: 原料コード | B1: 原料名 | C1: 原料ロット番号 | D1: 在庫数量 | E1: 単位 | F1: 受入数量 | G1: 使用数量 | H1: 賞味期限の先頭 | I1: 備考の先頭
A2: 001 | B2: ﾘﾝｺﾞ | C2: 190726 | D2: 0 | E2: ㎏ | F2: 240 | G2: 240
A3: 001 | B3: ﾘﾝｺﾞ | C3: 191219 | D3: 0 | E3: ㎏ | F3: 2195.2 | G3: 2195.2
A4: 001 | B4: ﾘﾝｺﾞ | C4: 200127 | D4: 0 | E4: ㎏ | F4: 1085.3 | G4: 1085.3
A5: 001 | B5: ﾘﾝｺﾞ | C5: 200203 | D5: 0 | E5: ㎏ | F5: 2559 | G5: 2559
A6: 001 | B6: ﾘﾝｺﾞ | C6: 200207 | D6: 0 | E6: ㎏ | F6: 588.7 | G6: 588.7
A7: 001 | B7: ﾘﾝｺﾞ | C7: 200213 | D7: 0 | E7: ㎏ | F7: 607.9 | G7: 607.9
A8: 001 | B8: ﾘﾝｺﾞ | C8: 200522-2 | D8: 0 | E8: ㎏ | F8: 4.7 | G8: 4.7
A9: 001 | B9: ﾘﾝｺﾞ | C9: 200714 | D9: 0 | E9: ㎏ | F9: 160 | G9: 160
A10: 001 | B10: ﾘﾝｺﾞ | C10: 200728 | D10: 0 | E10: ㎏ | F10: 10 | G10: 10
A11: 001 | B11: ﾘﾝｺﾞ | C11: 201109 | D11: -7.1054274e-15 | E11: ㎏ | F11: 30 | G11: 30
A12: 001 | B12: ﾘﾝｺﾞ | C12: 210105 | D12: -9.094947e-13 | E12: ㎏ | F12: 7828 | G12: 7828
A13: 001 | B13: ﾘﾝｺﾞ | C13: 210120 | D13: 0 | E13: ㎏ | F13: 2200 | G13: 2200
A14: 001 | B14: ﾘﾝｺﾞ | C14: 210215 | D14: 0 | E14: ㎏ | F14: 2478.6 | G14: 2478.6 | I14: 仕入先：㈲やまこう商店
A15: 001 | B15: ﾘﾝｺﾞ | C15: 210226 | D15: 0 | E15: ㎏ | F15: 2097 | G15: 2097
A16: 001 | B16: ﾘﾝｺﾞ | C16: 210301 | D16: 0 | E16: ㎏ | F16: 11 | G16: 11
A17: 001 | B17: ﾘﾝｺﾞ | C17: 210514 | D17: 0 | E17: ㎏ | F17: 77 | G17: 77
A18: 001 | B18: ﾘﾝｺﾞ | C18: 220106 | D18: 9.094947e-13 | E18: ㎏ | F18: 5178 | G18: 5178 | I18: 仕入先：㈲やまこう商店
A19: 001 | B19: ﾘﾝｺﾞ | C19: 220117 | D19: 0 | E19: ㎏ | F19: 2208 | G19: 2208
A20: 001 | B20: ﾘﾝｺﾞ | C20: 220120 | D20: 9.094947e-13 | E20: ㎏ | F20: 2144 | G20: 2144
A21: 001 | B21: ﾘﾝｺﾞ | C21: 220131 | D21: 0 | E21: ㎏ | F21: 5150 | G21: 5150 | I21: 仕入先：㈲やまこう商店
A22: 001 | B22: ﾘﾝｺﾞ | C22: 230106 | D22: 9.094947e-13 | E22: ㎏ | F22: 5155.5 | G22: 5155.5 | I22: 仕入先：㈲やまこう商店
A23: 001 | B23: ﾘﾝｺﾞ | C23: 230116 | D23: -4.5474735e-13 | E23: ㎏ | F23: 2141.5 | G23: 2141.5
A24: 001 | B24: ﾘﾝｺﾞ | C24: 230124 | D24: -4.5474735e-13 | E24: ㎏ | F24: 2734.2 | G24: 2734.2
A25: 001 | B25: ﾘﾝｺﾞ | C25: 230203 | D25: 0 | E25: ㎏ | F25: 2578.7 | G25: 2578.7 | I25: 仕入先：㈲やまこう商店
A26: 001 | B26: ﾘﾝｺﾞ | C26: 230727 | D26: 0 | E26: ㎏ | F26: 163.2 | G26: 163.2
A27: 001 | B27: ﾘﾝｺﾞ | C27: 240115 | D27: 0 | E27: ㎏ | F27: 5472.5 | G27: 5472.5 | I27: 仕入先：㈲やまこう商店
A28: 001 | B28: ﾘﾝｺﾞ | C28: 240125 | D28: 2.2737368e-13 | E28: ㎏ | F28: 1235.7 | G28: 1235.7 | I28: 仕入先：㈲やまこう商店
A29: 001 | B29: ﾘﾝｺﾞ | C29: 240205 | D29: 0 | E29: ㎏ | F29: 4494.7 | G29: 4494.7 | I29: 仕入先：㈲やまこう商店
A30: 001 | B30: ﾘﾝｺﾞ | C30: 250109 | D30: -9.094947e-13 | E30: ㎏ | F30: 5292.5 | G30: 5292.5 | I30: 仕入先：㈲やまこう商店
A31: 001 | B31: ﾘﾝｺﾞ | C31: 250117 | D31: -2.2737368e-13 | E31: ㎏ | F31: 1215 | G31: 1215
A32: 001 | B32: ﾘﾝｺﾞ | C32: 250210 | D32: -2.2737368e-13 | E32: ㎏ | F32: 1719.3 | G32: 1719.3 | I32: 仕入先：㈱シャンティ
A33: 002 | B33: ｶｷ | C33: 201015 | D33: 0 | E33: ㎏ | F33: 302 | G33: 302
A34: 002 | B34: ｶｷ | C34: 201016 | D34: 0 | E34: ㎏ | F34: 14 | G34: 14 | I34: 無償
A35: 002 | B35: ｶｷ | C35: 210128 | D35: 0 | E35: ㎏ | F35: 10 | G35: 10
A36: 002 | B36: ｶｷ | C36: 211023 | D36: -5.6843419e-14 | E36: ㎏ | F36: 332.4 | G36: 332.4
A37: 002 | B37: ｶｷ | C37: 221028 | D37: 1.1368684e-13 | E37: ㎏ | F37: 352.5 | G37: 352.5
A38: 002 | B38: ｶｷ | C38: 231020 | D38: 0 | E38: ㎏ | F38: 347.5 | G38: 347.5
A39: 002 | B39: ｶｷ | C39: 240226 | D39: -8.8817842e-16 | E39: ㎏ | F39: 4.6 | G39: 4.6
A40: 002 | B40: ｶｷ | C40: 241028 | D40: -2.8421709e-14 | E40: ㎏ | F40: 224.1 | G40: 224.1
...
